Workbook
Name valuevx: 42.314159
Name LocationList: '_Locations'!$A$1:$A$37

Sheet Work Hours Summary
A1: 📊 WORK HOURS SUMMARY
A2: Pay Period: 1-15/16 Jan 2026 | Total Employees: 11
A4: # | B4: Employee Name | C4: Emp # | D4: Total Hrs | E4: Days Wkd | F4: Daily >12 | G4: Wkly >60 | H4: 7+ Days | I4: OT >40 | J4: Wkly <40 | K4: Daily <8 | L4: Days <5 | M4: Period <80 | N4: STATUS
A5: 1 | B5: Barnes, Mauva | C5: 0118 | D5: ='Barnes, Mauva'!I49 | E5: ='Barnes, Mauva'!Q50 | F5: =SUMPRODUCT((('Barnes, Mauva'!I14+'Barnes, Mauva'!I15)>12)*1)+SUMPRODUCT((('Barnes, Mauva'!I16+'Barnes, Mauva'!I17)>12)*1)+SUMPRODUCT((('Barnes, Mauva'!I18+'Barnes, Mauva'!I19)>12)*1)+SUMPRODUCT((('Barnes, Mauva'!I20+'Barnes, Mauva'!I21)>12)*1)+SUMPRODUCT((('Barnes, Mauva'!I22+'Barnes, Mauva'!I23)>12)*1)+SUMPRODUCT((('Barnes, Mauva'!I24+'Barnes, Mauva'!I25)>12)*1)+SUMPRODUCT((('Barnes, Mauva'!I26+'Barnes, Mauva'!I27)>12)*1)+SUMPRODUCT((('Barnes, Mauva'!I30+'Barnes, Mauva'!I31)>12)*1)+SUMPRODUCT((('Barnes, Mauva'!I32+'Barnes, Mauva'!I33)>12)*1)+SUMPRODUCT((('Barnes, Mauva'!I34+'Barnes, Mauva'!I35)>12)*1)+SUMPRODUCT((('Barnes, Mauva'!I36+'Barnes, Mauva'!I37)>12)*1)+SUMPRODUCT((('Barnes, Mauva'!I38+'Barnes, Mauva'!I39)>12)*1)+SUMPRODUCT((('Barnes, Mauva'!I40+'Barnes, Mauva'!I41)>12)*1)+SUMPRODUCT((('Barnes, Mauva'!I42+'Barnes, Mauva'!I43)>12)*1)+SUMPRODUCT((('Barnes, Mauva'!I45+'Barnes, Mauva'!I46)>12)*1)+SUMPRODUCT((('Barnes, Mauva'!I47+'Barnes, Mauva'!I48)>12)*1) | G5: =IF(MAX(SUM('Barnes, Mauva'!I14:I27),SUM('Barnes, Mauva'!I30:I43))>60,"Yes","") | H5: =IF(OR(AND(('Barnes, Mauva'!I14+'Barnes, Mauva'!I15)>0,('Barnes, Mauva'!I16+'Barnes, Mauva'!I17)>0,('Barnes, Mauva'!I18+'Barnes, Mauva'!I19)>0,('Barnes, Mauva'!I20+'Barnes, Mauva'!I21)>0,('Barnes, Mauva'!I22+'Barnes, Mauva'!I23)>0,('Barnes, Mauva'!I24+'Barnes, Mauva'!I25)>0,('Barnes, Mauva'!I26+'Barnes, Mauva'!I27)>0),AND(('Barnes, Mauva'!I30+'Barnes, Mauva'!I31)>0,('Barnes, Mauva'!I32+'Barnes, Mauva'!I33)>0,('Barnes, Mauva'!I34+'Barnes, Mauva'!I35)>0,('Barnes, Mauva'!I36+'Barnes, Mauva'!I37)>0,('Barnes, Mauva'!I38+'Barnes, Mauva'!I39)>0,('Barnes, Mauva'!I40+'Barnes, Mauva'!I41)>0,('Barnes, Mauva'!I42+'Barnes, Mauva'!I43)>0)),"Yes","") | I5: =IF('Barnes, Mauva'!N49>40,"Yes","") | J5: =IF(OR(AND(SUM('Barnes, Mauva'!I14:I27)>0,SUM('Barnes, Mauva'!I14:I27)<40),AND(SUM('Barnes, Mauva'!I30:I43)>0,SUM('Barnes, Mauva'!I30:I43)<40)),"Yes","") | K5: =SUMPRODUCT(('Barnes, Mauva'!I14:I48>0)*('Barnes, Mauva'!I14:I48<8)) | L5: =IF('Barnes, Mauva'!Q50<5,"Yes","") | M5: =IF(AND('Barnes, Mauva'!I49>0,'Barnes, Mauva'!I49<80),"Yes","") | N5: =IF(OR(F5>0,G5="Yes",H5="Yes",I5="Yes"),"⚠️ OVERWORK",IF(OR(J5="Yes",K5>0,L5="Yes",M5="Yes"),"🔻 UNDERWORK","✓ OK"))
A6: 2 | B6: Browne, Francianna Milissa | C6: 2234 | D6: ='Browne, Francianna Milissa'!I49 | E6: ='Browne, Francianna Milissa'!Q50 | F6: =SUMPRODUCT((('Browne, Francianna Milissa'!I14+'Browne, Francianna Milissa'!I15)>12)*1)+SUMPRODUCT((('Browne, Francianna Milissa'!I16+'Browne, Francianna Milissa'!I17)>12)*1)+SUMPRODUCT((('Browne, Francianna Milissa'!I18+'Browne, Francianna Milissa'!I19)>12)*1)+SUMPRODUCT((('Browne, Francianna Milissa'!I20+'Browne, Francianna Milissa'!I21)>12)*1)+SUMPRODUCT((('Browne, Francianna Milissa'!I22+'Browne, Francianna Milissa'!I23)>12)*1)+SUMPRODUCT((('Browne, Francianna Milissa'!I24+'Browne, Francianna Milissa'!I25)>12)*1)+SUMPRODUCT((('Browne, Francianna Milissa'!I26+'Browne, Francianna Milissa'!I27)>12)*1)+SUMPRODUCT((('Browne, Francianna Milissa'!I30+'Browne, Francianna Milissa'!I31)>12)*1)+SUMPRODUCT((('Browne, Francianna Milissa'!I32+'Browne, Francianna Milissa'!I33)>12)*1)+SUMPRODUCT((('Browne, Francianna Milissa'!I34+'Browne, Francianna Milissa'!I35)>12)*1)+SUMPRODUCT((('Browne, Francianna Milissa'!I36+'Browne, Francianna Milissa'!I37)>12)*1)+SUMPRODUCT((('Browne, Francianna Milissa'!I38+'Browne, Francianna Milissa'!I39)>12)*1)+SUMPRODUCT((('Browne, Francianna Milissa'!I40+'Browne, Francianna Milissa'!I41)>12)*1)+SUMPRODUCT((('Browne, Francianna Milissa'!I42+'Browne, Francianna Milissa'!I43)>12)*1)+SUMPRODUCT((('Browne, Francianna Milissa'!I45+'Browne, Francianna Milissa'!I46)>12)*1)+SUMPRODUCT((('Browne, Francianna Milissa'!I47+'Browne, Francianna Milissa'!I48)>12)*1) | G6: =IF(MAX(SUM('Browne, Francianna Milissa'!I14:I27),SUM('Browne, Francianna Milissa'!I30:I43))>60,"Yes","") | H6: =IF(OR(AND(('Browne, Francianna Milissa'!I14+'Browne, Francianna Milissa'!I15)>0,('Browne, Francianna Milissa'!I16+'Browne, Francianna Milissa'!I17)>0,('Browne, Francianna Milissa'!I18+'Browne, Francianna Milissa'!I19)>0,('Browne, Francianna Milissa'!I20+'Browne, Francianna Milissa'!I21)>0,('Browne, Francianna Milissa'!I22+'Browne, Francianna Milissa'!I23)>0,('Browne, Francianna Milissa'!I24+'Browne, Francianna Milissa'!I25)>0,('Browne, Francianna Milissa'!I26+'Browne, Francianna Milissa'!I27)>0),AND(('Browne, Francianna Milissa'!I30+'Browne, Francianna Milissa'!I31)>0,('Browne, Francianna Milissa'!I32+'Browne, Francianna Milissa'!I33)>0,('Browne, Francianna Milissa'!I34+'Browne, Francianna Milissa'!I35)>0,('Browne, Francianna Milissa'!I36+'Browne, Francianna Milissa'!I37)>0,('Browne, Francianna Milissa'!I38+'Browne, Francianna Milissa'!I39)>0,('Browne, Francianna Milissa'!I40+'Browne, Francianna Milissa'!I41)>0,('Browne, Francianna Milissa'!I42+'Browne, Francianna Milissa'!I43)>0)),"Yes","") | I6: =IF('Browne, Francianna Milissa'!N49>40,"Yes","") | J6: =IF(OR(AND(SUM('Browne, Francianna Milissa'!I14:I27)>0,SUM('Browne, Francianna Milissa'!I14:I27)<40),AND(SUM('Browne, Francianna Milissa'!I30:I43)>0,SUM('Browne, Francianna Milissa'!I30:I43)<40)),"Yes","") | K6: =SUMPRODUCT(('Browne, Francianna Milissa'!I14:I48>0)*('Browne, Francianna Milissa'!I14:I48<8)) | L6: =IF('Browne, Francianna Milissa'!Q50<5,"Yes","") | M6: =IF(AND('Browne, Francianna Milissa'!I49>0,'Browne, Francianna Milissa'!I49<80),"Yes","") | N6: =IF(OR(F6>0,G6="Yes",H6="Yes",I6="Yes"),"⚠️ OVERWORK",IF(OR(J6="Yes",K6>0,L6="Yes",M6="Yes"),"🔻 UNDERWORK","✓ OK"))
A7: 3 | B7: Daniels, John Llewellyn | C7: 4777 | D7: ='Daniels, John Llewellyn'!I49 | E7: ='Daniels, John Llewellyn'!Q50 | F7: =SUMPRODUCT((('Daniels, John Llewellyn'!I14+'Daniels, John Llewellyn'!I15)>12)*1)+SUMPRODUCT((('Daniels, John Llewellyn'!I16+'Daniels, John Llewellyn'!I17)>12)*1)+SUMPRODUCT((('Daniels, John Llewellyn'!I18+'Daniels, John Llewellyn'!I19)>12)*1)+SUMPRODUCT((('Daniels, John Llewellyn'!I20+'Daniels, John Llewellyn'!I21)>12)*1)+SUMPRODUCT((('Daniels, John Llewellyn'!I22+'Daniels, John Llewellyn'!I23)>12)*1)+SUMPRODUCT((('Daniels, John Llewellyn'!I24+'Daniels, John Llewellyn'!I25)>12)*1)+SUMPRODUCT((('Daniels, John Llewellyn'!I26+'Daniels, John Llewellyn'!I27)>12)*1)+SUMPRODUCT((('Daniels, John Llewellyn'!I30+'Daniels, John Llewellyn'!I31)>12)*1)+SUMPRODUCT((('Daniels, John Llewellyn'!I32+'Daniels, John Llewellyn'!I33)>12)*1)+SUMPRODUCT((('Daniels, John Llewellyn'!I34+'Daniels, John Llewellyn'!I35)>12)*1)+SUMPRODUCT((('Daniels, John Llewellyn'!I36+'Daniels, John Llewellyn'!I37)>12)*1)+SUMPRODUCT((('Daniels, John Llewellyn'!I38+'Daniels, John Llewellyn'!I39)>12)*1)+SUMPRODUCT((('Daniels, John Llewellyn'!I40+'Daniels, John Llewellyn'!I41)>12)*1)+SUMPRODUCT((('Daniels, John Llewellyn'!I42+'Daniels, John Llewellyn'!I43)>12)*1)+SUMPRODUCT((('Daniels, John Llewellyn'!I45+'Daniels, John Llewellyn'!I46)>12)*1)+SUMPRODUCT((('Daniels, John Llewellyn'!I47+'Daniels, John Llewellyn'!I48)>12)*1) | G7: =IF(MAX(SUM('Daniels, John Llewellyn'!I14:I27),SUM('Daniels, John Llewellyn'!I30:I43))>60,"Yes","") | H7: =IF(OR(AND(('Daniels, John Llewellyn'!I14+'Daniels, John Llewellyn'!I15)>0,('Daniels, John Llewellyn'!I16+'Daniels, John Llewellyn'!I17)>0,('Daniels, John Llewellyn'!I18+'Daniels, John Llewellyn'!I19)>0,('Daniels, John Llewellyn'!I20+'Daniels, John Llewellyn'!I21)>0,('Daniels, John Llewellyn'!I22+'Daniels, John Llewellyn'!I23)>0,('Daniels, John Llewellyn'!I24+'Daniels, John Llewellyn'!I25)>0,('Daniels, John Llewellyn'!I26+'Daniels, John Llewellyn'!I27)>0),AND(('Daniels, John Llewellyn'!I30+'Daniels, John Llewellyn'!I31)>0,('Daniels, John Llewellyn'!I32+'Daniels, John Llewellyn'!I33)>0,('Daniels, John Llewellyn'!I34+'Daniels, John Llewellyn'!I35)>0,('Daniels, John Llewellyn'!I36+'Daniels, John Llewellyn'!I37)>0,('Daniels, John Llewellyn'!I38+'Daniels, John Llewellyn'!I39)>0,('Daniels, John Llewellyn'!I40+'Daniels, John Llewellyn'!I41)>0,('Daniels, John Llewellyn'!I42+'Daniels, John Llewellyn'!I43)>0)),"Yes","") | I7: =IF('Daniels, John Llewellyn'!N49>40,"Yes","") | J7: =IF(OR(AND(SUM('Daniels, John Llewellyn'!I14:I27)>0,SUM('Daniels, John Llewellyn'!I14:I27)<40),AND(SUM('Daniels, John Llewellyn'!I30:I43)>0,SUM('Daniels, John Llewellyn'!I30:I43)<40)),"Yes","") | K7: =SUMPRODUCT(('Daniels, John Llewellyn'!I14:I48>0)*('Daniels, John Llewellyn'!I14:I48<8)) | L7: =IF('Daniels, John Llewellyn'!Q50<5,"Yes","") | M7: =IF(AND('Daniels, John Llewellyn'!I49>0,'Daniels, John Llewellyn'!I49<80),"Yes","") | N7: =IF(OR(F7>0,G7="Yes",H7="Yes",I7="Yes"),"⚠️ OVERWORK",IF(OR(J7="Yes",K7>0,L7="Yes",M7="Yes"),"🔻 UNDERWORK","✓ OK"))
A8: 4 | B8: David, Jewelle Phillipa | C8: 571 | D8: ='David, Jewelle Phillipa'!I49 | E8: ='David, Jewelle Phillipa'!Q50 | F8: =SUMPRODUCT((('David, Jewelle Phillipa'!I14+'David, Jewelle Phillipa'!I15)>12)*1)+SUMPRODUCT((('David, Jewelle Phillipa'!I16+'David, Jewelle Phillipa'!I17)>12)*1)+SUMPRODUCT((('David, Jewelle Phillipa'!I18+'David, Jewelle Phillipa'!I19)>12)*1)+SUMPRODUCT((('David, Jewelle Phillipa'!I20+'David, Jewelle Phillipa'!I21)>12)*1)+SUMPRODUCT((('David, Jewelle Phillipa'!I22+'David, Jewelle Phillipa'!I23)>12)*1)+SUMPRODUCT((('David, Jewelle Phillipa'!I24+'David, Jewelle Phillipa'!I25)>12)*1)+SUMPRODUCT((('David, Jewelle Phillipa'!I26+'David, Jewelle Phillipa'!I27)>12)*1)+SUMPRODUCT((('David, Jewelle Phillipa'!I30+'David, Jewelle Phillipa'!I31)>12)*1)+SUMPRODUCT((('David, Jewelle Phillipa'!I32+'David, Jewelle Phillipa'!I33)>12)*1)+SUMPRODUCT((('David, Jewelle Phillipa'!I34+'David, Jewelle Phillipa'!I35)>12)*1)+SUMPRODUCT((('David, Jewelle Phillipa'!I36+'David, Jewelle Phillipa'!I37)>12)*1)+SUMPRODUCT((('David, Jewelle Phillipa'!I38+'David, Jewelle Phillipa'!I39)>12)*1)+SUMPRODUCT((('David, Jewelle Phillipa'!I40+'David, Jewelle Phillipa'!I41)>12)*1)+SUMPRODUCT((('David, Jewelle Phillipa'!I42+'David, Jewelle Phillipa'!I43)>12)*1)+SUMPRODUCT((('David, Jewelle Phillipa'!I45+'David, Jewelle Phillipa'!I46)>12)*1)+SUMPRODUCT((('David, Jewelle Phillipa'!I47+'David, Jewelle Phillipa'!I48)>12)*1) | G8: =IF(MAX(SUM('David, Jewelle Phillipa'!I14:I27),SUM('David, Jewelle Phillipa'!I30:I43))>60,"Yes","") | H8: =IF(OR(AND(('David, Jewelle Phillipa'!I14+'David, Jewelle Phillipa'!I15)>0,('David, Jewelle Phillipa'!I16+'David, Jewelle Phillipa'!I17)>0,('David, Jewelle Phillipa'!I18+'David, Jewelle Phillipa'!I19)>0,('David, Jewelle Phillipa'!I20+'David, Jewelle Phillipa'!I21)>0,('David, Jewelle Phillipa'!I22+'David, Jewelle Phillipa'!I23)>0,('David, Jewelle Phillipa'!I24+'David, Jewelle Phillipa'!I25)>0,('David, Jewelle Phillipa'!I26+'David, Jewelle Phillipa'!I27)>0),AND(('David, Jewelle Phillipa'!I30+'David, Jewelle Phillipa'!I31)>0,('David, Jewelle Phillipa'!I32+'David, Jewelle Phillipa'!I33)>0,('David, Jewelle Phillipa'!I34+'David, Jewelle Phillipa'!I35)>0,('David, Jewelle Phillipa'!I36+'David, Jewelle Phillipa'!I37)>0,('David, Jewelle Phillipa'!I38+'David, Jewelle Phillipa'!I39)>0,('David, Jewelle Phillipa'!I40+'David, Jewelle Phillipa'!I41)>0,('David, Jewelle Phillipa'!I42+'David, Jewelle Phillipa'!I43)>0)),"Yes","") | I8: =IF('David, Jewelle Phillipa'!N49>40,"Yes","") | J8: =IF(OR(AND(SUM('David, Jewelle Phillipa'!I14:I27)>0,SUM('David, Jewelle Phillipa'!I14:I27)<40),AND(SUM('David, Jewelle Phillipa'!I30:I43)>0,SUM('David, Jewelle Phillipa'!I30:I43)<40)),"Yes","") | K8: =SUMPRODUCT(('David, Jewelle Phillipa'!I14:I48>0)*('David, Jewelle Phillipa'!I14:I48<8)) | L8: =IF('David, Jewelle Phillipa'!Q50<5,"Yes","") | M8: =IF(AND('David, Jewelle Phillipa'!I49>0,'David, Jewelle Phillipa'!I49<80),"Yes","") | N8: =IF(OR(F8>0,G8="Yes",H8="Yes",I8="Yes"),"⚠️ OVERWORK",IF(OR(J8="Yes",K8>0,L8="Yes",M8="Yes"),"🔻 UNDERWORK","✓ OK"))
A9: 5 | B9: Dorsett, Susan Patricia | C9: 971 | D9: ='Dorsett, Susan Patricia'!I49 | E9: ='Dorsett, Susan Patricia'!Q50 | F9: =SUMPRODUCT((('Dorsett, Susan Patricia'!I14+'Dorsett, Susan Patricia'!I15)>12)*1)+SUMPRODUCT((('Dorsett, Susan Patricia'!I16+'Dorsett, Susan Patricia'!I17)>12)*1)+SUMPRODUCT((('Dorsett, Susan Patricia'!I18+'Dorsett, Susan Patricia'!I19)>12)*1)+SUMPRODUCT((('Dorsett, Susan Patricia'!I20+'Dorsett, Susan Patricia'!I21)>12)*1)+SUMPRODUCT((('Dorsett, Susan Patricia'!I22+'Dorsett, Susan Patricia'!I23)>12)*1)+SUMPRODUCT((('Dorsett, Susan Patricia'!I24+'Dorsett, Susan Patricia'!I25)>12)*1)+SUMPRODUCT((('Dorsett, Susan Patricia'!I26+'Dorsett, Susan Patricia'!I27)>12)*1)+SUMPRODUCT((('Dorsett, Susan Patricia'!I30+'Dorsett, Susan Patricia'!I31)>12)*1)+SUMPRODUCT((('Dorsett, Susan Patricia'!I32+'Dorsett, Susan Patricia'!I33)>12)*1)+SUMPRODUCT((('Dorsett, Susan Patricia'!I34+'Dorsett, Susan Patricia'!I35)>12)*1)+SUMPRODUCT((('Dorsett, Susan Patricia'!I36+'Dorsett, Susan Patricia'!I37)>12)*1)+SUMPRODUCT((('Dorsett, Susan Patricia'!I38+'Dorsett, Susan Patricia'!I39)>12)*1)+SUMPRODUCT((('Dorsett, Susan Patricia'!I40+'Dorsett, Susan Patricia'!I41)>12)*1)+SUMPRODUCT((('Dorsett, Susan Patricia'!I42+'Dorsett, Susan Patricia'!I43)>12)*1)+SUMPRODUCT((('Dorsett, Susan Patricia'!I45+'Dorsett, Susan Patricia'!I46)>12)*1)+SUMPRODUCT((('Dorsett, Susan Patricia'!I47+'Dorsett, Susan Patricia'!I48)>12)*1) | G9: =IF(MAX(SUM('Dorsett, Susan Patricia'!I14:I27),SUM('Dorsett, Susan Patricia'!I30:I43))>60,"Yes","") | H9: =IF(OR(AND(('Dorsett, Susan Patricia'!I14+'Dorsett, Susan Patricia'!I15)>0,('Dorsett, Susan Patricia'!I16+'Dorsett, Susan Patricia'!I17)>0,('Dorsett, Susan Patricia'!I18+'Dorsett, Susan Patricia'!I19)>0,('Dorsett, Susan Patricia'!I20+'Dorsett, Susan Patricia'!I21)>0,('Dorsett, Susan Patricia'!I22+'Dorsett, Susan Patricia'!I23)>0,('Dorsett, Susan Patricia'!I24+'Dorsett, Susan Patricia'!I25)>0,('Dorsett, Susan Patricia'!I26+'Dorsett, Susan Patricia'!I27)>0),AND(('Dorsett, Susan Patricia'!I30+'Dorsett, Susan Patricia'!I31)>0,('Dorsett, Susan Patricia'!I32+'Dorsett, Susan Patricia'!I33)>0,('Dorsett, Susan Patricia'!I34+'Dorsett, Susan Patricia'!I35)>0,('Dorsett, Susan Patricia'!I36+'Dorsett, Susan Patricia'!I37)>0,('Dorsett, Susan Patricia'!I38+'Dorsett, Susan Patricia'!I39)>0,('Dorsett, Susan Patricia'!I40+'Dorsett, Susan Patricia'!I41)>0,('Dorsett, Susan Patricia'!I42+'Dorsett, Susan Patricia'!I43)>0)),"Yes","") | I9: =IF('Dorsett, Susan Patricia'!N49>40,"Yes","") | J9: =IF(OR(AND(SUM('Dorsett, Susan Patricia'!I14:I27)>0,SUM('Dorsett, Susan Patricia'!I14:I27)<40),AND(SUM('Dorsett, Susan Patricia'!I30:I43)>0,SUM('Dorsett, Susan Patricia'!I30:I43)<40)),"Yes","") | K9: =SUMPRODUCT(('Dorsett, Susan Patricia'!I14:I48>0)*('Dorsett, Susan Patricia'!I14:I48<8)) | L9: =IF('Dorsett, Susan Patricia'!Q50<5,"Yes","") | M9: =IF(AND('Dorsett, Susan Patricia'!I49>0,'Dorsett, Susan Patricia'!I49<80),"Yes","") | N9: =IF(OR(F9>0,G9="Yes",H9="Yes",I9="Yes"),"⚠️ OVERWORK",IF(OR(J9="Yes",K9>0,L9="Yes",M9="Yes"),"🔻 UNDERWORK","✓ OK"))
A10: 6 | B10: Henry, Colin Vincent | C10: 5507 | D10: ='Henry, Colin Vincent'!I49 | E10: ='Henry, Colin Vincent'!Q50 | F10: =SUMPRODUCT((('Henry, Colin Vincent'!I14+'Henry, Colin Vincent'!I15)>12)*1)+SUMPRODUCT((('Henry, Colin Vincent'!I16+'Henry, Colin Vincent'!I17)>12)*1)+SUMPRODUCT((('Henry, Colin Vincent'!I18+'Henry, Colin Vincent'!I19)>12)*1)+SUMPRODUCT((('Henry, Colin Vincent'!I20+'Henry, Colin Vincent'!I21)>12)*1)+SUMPRODUCT((('Henry, Colin Vincent'!I22+'Henry, Colin Vincent'!I23)>12)*1)+SUMPRODUCT((('Henry, Colin Vincent'!I24+'Henry, Colin Vincent'!I25)>12)*1)+SUMPRODUCT((('Henry, Colin Vincent'!I26+'Henry, Colin Vincent'!I27)>12)*1)+SUMPRODUCT((('Henry, Colin Vincent'!I30+'Henry, Colin Vincent'!I31)>12)*1)+SUMPRODUCT((('Henry, Colin Vincent'!I32+'Henry, Colin Vincent'!I33)>12)*1)+SUMPRODUCT((('Henry, Colin Vincent'!I34+'Henry, Colin Vincent'!I35)>12)*1)+SUMPRODUCT((('Henry, Colin Vincent'!I36+'Henry, Colin Vincent'!I37)>12)*1)+SUMPRODUCT((('Henry, Colin Vincent'!I38+'Henry, Colin Vincent'!I39)>12)*1)+SUMPRODUCT((('Henry, Colin Vincent'!I40+'Henry, Colin Vincent'!I41)>12)*1)+SUMPRODUCT((('Henry, Colin Vincent'!I42+'Henry, Colin Vincent'!I43)>12)*1)+SUMPRODUCT((('Henry, Colin Vincent'!I45+'Henry, Colin Vincent'!I46)>12)*1)+SUMPRODUCT((('Henry, Colin Vincent'!I47+'Henry, Colin Vincent'!I48)>12)*1) | G10: =IF(MAX(SUM('Henry, Colin Vincent'!I14:I27),SUM('Henry, Colin Vincent'!I30:I43))>60,"Yes","") | H10: =IF(OR(AND(('Henry, Colin Vincent'!I14+'Henry, Colin Vincent'!I15)>0,('Henry, Colin Vincent'!I16+'Henry, Colin Vincent'!I17)>0,('Henry, Colin Vincent'!I18+'Henry, Colin Vincent'!I19)>0,('Henry, Colin Vincent'!I20+'Henry, Colin Vincent'!I21)>0,('Henry, Colin Vincent'!I22+'Henry, Colin Vincent'!I23)>0,('Henry, Colin Vincent'!I24+'Henry, Colin Vincent'!I25)>0,('Henry, Colin Vincent'!I26+'Henry, Colin Vincent'!I27)>0),AND(('Henry, Colin Vincent'!I30+'Henry, Colin Vincent'!I31)>0,('Henry, Colin Vincent'!I32+'Henry, Colin Vincent'!I33)>0,('Henry, Colin Vincent'!I34+'Henry, Colin Vincent'!I35)>0,('Henry, Colin Vincent'!I36+'Henry, Colin Vincent'!I37)>0,('Henry, Colin Vincent'!I38+'Henry, Colin Vincent'!I39)>0,('Henry, Colin Vincent'!I40+'Henry, Colin Vincent'!I41)>0,('Henry, Colin Vincent'!I42+'Henry, Colin Vincent'!I43)>0)),"Yes","") | I10: =IF('Henry, Colin Vincent'!N49>40,"Yes","") | J10: =IF(OR(AND(SUM('Henry, Colin Vincent'!I14:I27)>0,SUM('Henry, Colin Vincent'!I14:I27)<40),AND(SUM('Henry, Colin Vincent'!I30:I43)>0,SUM('Henry, Colin Vincent'!I30:I43)<40)),"Yes","") | K10: =SUMPRODUCT(('Henry, Colin Vincent'!I14:I48>0)*('Henry, Colin Vincent'!I14:I48<8)) | L10: =IF('Henry, Colin Vincent'!Q50<5,"Yes","") | M10: =IF(AND('Henry, Colin Vincent'!I49>0,'Henry, Colin Vincent'!I49<80),"Yes","") | N10: =IF(OR(F10>0,G10="Yes",H10="Yes",I10="Yes"),"⚠️ OVERWORK",IF(OR(J10="Yes",K10>0,L10="Yes",M10="Yes"),"🔻 UNDERWORK","✓ OK"))
A11: 7 | B11: Pearson, Roslyn Andrea | C11: 755 | D11: ='Pearson, Roslyn Andrea'!I49 | E11: ='Pearson, Roslyn Andrea'!Q50 | F11: =SUMPRODUCT((('Pearson, Roslyn Andrea'!I14+'Pearson, Roslyn Andrea'!I15)>12)*1)+SUMPRODUCT((('Pearson, Roslyn Andrea'!I16+'Pearson, Roslyn Andrea'!I17)>12)*1)+SUMPRODUCT((('Pearson, Roslyn Andrea'!I18+'Pearson, Roslyn Andrea'!I19)>12)*1)+SUMPRODUCT((('Pearson, Roslyn Andrea'!I20+'Pearson, Roslyn Andrea'!I21)>12)*1)+SUMPRODUCT((('Pearson, Roslyn Andrea'!I22+'Pearson, Roslyn Andrea'!I23)>12)*1)+SUMPRODUCT((('Pearson, Roslyn Andrea'!I24+'Pearson, Roslyn Andrea'!I25)>12)*1)+SUMPRODUCT((('Pearson, Roslyn Andrea'!I26+'Pearson, Roslyn Andrea'!I27)>12)*1)+SUMPRODUCT((('Pearson, Roslyn Andrea'!I30+'Pearson, Roslyn Andrea'!I31)>12)*1)+SUMPRODUCT((('Pearson, Roslyn Andrea'!I32+'Pearson, Roslyn Andrea'!I33)>12)*1)+SUMPRODUCT((('Pearson, Roslyn Andrea'!I34+'Pearson, Roslyn Andrea'!I35)>12)*1)+SUMPRODUCT((('Pearson, Roslyn Andrea'!I36+'Pearson, Roslyn Andrea'!I37)>12)*1)+SUMPRODUCT((('Pearson, Roslyn Andrea'!I38+'Pearson, Roslyn Andrea'!I39)>12)*1)+SUMPRODUCT((('Pearson, Roslyn Andrea'!I40+'Pearson, Roslyn Andrea'!I41)>12)*1)+SUMPRODUCT((('Pearson, Roslyn Andrea'!I42+'Pearson, Roslyn Andrea'!I43)>12)*1)+SUMPRODUCT((('Pearson, Roslyn Andrea'!I45+'Pearson, Roslyn Andrea'!I46)>12)*1)+SUMPRODUCT((('Pearson, Roslyn Andrea'!I47+'Pearson, Roslyn Andrea'!I48)>12)*1) | G11: =IF(MAX(SUM('Pearson, Roslyn Andrea'!I14:I27),SUM('Pearson, Roslyn Andrea'!I30:I43))>60,"Yes","") | H11: =IF(OR(AND(('Pearson, Roslyn Andrea'!I14+'Pearson, Roslyn Andrea'!I15)>0,('Pearson, Roslyn Andrea'!I16+'Pearson, Roslyn Andrea'!I17)>0,('Pearson, Roslyn Andrea'!I18+'Pearson, Roslyn Andrea'!I19)>0,('Pearson, Roslyn Andrea'!I20+'Pearson, Roslyn Andrea'!I21)>0,('Pearson, Roslyn Andrea'!I22+'Pearson, Roslyn Andrea'!I23)>0,('Pearson, Roslyn Andrea'!I24+'Pearson, Roslyn Andrea'!I25)>0,('Pearson, Roslyn Andrea'!I26+'Pearson, Roslyn Andrea'!I27)>0),AND(('Pearson, Roslyn Andrea'!I30+'Pearson, Roslyn Andrea'!I31)>0,('Pearson, Roslyn Andrea'!I32+'Pearson, Roslyn Andrea'!I33)>0,('Pearson, Roslyn Andrea'!I34+'Pearson, Roslyn Andrea'!I35)>0,('Pearson, Roslyn Andrea'!I36+'Pearson, Roslyn Andrea'!I37)>0,('Pearson, Roslyn Andrea'!I38+'Pearson, Roslyn Andrea'!I39)>0,('Pearson, Roslyn Andrea'!I40+'Pearson, Roslyn Andrea'!I41)>0,('Pearson, Roslyn Andrea'!I42+'Pearson, Roslyn Andrea'!I43)>0)),"Yes","") | I11: =IF('Pearson, Roslyn Andrea'!N49>40,"Yes","") | J11: =IF(OR(AND(SUM('Pearson, Roslyn Andrea'!I14:I27)>0,SUM('Pearson, Roslyn Andrea'!I14:I27)<40),AND(SUM('Pearson, Roslyn Andrea'!I30:I43)>0,SUM('Pearson, Roslyn Andrea'!I30:I43)<40)),"Yes","") | K11: =SUMPRODUCT(('Pearson, Roslyn Andrea'!I14:I48>0)*('Pearson, Roslyn Andrea'!I14:I48<8)) | L11: =IF('Pearson, Roslyn Andrea'!Q50<5,"Yes","") | M11: =IF(AND('Pearson, Roslyn Andrea'!I49>0,'Pearson, Roslyn Andrea'!I49<80),"Yes","") | N11: =IF(OR(F11>0,G11="Yes",H11="Yes",I11="Yes"),"⚠️ OVERWORK",IF(OR(J11="Yes",K11>0,L11="Yes",M11="Yes"),"🔻 UNDERWORK","✓ OK"))
A12: 8 | B12: Proffitt, Clive Rodericks | C12: 229 | D12: ='Proffitt, Clive Rodericks'!I49 | E12: ='Proffitt, Clive Rodericks'!Q50 | F12: =SUMPRODUCT((('Proffitt, Clive Rodericks'!I14+'Proffitt, Clive Rodericks'!I15)>12)*1)+SUMPRODUCT((('Proffitt, Clive Rodericks'!I16+'Proffitt, Clive Rodericks'!I17)>12)*1)+SUMPRODUCT((('Proffitt, Clive Rodericks'!I18+'Proffitt, Clive Rodericks'!I19)>12)*1)+SUMPRODUCT((('Proffitt, Clive Rodericks'!I20+'Proffitt, Clive Rodericks'!I21)>12)*1)+SUMPRODUCT((('Proffitt, Clive Rodericks'!I22+'Proffitt, Clive Rodericks'!I23)>12)*1)+SUMPRODUCT((('Proffitt, Clive Rodericks'!I24+'Proffitt, Clive Rodericks'!I25)>12)*1)+SUMPRODUCT((('Proffitt, Clive Rodericks'!I26+'Proffitt, Clive Rodericks'!I27)>12)*1)+SUMPRODUCT((('Proffitt, Clive Rodericks'!I30+'Proffitt, Clive Rodericks'!I31)>12)*1)+SUMPRODUCT((('Proffitt, Clive Rodericks'!I32+'Proffitt, Clive Rodericks'!I33)>12)*1)+SUMPRODUCT((('Proffitt, Clive Rodericks'!I34+'Proffitt, Clive Rodericks'!I35)>12)*1)+SUMPRODUCT((('Proffitt, Clive Rodericks'!I36+'Proffitt, Clive Rodericks'!I37)>12)*1)+SUMPRODUCT((('Proffitt, Clive Rodericks'!I38+'Proffitt, Clive Rodericks'!I39)>12)*1)+SUMPRODUCT((('Proffitt, Clive Rodericks'!I40+'Proffitt, Clive Rodericks'!I41)>12)*1)+SUMPRODUCT((('Proffitt, Clive Rodericks'!I42+'Proffitt, Clive Rodericks'!I43)>12)*1)+SUMPRODUCT((('Proffitt, Clive Rodericks'!I45+'Proffitt, Clive Rodericks'!I46)>12)*1)+SUMPRODUCT((('Proffitt, Clive Rodericks'!I47+'Proffitt, Clive Rodericks'!I48)>12)*1) | G12: =IF(MAX(SUM('Proffitt, Clive Rodericks'!I14:I27),SUM('Proffitt, Clive Rodericks'!I30:I43))>60,"Yes","") | H12: =IF(OR(AND(('Proffitt, Clive Rodericks'!I14+'Proffitt, Clive Rodericks'!I15)>0,('Proffitt, Clive Rodericks'!I16+'Proffitt, Clive Rodericks'!I17)>0,('Proffitt, Clive Rodericks'!I18+'Proffitt, Clive Rodericks'!I19)>0,('Proffitt, Clive Rodericks'!I20+'Proffitt, Clive Rodericks'!I21)>0,('Proffitt, Clive Rodericks'!I22+'Proffitt, Clive Rodericks'!I23)>0,('Proffitt, Clive Rodericks'!I24+'Proffitt, Clive Rodericks'!I25)>0,('Proffitt, Clive Rodericks'!I26+'Proffitt, Clive Rodericks'!I27)>0),AND(('Proffitt, Clive Rodericks'!I30+'Proffitt, Clive Rodericks'!I31)>0,('Proffitt, Clive Rodericks'!I32+'Proffitt, Clive Rodericks'!I33)>0,('Proffitt, Clive Rodericks'!I34+'Proffitt, Clive Rodericks'!I35)>0,('Proffitt, Clive Rodericks'!I36+'Proffitt, Clive Rodericks'!I37)>0,('Proffitt, Clive Rodericks'!I38+'Proffitt, Clive Rodericks'!I39)>0,('Proffitt, Clive Rodericks'!I40+'Proffitt, Clive Rodericks'!I41)>0,('Proffitt, Clive Rodericks'!I42+'Proffitt, Clive Rodericks'!I43)>0)),"Yes","") | I12: =IF('Proffitt, Clive Rodericks'!N49>40,"Yes","") | J12: =IF(OR(AND(SUM('Proffitt, Clive Rodericks'!I14:I27)>0,SUM('Proffitt, Clive Rodericks'!I14:I27)<40),AND(SUM('Proffitt, Clive Rodericks'!I30:I43)>0,SUM('Proffitt, Clive Rodericks'!I30:I43)<40)),"Yes","") | K12: =SUMPRODUCT(('Proffitt, Clive Rodericks'!I14:I48>0)*('Proffitt, Clive Rodericks'!I14:I48<8)) | L12: =IF('Proffitt, Clive Rodericks'!Q50<5,"Yes","") | M12: =IF(AND('Proffitt, Clive Rodericks'!I49>0,'Proffitt, Clive Rodericks'!I49<80),"Yes","") | N12: =IF(OR(F12>0,G12="Yes",H12="Yes",I12="Yes"),"⚠️ OVERWORK",IF(OR(J12="Yes",K12>0,L12="Yes",M12="Yes"),"🔻 UNDERWORK","✓ OK"))
A13: 9 | B13: Ridley, Theresa | C13: 564 | D13: ='Ridley, Theresa'!I49 | E13: ='Ridley, Theresa'!Q50 | F13: =SUMPRODUCT((('Ridley, Theresa'!I14+'Ridley, Theresa'!I15)>12)*1)+SUMPRODUCT((('Ridley, Theresa'!I16+'Ridley, Theresa'!I17)>12)*1)+SUMPRODUCT((('Ridley, Theresa'!I18+'Ridley, Theresa'!I19)>12)*1)+SUMPRODUCT((('Ridley, Theresa'!I20+'Ridley, Theresa'!I21)>12)*1)+SUMPRODUCT((('Ridley, Theresa'!I22+'Ridley, Theresa'!I23)>12)*1)+SUMPRODUCT((('Ridley, Theresa'!I24+'Ridley, Theresa'!I25)>12)*1)+SUMPRODUCT((('Ridley, Theresa'!I26+'Ridley, Theresa'!I27)>12)*1)+SUMPRODUCT((('Ridley, Theresa'!I30+'Ridley, Theresa'!I31)>12)*1)+SUMPRODUCT((('Ridley, Theresa'!I32+'Ridley, Theresa'!I33)>12)*1)+SUMPRODUCT((('Ridley, Theresa'!I34+'Ridley, Theresa'!I35)>12)*1)+SUMPRODUCT((('Ridley, Theresa'!I36+'Ridley, Theresa'!I37)>12)*1)+SUMPRODUCT((('Ridley, Theresa'!I38+'Ridley, Theresa'!I39)>12)*1)+SUMPRODUCT((('Ridley, Theresa'!I40+'Ridley, Theresa'!I41)>12)*1)+SUMPRODUCT((('Ridley, Theresa'!I42+'Ridley, Theresa'!I43)>12)*1)+SUMPRODUCT((('Ridley, Theresa'!I45+'Ridley, Theresa'!I46)>12)*1)+SUMPRODUCT((('Ridley, Theresa'!I47+'Ridley, Theresa'!I48)>12)*1) | G13: =IF(MAX(SUM('Ridley, Theresa'!I14:I27),SUM('Ridley, Theresa'!I30:I43))>60,"Yes","") | H13: =IF(OR(AND(('Ridley, Theresa'!I14+'Ridley, Theresa'!I15)>0,('Ridley, Theresa'!I16+'Ridley, Theresa'!I17)>0,('Ridley, Theresa'!I18+'Ridley, Theresa'!I19)>0,('Ridley, Theresa'!I20+'Ridley, Theresa'!I21)>0,('Ridley, Theresa'!I22+'Ridley, Theresa'!I23)>0,('Ridley, Theresa'!I24+'Ridley, Theresa'!I25)>0,('Ridley, Theresa'!I26+'Ridley, Theresa'!I27)>0),AND(('Ridley, Theresa'!I30+'Ridley, Theresa'!I31)>0,('Ridley, Theresa'!I32+'Ridley, Theresa'!I33)>0,('Ridley, Theresa'!I34+'Ridley, Theresa'!I35)>0,('Ridley, Theresa'!I36+'Ridley, Theresa'!I37)>0,('Ridley, Theresa'!I38+'Ridley, Theresa'!I39)>0,('Ridley, Theresa'!I40+'Ridley, Theresa'!I41)>0,('Ridley, Theresa'!I42+'Ridley, Theresa'!I43)>0)),"Yes","") | I13: =IF('Ridley, Theresa'!N49>40,"Yes","") | J13: =IF(OR(AND(SUM('Ridley, Theresa'!I14:I27)>0,SUM('Ridley, Theresa'!I14:I27)<40),AND(SUM('Ridley, Theresa'!I30:I43)>0,SUM('Ridley, Theresa'!I30:I43)<40)),"Yes","") | K13: =SUMPRODUCT(('Ridley, Theresa'!I14:I48>0)*('Ridley, Theresa'!I14:I48<8)) | L13: =IF('Ridley, Theresa'!Q50<5,"Yes","") | M13: =IF(AND('Ridley, Theresa'!I49>0,'Ridley, Theresa'!I49<80),"Yes","") | N13: =IF(OR(F13>0,G13="Yes",H13="Yes",I13="Yes"),"⚠️ OVERWORK",IF(OR(J13="Yes",K13>0,L13="Yes",M13="Yes"),"🔻 UNDERWORK","✓ OK"))
A14: 10 | B14: Spencer, Shemar Ethy | C14: 5489 | D14: ='Spencer, Shemar Ethy'!I49 | E14: ='Spencer, Shemar Ethy'!Q50 | F14: =SUMPRODUCT((('Spencer, Shemar Ethy'!I14+'Spencer, Shemar Ethy'!I15)>12)*1)+SUMPRODUCT((('Spencer, Shemar Ethy'!I16+'Spencer, Shemar Ethy'!I17)>12)*1)+SUMPRODUCT((('Spencer, Shemar Ethy'!I18+'Spencer, Shemar Ethy'!I19)>12)*1)+SUMPRODUCT((('Spencer, Shemar Ethy'!I20+'Spencer, Shemar Ethy'!I21)>12)*1)+SUMPRODUCT((('Spencer, Shemar Ethy'!I22+'Spencer, Shemar Ethy'!I23)>12)*1)+SUMPRODUCT((('Spencer, Shemar Ethy'!I24+'Spencer, Shemar Ethy'!I25)>12)*1)+SUMPRODUCT((('Spencer, Shemar Ethy'!I26+'Spencer, Shemar Ethy'!I27)>12)*1)+SUMPRODUCT((('Spencer, Shemar Ethy'!I30+'Spencer, Shemar Ethy'!I31)>12)*1)+SUMPRODUCT((('Spencer, Shemar Ethy'!I32+'Spencer, Shemar Ethy'!I33)>12)*1)+SUMPRODUCT((('Spencer, Shemar Ethy'!I34+'Spencer, Shemar Ethy'!I35)>12)*1)+SUMPRODUCT((('Spencer, Shemar Ethy'!I36+'Spencer, Shemar Ethy'!I37)>12)*1)+SUMPRODUCT((('Spencer, Shemar Ethy'!I38+'Spencer, Shemar Ethy'!I39)>12)*1)+SUMPRODUCT((('Spencer, Shemar Ethy'!I40+'Spencer, Shemar Ethy'!I41)>12)*1)+SUMPRODUCT((('Spencer, Shemar Ethy'!I42+'Spencer, Shemar Ethy'!I43)>12)*1)+SUMPRODUCT((('Spencer, Shemar Ethy'!I45+'Spencer, Shemar Ethy'!I46)>12)*1)+SUMPRODUCT((('Spencer, Shemar Ethy'!I47+'Spencer, Shemar Ethy'!I48)>12)*1) | G14: =IF(MAX(SUM('Spencer, Shemar Ethy'!I14:I27),SUM('Spencer, Shemar Ethy'!I30:I43))>60,"Yes","") | H14: =IF(OR(AND(('Spencer, Shemar Ethy'!I14+'Spencer, Shemar Ethy'!I15)>0,('Spencer, Shemar Ethy'!I16+'Spencer, Shemar Ethy'!I17)>0,('Spencer, Shemar Ethy'!I18+'Spencer, Shemar Ethy'!I19)>0,('Spencer, Shemar Ethy'!I20+'Spencer, Shemar Ethy'!I21)>0,('Spencer, Shemar Ethy'!I22+'Spencer, Shemar Ethy'!I23)>0,('Spencer, Shemar Ethy'!I24+'Spencer, Shemar Ethy'!I25)>0,('Spencer, Shemar Ethy'!I26+'Spencer, Shemar Ethy'!I27)>0),AND(('Spencer, Shemar Ethy'!I30+'Spencer, Shemar Ethy'!I31)>0,('Spencer, Shemar Ethy'!I32+'Spencer, Shemar Ethy'!I33)>0,('Spencer, Shemar Ethy'!I34+'Spencer, Shemar Ethy'!I35)>0,('Spencer, Shemar Ethy'!I36+'Spencer, Shemar Ethy'!I37)>0,('Spencer, Shemar Ethy'!I38+'Spencer, Shemar Ethy'!I39)>0,('Spencer, Shemar Ethy'!I40+'Spencer, Shemar Ethy'!I41)>0,('Spencer, Shemar Ethy'!I42+'Spencer, Shemar Ethy'!I43)>0)),"Yes","") | I14: =IF('Spencer, Shemar Ethy'!N49>40,"Yes","") | J14: =IF(OR(AND(SUM('Spencer, Shemar Ethy'!I14:I27)>0,SUM('Spencer, Shemar Ethy'!I14:I27)<40),AND(SUM('Spencer, Shemar Ethy'!I30:I43)>0,SUM('Spencer, Shemar Ethy'!I30:I43)<40)),"Yes","") | K14: =SUMPRODUCT(('Spencer, Shemar Ethy'!I14:I48>0)*('Spencer, Shemar Ethy'!I14:I48<8)) | L14: =IF('Spencer, Shemar Ethy'!Q50<5,"Yes","") | M14: =IF(AND('Spencer, Shemar Ethy'!I49>0,'Spencer, Shemar Ethy'!I49<80),"Yes","") | N14: =IF(OR(F14>0,G14="Yes",H14="Yes",I14="Yes"),"⚠️ OVERWORK",IF(OR(J14="Yes",K14>0,L14="Yes",M14="Yes"),"🔻 UNDERWORK","✓ OK"))
A15: 11 | B15: Whinfield, Merlyn Beatrice | C15: 3345 | D15: ='Whinfield, Merlyn Beatrice'!I49 | E15: ='Whinfield, Merlyn Beatrice'!Q50 | F15: =SUMPRODUCT((('Whinfield, Merlyn Beatrice'!I14+'Whinfield, Merlyn Beatrice'!I15)>12)*1)+SUMPRODUCT((('Whinfield, Merlyn Beatrice'!I16+'Whinfield, Merlyn Beatrice'!I17)>12)*1)+SUMPRODUCT((('Whinfield, Merlyn Beatrice'!I18+'Whinfield, Merlyn Beatrice'!I19)>12)*1)+SUMPRODUCT((('Whinfield, Merlyn Beatrice'!I20+'Whinfield, Merlyn Beatrice'!I21)>12)*1)+SUMPRODUCT((('Whinfield, Merlyn Beatrice'!I22+'Whinfield, Merlyn Beatrice'!I23)>12)*1)+SUMPRODUCT((('Whinfield, Merlyn Beatrice'!I24+'Whinfield, Merlyn Beatrice'!I25)>12)*1)+SUMPRODUCT((('Whinfield, Merlyn Beatrice'!I26+'Whinfield, Merlyn Beatrice'!I27)>12)*1)+SUMPRODUCT((('Whinfield, Merlyn Beatrice'!I30+'Whinfield, Merlyn Beatrice'!I31)>12)*1)+SUMPRODUCT((('Whinfield, Merlyn Beatrice'!I32+'Whinfield, Merlyn Beatrice'!I33)>12)*1)+SUMPRODUCT((('Whinfield, Merlyn Beatrice'!I34+'Whinfield, Merlyn Beatrice'!I35)>12)*1)+SUMPRODUCT((('Whinfield, Merlyn Beatrice'!I36+'Whinfield, Merlyn Beatrice'!I37)>12)*1)+SUMPRODUCT((('Whinfield, Merlyn Beatrice'!I38+'Whinfield, Merlyn Beatrice'!I39)>12)*1)+SUMPRODUCT((('Whinfield, Merlyn Beatrice'!I40+'Whinfield, Merlyn Beatrice'!I41)>12)*1)+SUMPRODUCT((('Whinfield, Merlyn Beatrice'!I42+'Whinfield, Merlyn Beatrice'!I43)>12)*1)+SUMPRODUCT((('Whinfield, Merlyn Beatrice'!I45+'Whinfield, Merlyn Beatrice'!I46)>12)*1)+SUMPRODUCT((('Whinfield, Merlyn Beatrice'!I47+'Whinfield, Merlyn Beatrice'!I48)>12)*1) | G15: =IF(MAX(SUM('Whinfield, Merlyn Beatrice'!I14:I27),SUM('Whinfield, Merlyn Beatrice'!I30:I43))>60,"Yes","") | H15: =IF(OR(AND(('Whinfield, Merlyn Beatrice'!I14+'Whinfield, Merlyn Beatrice'!I15)>0,('Whinfield, Merlyn Beatrice'!I16+'Whinfield, Merlyn Beatrice'!I17)>0,('Whinfield, Merlyn Beatrice'!I18+'Whinfield, Merlyn Beatrice'!I19)>0,('Whinfield, Merlyn Beatrice'!I20+'Whinfield, Merlyn Beatrice'!I21)>0,('Whinfield, Merlyn Beatrice'!I22+'Whinfield, Merlyn Beatrice'!I23)>0,('Whinfield, Merlyn Beatrice'!I24+'Whinfield, Merlyn Beatrice'!I25)>0,('Whinfield, Merlyn Beatrice'!I26+'Whinfield, Merlyn Beatrice'!I27)>0),AND(('Whinfield, Merlyn Beatrice'!I30+'Whinfield, Merlyn Beatrice'!I31)>0,('Whinfield, Merlyn Beatrice'!I32+'Whinfield, Merlyn Beatrice'!I33)>0,('Whinfield, Merlyn Beatrice'!I34+'Whinfield, Merlyn Beatrice'!I35)>0,('Whinfield, Merlyn Beatrice'!I36+'Whinfield, Merlyn Beatrice'!I37)>0,('Whinfield, Merlyn Beatrice'!I38+'Whinfield, Merlyn Beatrice'!I39)>0,('Whinfield, Merlyn Beatrice'!I40+'Whinfield, Merlyn Beatrice'!I41)>0,('Whinfield, Merlyn Beatrice'!I42+'Whinfield, Merlyn Beatrice'!I43)>0)),"Yes","") | I15: =IF('Whinfield, Merlyn Beatrice'!N49>40,"Yes","") | J15: =IF(OR(AND(SUM('Whinfield, Merlyn Beatrice'!I14:I27)>0,SUM('Whinfield, Merlyn Beatrice'!I14:I27)<40),AND(SUM('Whinfield, Merlyn Beatrice'!I30:I43)>0,SUM('Whinfield, Merlyn Beatrice'!I30:I43)<40)),"Yes","") | K15: =SUMPRODUCT(('Whinfield, Merlyn Beatrice'!I14:I48>0)*('Whinfield, Merlyn Beatrice'!I14:I48<8)) | L15: =IF('Whinfield, Merlyn Beatrice'!Q50<5,"Yes","") | M15: =IF(AND('Whinfield, Merlyn Beatrice'!I49>0,'Whinfield, Merlyn Beatrice'!I49<80),"Yes","") | N15: =IF(OR(F15>0,G15="Yes",H15="Yes",I15="Yes"),"⚠️ OVERWORK",IF(OR(J15="Yes",K15>0,L15="Yes",M15="Yes"),"🔻 UNDERWORK","✓ OK"))
A17: SUMMARY
A18: ⚠️ Overwork Flags: | C18: =COUNTIF(N5:N16,"⚠️ OVERWORK")
A19: 🔻 Underwork Flags: | C19: =COUNTIF(N5:N16,"🔻 UNDERWORK")
A20: ✓ OK: | C20: =COUNTIF(N5:N16,"✓ OK")
A22: THRESHOLDS:
A23: Overwork: Daily >12hrs | Weekly >60hrs | 7+ consecutive days | OT >40hrs/period
A24: Underwork: Weekly <40hrs | Daily <8hrs (when worked) | <5 days/week | Period <80hrs total

Sheet upload
A1: PAYROLL_ID | B1: EMPLOYEENAME | C1: INCOME_CODE | D1: HOURS | E1: DOLLARS
A2: ='Payroll Summary'!B4 | B2: ='Payroll Summary'!A4 | C2: AL | D2: ='Payroll Summary'!J4
A3: =A2 | B3: =B2 | C3: BS | D3: ='Payroll Summary'!D4
A4: =A3 | B4: =B3 | C4: DT | D4: ='Payroll Summary'!F4
A5: =A4 | B5: =B4 | C5: R | D5: ='Payroll Summary'!G4
A6: =A5 | B6: =B5 | C6: I | D6: ='Payroll Summary'!O4
A7: =A6 | B7: =B6 | C7: MA | D7: ='Payroll Summary'!I4
A8: =A7 | B8: =B7 | C8: OT | D8: ='Payroll Summary'!E4
A9: =A8 | B9: =B8 | C9: RA | D9: ='Payroll Summary'!H4
A10: =A9 | B10: =B9 | C10: STATIONALLOWANC | D10: ='Payroll Summary'!L4
A11: =A10 | B11: =B10 | C11: GAS | D11: ='Payroll Summary'!M4
A12: =A11 | B12: =B11 | C12: PRVLED | D12: ='Payroll Summary'!N4
A13: ='Payroll Summary'!B5 | B13: ='Payroll Summary'!A5 | C13: AL | D13: ='Payroll Summary'!J5
A14: =A13 | B14: =B13 | C14: BS | D14: ='Payroll Summary'!D5
A15: =A14 | B15: =B14 | C15: DT | D15: ='Payroll Summary'!F5
A16: =A15 | B16: =B15 | C16: R | D16: ='Payroll Summary'!G5
A17: =A16 | B17: =B16 | C17: I | D17: ='Payroll Summary'!O5
A18: =A17 | B18: =B17 | C18: MA | D18: ='Payroll Summary'!I5
A19: =A18 | B19: =B18 | C19: OT | D19: ='Payroll Summary'!E5
A20: =A19 | B20: =B19 | C20: RA | D20: ='Payroll Summary'!H5
A21: =A20 | B21: =B20 | C21: STATIONALLOWANC | D21: ='Payroll Summary'!L5
A22: =A21 | B22: =B21 | C22: GAS | D22: ='Payroll Summary'!M5
A23: =A22 | B23: =B22 | C23: PRVLED | D23: ='Payroll Summary'!N5
A24: ='Payroll Summary'!B6 | B24: ='Payroll Summary'!A6 | C24: AL | D24: ='Payroll Summary'!J6
A25: =A24 | B25: =B24 | C25: BS | D25: ='Payroll Summary'!D6
A26: =A25 | B26: =B25 | C26: DT | D26: ='Payroll Summary'!F6
A27: =A26 | B27: =B26 | C27: R | D27: ='Payroll Summary'!G6
A28: =A27 | B28: =B27 | C28: I | D28: ='Payroll Summary'!O6
A29: =A28 | B29: =B28 | C29: MA | D29: ='Payroll Summary'!I6
A30: =A29 | B30: =B29 | C30: OT | D30: ='Payroll Summary'!E6
A31: =A30 | B31: =B30 | C31: RA | D31: ='Payroll Summary'!H6
A32: =A31 | B32: =B31 | C32: STATIONALLOWANC | D32: ='Payroll Summary'!L6
A33: =A32 | B33: =B32 | C33: GAS | D33: ='Payroll Summary'!M6
A34: =A33 | B34: =B33 | C34: PRVLED | D34: ='Payroll Summary'!N6
A35: ='Payroll Summary'!B7 | B35: ='Payroll Summary'!A7 | C35: AL | D35: ='Payroll Summary'!J7
A36: =A35 | B36: =B35 | C36: BS | D36: ='Payroll Summary'!D7
A37: =A36 | B37: =B36 | C37: DT | D37: ='Payroll Summary'!F7
A38: =A37 | B38: =B37 | C38: R | D38: ='Payroll Summary'!G7
A39: =A38 | B39: =B38 | C39: I | D39: ='Payroll Summary'!O7
A40: =A39 | B40: =B39 | C40: MA | D40: ='Payroll Summary'!I7
...

Sheet Payroll Summary
A1: Master Payroll Summary
A3: Name | B3: Number | C3: Agency | D3: Basic Hrs | E3: Overtime Hrs | F3: Hol Hrs | G3: Responsibilities | H3: Risk | I3: Meals | J3: Annual Leave Hrs | K3: Days Worked | L3: Station Allow | M3: Gas Allow | N3: Project Mgmt Allow | O3: Incentive
A4: ='Daniels, John Llewellyn'!M5 | B4: ='Daniels, John Llewellyn'!M4 | C4: ='Daniels, John Llewellyn'!O7 | D4: ='Daniels, John Llewellyn'!M49 | E4: ='Daniels, John Llewellyn'!N49 | F4: ='Daniels, John Llewellyn'!O49 | G4: ='Daniels, John Llewellyn'!P49 | H4: ='Daniels, John Llewellyn'!Q49 | I4: ='Daniels, John Llewellyn'!R49 | J4: ='Daniels, John Llewellyn'!S49 | K4: ='Daniels, John Llewellyn'!Q50 | L4: 0 | M4: 0 | N4: 0 | O4: 0
A5: ='Ridley, Theresa'!M5 | B5: ='Ridley, Theresa'!M4 | C5: ='Ridley, Theresa'!O7 | D5: ='Ridley, Theresa'!M49 | E5: ='Ridley, Theresa'!N49 | F5: ='Ridley, Theresa'!O49 | G5: ='Ridley, Theresa'!P49 | H5: ='Ridley, Theresa'!Q49 | I5: ='Ridley, Theresa'!R49 | J5: ='Ridley, Theresa'!S49 | K5: ='Ridley, Theresa'!Q50 | L5: 0 | M5: 0 | N5: 0 | O5: 0
A6: ='Browne, Francianna Milissa'!M5 | B6: ='Browne, Francianna Milissa'!M4 | C6: ='Browne, Francianna Milissa'!O7 | D6: ='Browne, Francianna Milissa'!M49 | E6: ='Browne, Francianna Milissa'!N49 | F6: ='Browne, Francianna Milissa'!O49 | G6: ='Browne, Francianna Milissa'!P49 | H6: ='Browne, Francianna Milissa'!Q49 | I6: ='Browne, Francianna Milissa'!R49 | J6: ='Browne, Francianna Milissa'!S49 | K6: ='Browne, Francianna Milissa'!Q50 | L6: 0 | M6: 0 | N6: 0 | O6: 0
A7: ='Henry, Colin Vincent'!M5 | B7: ='Henry, Colin Vincent'!M4 | C7: ='Henry, Colin Vincent'!O7 | D7: ='Henry, Colin Vincent'!M49 | E7: ='Henry, Colin Vincent'!N49 | F7: ='Henry, Colin Vincent'!O49 | G7: ='Henry, Colin Vincent'!P49 | H7: ='Henry, Colin Vincent'!Q49 | I7: ='Henry, Colin Vincent'!R49 | J7: ='Henry, Colin Vincent'!S49 | K7: ='Henry, Colin Vincent'!Q50 | L7: 0 | M7: 0 | N7: 0 | O7: 0
A8: ='Dorsett, Susan Patricia'!M5 | B8: ='Dorsett, Susan Patricia'!M4 | C8: ='Dorsett, Susan Patricia'!O7 | D8: ='Dorsett, Susan Patricia'!M49 | E8: ='Dorsett, Susan Patricia'!N49 | F8: ='Dorsett, Susan Patricia'!O49 | G8: ='Dorsett, Susan Patricia'!P49 | H8: ='Dorsett, Susan Patricia'!Q49 | I8: ='Dorsett, Susan Patricia'!R49 | J8: ='Dorsett, Susan Patricia'!S49 | K8: ='Dorsett, Susan Patricia'!Q50 | L8: 0 | M8: 0 | N8: 0 | O8: 0
A9: ='Pearson, Roslyn Andrea'!M5 | B9: ='Pearson, Roslyn Andrea'!M4 | C9: ='Pearson, Roslyn Andrea'!O7 | D9: ='Pearson, Roslyn Andrea'!M49 | E9: ='Pearson, Roslyn Andrea'!N49 | F9: ='Pearson, Roslyn Andrea'!O49 | G9: ='Pearson, Roslyn Andrea'!P49 | H9: ='Pearson, Roslyn Andrea'!Q49 | I9: ='Pearson, Roslyn Andrea'!R49 | J9: ='Pearson, Roslyn Andrea'!S49 | K9: ='Pearson, Roslyn Andrea'!Q50 | L9: 0 | M9: 0 | N9: 0 | O9: 0
A10: ='Barnes, Mauva'!M5 | B10: ='Barnes, Mauva'!M4 | C10: ='Barnes, Mauva'!O7 | D10: ='Barnes, Mauva'!M49 | E10: ='Barnes, Mauva'!N49 | F10: ='Barnes, Mauva'!O49 | G10: ='Barnes, Mauva'!P49 | H10: ='Barnes, Mauva'!Q49 | I10: ='Barnes, Mauva'!R49 | J10: ='Barnes, Mauva'!S49 | K10: ='Barnes, Mauva'!Q50 | L10: 0 | M10: 0 | N10: 0 | O10: 0
A11: ='Proffitt, Clive Rodericks'!M5 | B11: ='Proffitt, Clive Rodericks'!M4 | C11: ='Proffitt, Clive Rodericks'!O7 | D11: ='Proffitt, Clive Rodericks'!M49 | E11: ='Proffitt, Clive Rodericks'!N49 | F11: ='Proffitt, Clive Rodericks'!O49 | G11: ='Proffitt, Clive Rodericks'!P49 | H11: ='Proffitt, Clive Rodericks'!Q49 | I11: ='Proffitt, Clive Rodericks'!R49 | J11: ='Proffitt, Clive Rodericks'!S49 | K11: ='Proffitt, Clive Rodericks'!Q50 | L11: 0 | M11: 0 | N11: 0 | O11: 0
A12: ='Spencer, Shemar Ethy'!M5 | B12: ='Spencer, Shemar Ethy'!M4 | C12: ='Spencer, Shemar Ethy'!O7 | D12: ='Spencer, Shemar Ethy'!M49 | E12: ='Spencer, Shemar Ethy'!N49 | F12: ='Spencer, Shemar Ethy'!O49 | G12: ='Spencer, Shemar Ethy'!P49 | H12: ='Spencer, Shemar Ethy'!Q49 | I12: ='Spencer, Shemar Ethy'!R49 | J12: ='Spencer, Shemar Ethy'!S49 | K12: ='Spencer, Shemar Ethy'!Q50 | L12: 0 | M12: 0 | N12: 0 | O12: 0
A13: ='Whinfield, Merlyn Beatrice'!M5 | B13: ='Whinfield, Merlyn Beatrice'!M4 | C13: ='Whinfield, Merlyn Beatrice'!O7 | D13: ='Whinfield, Merlyn Beatrice'!M49 | E13: ='Whinfield, Merlyn Beatrice'!N49 | F13: ='Whinfield, Merlyn Beatrice'!O49 | G13: ='Whinfield, Merlyn Beatrice'!P49 | H13: ='Whinfield, Merlyn Beatrice'!Q49 | I13: ='Whinfield, Merlyn Beatrice'!R49 | J13: ='Whinfield, Merlyn Beatrice'!S49 | K13: ='Whinfield, Merlyn Beatrice'!Q50 | L13: 0 | M13: 0 | N13: 0 | O13: 0
A14: ='David, Jewelle Phillipa'!M5 | B14: ='David, Jewelle Phillipa'!M4 | C14: ='David, Jewelle Phillipa'!O7 | D14: ='David, Jewelle Phillipa'!M49 | E14: ='David, Jewelle Phillipa'!N49 | F14: ='David, Jewelle Phillipa'!O49 | G14: ='David, Jewelle Phillipa'!P49 | H14: ='David, Jewelle Phillipa'!Q49 | I14: ='David, Jewelle Phillipa'!R49 | J14: ='David, Jewelle Phillipa'!S49 | K14: ='David, Jewelle Phillipa'!Q50 | L14: 0 | M14: 0 | N14: 0 | O14: 0
A16: TOTAL | D16: =SUM(D4:D14) | E16: =SUM(E4:E14) | F16: =SUM(F4:F14) | G16: =SUM(G4:G14) | H16: =SUM(H4:H14) | I16: =SUM(I4:I14) | J16: =SUM(J4:J14) | K16: =SUM(K4:K14) | L16: =SUM(L4:L15)

Sheet TEMPLATE
V2: 2025 | Z2: Month: | AA2: 3
V3: =DATE(V2,AA2,1)
C4: Federal Manangement Systems | K4: Employee Number: | V4: Su | W4: M | X4: Tu | Y4: W | Z4: Th | AA4: F | AB4: Sa | AD4: Overtime Options
K5: Employee Name: | M5: Claudette Yearwood | V5: =IF(MONTH($V$3)<>MONTH($V$3-WEEKDAY($V$3,1)+(ROW(V5)-ROW($V$5))*7+(COLUMN(V5)-COLUMN($V$5)+1)),"",$V$3-WEEKDAY($V$3,1)+(ROW(V5)-ROW($V$5))*7+(COLUMN(V5)-COLUMN($V$5)+1)) | W5: =IF(MONTH($V$3)<>MONTH($V$3-WEEKDAY($V$3,1)+(ROW(W5)-ROW($V$5))*7+(COLUMN(W5)-COLUMN($V$5)+1)),"",$V$3-WEEKDAY($V$3,1)+(ROW(W5)-ROW($V$5))*7+(COLUMN(W5)-COLUMN($V$5)+1)) | X5: =IF(MONTH($V$3)<>MONTH($V$3-WEEKDAY($V$3,1)+(ROW(X5)-ROW($V$5))*7+(COLUMN(X5)-COLUMN($V$5)+1)),"",$V$3-WEEKDAY($V$3,1)+(ROW(X5)-ROW($V$5))*7+(COLUMN(X5)-COLUMN($V$5)+1)) | Y5: =IF(MONTH($V$3)<>MONTH($V$3-WEEKDAY($V$3,1)+(ROW(Y5)-ROW($V$5))*7+(COLUMN(Y5)-COLUMN($V$5)+1)),"",$V$3-WEEKDAY($V$3,1)+(ROW(Y5)-ROW($V$5))*7+(COLUMN(Y5)-COLUMN($V$5)+1)) | Z5: =IF(MONTH($V$3)<>MONTH($V$3-WEEKDAY($V$3,1)+(ROW(Z5)-ROW($V$5))*7+(COLUMN(Z5)-COLUMN($V$5)+1)),"",$V$3-WEEKDAY($V$3,1)+(ROW(Z5)-ROW($V$5))*7+(COLUMN(Z5)-COLUMN($V$5)+1)) | AA5: =IF(MONTH($V$3)<>MONTH($V$3-WEEKDAY($V$3,1)+(ROW(AA5)-ROW($V$5))*7+(COLUMN(AA5)-COLUMN($V$5)+1)),"",$V$3-WEEKDAY($V$3,1)+(ROW(AA5)-ROW($V$5))*7+(COLUMN(AA5)-COLUMN($V$5)+1)) | AB5: =IF(MONTH($V$3)<>MONTH($V$3-WEEKDAY($V$3,1)+(ROW(AB5)-ROW($V$5))*7+(COLUMN(AB5)-COLUMN($V$5)+1)),"",$V$3-WEEKDAY($V$3,1)+(ROW(AB5)-ROW($V$5))*7+(COLUMN(AB5)-COLUMN($V$5)+1)) | AE5: TRUE
C6: 120 Peter Rose St | M6: Armed or unarmed | O6: Unarmed | V6: =IF(MONTH($V$3)<>MONTH($V$3-WEEKDAY($V$3,1)+(ROW(V6)-ROW($V$5))*7+(COLUMN(V6)-COLUMN($V$5)+1)),"",$V$3-WEEKDAY($V$3,1)+(ROW(V6)-ROW($V$5))*7+(COLUMN(V6)-COLUMN($V$5)+1)) | W6: =IF(MONTH($V$3)<>MONTH($V$3-WEEKDAY($V$3,1)+(ROW(W6)-ROW($V$5))*7+(COLUMN(W6)-COLUMN($V$5)+1)),"",$V$3-WEEKDAY($V$3,1)+(ROW(W6)-ROW($V$5))*7+(COLUMN(W6)-COLUMN($V$5)+1)) | X6: =IF(MONTH($V$3)<>MONTH($V$3-WEEKDAY($V$3,1)+(ROW(X6)-ROW($V$5))*7+(COLUMN(X6)-COLUMN($V$5)+1)),"",$V$3-WEEKDAY($V$3,1)+(ROW(X6)-ROW($V$5))*7+(COLUMN(X6)-COLUMN($V$5)+1)) | Y6: =IF(MONTH($V$3)<>MONTH($V$3-WEEKDAY($V$3,1)+(ROW(Y6)-ROW($V$5))*7+(COLUMN(Y6)-COLUMN($V$5)+1)),"",$V$3-WEEKDAY($V$3,1)+(ROW(Y6)-ROW($V$5))*7+(COLUMN(Y6)-COLUMN($V$5)+1)) | Z6: =IF(MONTH($V$3)<>MONTH($V$3-WEEKDAY($V$3,1)+(ROW(Z6)-ROW($V$5))*7+(COLUMN(Z6)-COLUMN($V$5)+1)),"",$V$3-WEEKDAY($V$3,1)+(ROW(Z6)-ROW($V$5))*7+(COLUMN(Z6)-COLUMN($V$5)+1)) | AA6: =IF(MONTH($V$3)<>MONTH($V$3-WEEKDAY($V$3,1)+(ROW(AA6)-ROW($V$5))*7+(COLUMN(AA6)-COLUMN($V$5)+1)),"",$V$3-WEEKDAY($V$3,1)+(ROW(AA6)-ROW($V$5))*7+(COLUMN(AA6)-COLUMN($V$5)+1)) | AB6: =IF(MONTH($V$3)<>MONTH($V$3-WEEKDAY($V$3,1)+(ROW(AB6)-ROW($V$5))*7+(COLUMN(AB6)-COLUMN($V$5)+1)),"",$V$3-WEEKDAY($V$3,1)+(ROW(AB6)-ROW($V$5))*7+(COLUMN(AB6)-COLUMN($V$5)+1)) | AD6: After: | AE6: 8 | AF6: Hrs
C7: Queenstown | M7: Agency | O7: Caricom | V7: =IF(MONTH($V$3)<>MONTH($V$3-WEEKDAY($V$3,1)+(ROW(V7)-ROW($V$5))*7+(COLUMN(V7)-COLUMN($V$5)+1)),"",$V$3-WEEKDAY($V$3,1)+(ROW(V7)-ROW($V$5))*7+(COLUMN(V7)-COLUMN($V$5)+1)) | W7: =IF(MONTH($V$3)<>MONTH($V$3-WEEKDAY($V$3,1)+(ROW(W7)-ROW($V$5))*7+(COLUMN(W7)-COLUMN($V$5)+1)),"",$V$3-WEEKDAY($V$3,1)+(ROW(W7)-ROW($V$5))*7+(COLUMN(W7)-COLUMN($V$5)+1)) | X7: =IF(MONTH($V$3)<>MONTH($V$3-WEEKDAY($V$3,1)+(ROW(X7)-ROW($V$5))*7+(COLUMN(X7)-COLUMN($V$5)+1)),"",$V$3-WEEKDAY($V$3,1)+(ROW(X7)-ROW($V$5))*7+(COLUMN(X7)-COLUMN($V$5)+1)) | Y7: =IF(MONTH($V$3)<>MONTH($V$3-WEEKDAY($V$3,1)+(ROW(Y7)-ROW($V$5))*7+(COLUMN(Y7)-COLUMN($V$5)+1)),"",$V$3-WEEKDAY($V$3,1)+(ROW(Y7)-ROW($V$5))*7+(COLUMN(Y7)-COLUMN($V$5)+1)) | Z7: =IF(MONTH($V$3)<>MONTH($V$3-WEEKDAY($V$3,1)+(ROW(Z7)-ROW($V$5))*7+(COLUMN(Z7)-COLUMN($V$5)+1)),"",$V$3-WEEKDAY($V$3,1)+(ROW(Z7)-ROW($V$5))*7+(COLUMN(Z7)-COLUMN($V$5)+1)) | AA7: =IF(MONTH($V$3)<>MONTH($V$3-WEEKDAY($V$3,1)+(ROW(AA7)-ROW($V$5))*7+(COLUMN(AA7)-COLUMN($V$5)+1)),"",$V$3-WEEKDAY($V$3,1)+(ROW(AA7)-ROW($V$5))*7+(COLUMN(AA7)-COLUMN($V$5)+1)) | AB7: =IF(MONTH($V$3)<>MONTH($V$3-WEEKDAY($V$3,1)+(ROW(AB7)-ROW($V$5))*7+(COLUMN(AB7)-COLUMN($V$5)+1)),"",$V$3-WEEKDAY($V$3,1)+(ROW(AB7)-ROW($V$5))*7+(COLUMN(AB7)-COLUMN($V$5)+1))
C8: Georgetown, Guyana | V8: =IF(MONTH($V$3)<>MONTH($V$3-WEEKDAY($V$3,1)+(ROW(V8)-ROW($V$5))*7+(COLUMN(V8)-COLUMN($V$5)+1)),"",$V$3-WEEKDAY($V$3,1)+(ROW(V8)-ROW($V$5))*7+(COLUMN(V8)-COLUMN($V$5)+1)) | W8: =IF(MONTH($V$3)<>MONTH($V$3-WEEKDAY($V$3,1)+(ROW(W8)-ROW($V$5))*7+(COLUMN(W8)-COLUMN($V$5)+1)),"",$V$3-WEEKDAY($V$3,1)+(ROW(W8)-ROW($V$5))*7+(COLUMN(W8)-COLUMN($V$5)+1)) | X8: =IF(MONTH($V$3)<>MONTH($V$3-WEEKDAY($V$3,1)+(ROW(X8)-ROW($V$5))*7+(COLUMN(X8)-COLUMN($V$5)+1)),"",$V$3-WEEKDAY($V$3,1)+(ROW(X8)-ROW($V$5))*7+(COLUMN(X8)-COLUMN($V$5)+1)) | Y8: =IF(MONTH($V$3)<>MONTH($V$3-WEEKDAY($V$3,1)+(ROW(Y8)-ROW($V$5))*7+(COLUMN(Y8)-COLUMN($V$5)+1)),"",$V$3-WEEKDAY($V$3,1)+(ROW(Y8)-ROW($V$5))*7+(COLUMN(Y8)-COLUMN($V$5)+1)) | Z8: =IF(MONTH($V$3)<>MONTH($V$3-WEEKDAY($V$3,1)+(ROW(Z8)-ROW($V$5))*7+(COLUMN(Z8)-COLUMN($V$5)+1)),"",$V$3-WEEKDAY($V$3,1)+(ROW(Z8)-ROW($V$5))*7+(COLUMN(Z8)-COLUMN($V$5)+1)) | AA8: =IF(MONTH($V$3)<>MONTH($V$3-WEEKDAY($V$3,1)+(ROW(AA8)-ROW($V$5))*7+(COLUMN(AA8)-COLUMN($V$5)+1)),"",$V$3-WEEKDAY($V$3,1)+(ROW(AA8)-ROW($V$5))*7+(COLUMN(AA8)-COLUMN($V$5)+1)) | AB8: =IF(MONTH($V$3)<>MONTH($V$3-WEEKDAY($V$3,1)+(ROW(AB8)-ROW($V$5))*7+(COLUMN(AB8)-COLUMN($V$5)+1)),"",$V$3-WEEKDAY($V$3,1)+(ROW(AB8)-ROW($V$5))*7+(COLUMN(AB8)-COLUMN($V$5)+1)) | AE8: TRUE
C10: 592-223-7560 | K10: Week Starting: | M10: 45977 | T10: [42] | V10: =IF(MONTH($V$3)<>MONTH($V$3-WEEKDAY($V$3,1)+(ROW(V10)-ROW($V$5))*7+(COLUMN(V10)-COLUMN($V$5)+1)),"",$V$3-WEEKDAY($V$3,1)+(ROW(V10)-ROW($V$5))*7+(COLUMN(V10)-COLUMN($V$5)+1)) | W10: =IF(MONTH($V$3)<>MONTH($V$3-WEEKDAY($V$3,1)+(ROW(W10)-ROW($V$5))*7+(COLUMN(W10)-COLUMN($V$5)+1)),"",$V$3-WEEKDAY($V$3,1)+(ROW(W10)-ROW($V$5))*7+(COLUMN(W10)-COLUMN($V$5)+1)) | X10: =IF(MONTH($V$3)<>MONTH($V$3-WEEKDAY($V$3,1)+(ROW(X10)-ROW($V$5))*7+(COLUMN(X10)-COLUMN($V$5)+1)),"",$V$3-WEEKDAY($V$3,1)+(ROW(X10)-ROW($V$5))*7+(COLUMN(X10)-COLUMN($V$5)+1)) | Y10: =IF(MONTH($V$3)<>MONTH($V$3-WEEKDAY($V$3,1)+(ROW(Y10)-ROW($V$5))*7+(COLUMN(Y10)-COLUMN($V$5)+1)),"",$V$3-WEEKDAY($V$3,1)+(ROW(Y10)-ROW($V$5))*7+(COLUMN(Y10)-COLUMN($V$5)+1)) | Z10: =IF(MONTH($V$3)<>MONTH($V$3-WEEKDAY($V$3,1)+(ROW(Z10)-ROW($V$5))*7+(COLUMN(Z10)-COLUMN($V$5)+1)),"",$V$3-WEEKDAY($V$3,1)+(ROW(Z10)-ROW($V$5))*7+(COLUMN(Z10)-COLUMN($V$5)+1)) | AA10: =IF(MONTH($V$3)<>MONTH($V$3-WEEKDAY($V$3,1)+(ROW(AA10)-ROW($V$5))*7+(COLUMN(AA10)-COLUMN($V$5)+1)),"",$V$3-WEEKDAY($V$3,1)+(ROW(AA10)-ROW($V$5))*7+(COLUMN(AA10)-COLUMN($V$5)+1)) | AB10: =IF(MONTH($V$3)<>MONTH($V$3-WEEKDAY($V$3,1)+(ROW(AB10)-ROW($V$5))*7+(COLUMN(AB10)-COLUMN($V$5)+1)),"",$V$3-WEEKDAY($V$3,1)+(ROW(AB10)-ROW($V$5))*7+(COLUMN(AB10)-COLUMN($V$5)+1)) | AD10: After: | AE10: 40 | AF10: Hrs
V11: =IF(MONTH($V$3)<>MONTH($V$3-WEEKDAY($V$3,1)+(ROW(V11)-ROW($V$5))*7+(COLUMN(V11)-COLUMN($V$5)+1)),"",$V$3-WEEKDAY($V$3,1)+(ROW(V11)-ROW($V$5))*7+(COLUMN(V11)-COLUMN($V$5)+1)) | W11: =IF(MONTH($V$3)<>MONTH($V$3-WEEKDAY($V$3,1)+(ROW(W11)-ROW($V$5))*7+(COLUMN(W11)-COLUMN($V$5)+1)),"",$V$3-WEEKDAY($V$3,1)+(ROW(W11)-ROW($V$5))*7+(COLUMN(W11)-COLUMN($V$5)+1)) | X11: =IF(MONTH($V$3)<>MONTH($V$3-WEEKDAY($V$3,1)+(ROW(X11)-ROW($V$5))*7+(COLUMN(X11)-COLUMN($V$5)+1)),"",$V$3-WEEKDAY($V$3,1)+(ROW(X11)-ROW($V$5))*7+(COLUMN(X11)-COLUMN($V$5)+1)) | Y11: =IF(MONTH($V$3)<>MONTH($V$3-WEEKDAY($V$3,1)+(ROW(Y11)-ROW($V$5))*7+(COLUMN(Y11)-COLUMN($V$5)+1)),"",$V$3-WEEKDAY($V$3,1)+(ROW(Y11)-ROW($V$5))*7+(COLUMN(Y11)-COLUMN($V$5)+1)) | Z11: =IF(MONTH($V$3)<>MONTH($V$3-WEEKDAY($V$3,1)+(ROW(Z11)-ROW($V$5))*7+(COLUMN(Z11)-COLUMN($V$5)+1)),"",$V$3-WEEKDAY($V$3,1)+(ROW(Z11)-ROW($V$5))*7+(COLUMN(Z11)-COLUMN($V$5)+1)) | AA11: =IF(MONTH($V$3)<>MONTH($V$3-WEEKDAY($V$3,1)+(ROW(AA11)-ROW($V$5))*7+(COLUMN(AA11)-COLUMN($V$5)+1)),"",$V$3-WEEKDAY($V$3,1)+(ROW(AA11)-ROW($V$5))*7+(COLUMN(AA11)-COLUMN($V$5)+1)) | AB11: =IF(MONTH($V$3)<>MONTH($V$3-WEEKDAY($V$3,1)+(ROW(AB11)-ROW($V$5))*7+(COLUMN(AB11)-COLUMN($V$5)+1)),"",$V$3-WEEKDAY($V$3,1)+(ROW(AB11)-ROW($V$5))*7+(COLUMN(AB11)-COLUMN($V$5)+1))
A12: Day Off | B12: Holiday Double | C12: Day of Week | D12: Time In | E12: Time Out | G12: Time In | H12: Time Out | I12: Total Hrs | J12: Location | K12: Supervisor | L12: Supervisor Approval | M12: Regular Hrs | N12: Overtime Hrs | O12: Hol Hrs | P12: Responsibilities | Q12: Risk | R12: Meals | S12: Vac Hrs | T12: Reason for Overtime
A14: On Day | C14: =M10 | E14: =IF(D14="", "", IF(D14=TIME(0,0,0), 0, IF(AND(D14>=TIME(0,0,1), D14<=TIME(2,0,0)), TIME(7,0,0), IF(AND(D14>=TIME(5,0,0), D14<=TIME(8,0,0)), TIME(12,0,0), IF(AND(D14>TIME(8,0,0), D14<=TIME(13,59,0)), TIME(15,0,0), IF(AND(D14>=TIME(14,0,0), D14<=TIME(17,59,0)), TIME(21,0,0), IF(AND(D14>=TIME(18,0,0), D14<=TIME(21,59,0)), TIME(0,0,0), IF(AND(D14>=TIME(22,0,0), D14<=TIME(23,59,59)), TIME(7,0,0), "")))))))) | G14: =E14 | I14: =ROUND(IF(OR(D14="",E14="",E14=0),0,IF(H14="",MOD(E14-D14,1)*24,MOD(H14-D14,1)*24)),2) | M14: =IF(OR($A14="Holiday",$A15="Holiday"),IF(OR($C14="",$D14=""),0, IF(OR($A14="Holiday",$A15="Holiday"),0, IF(AND(NOT(OR($A14="Annual Leave",$A15="Annual Leave")),$A14="Off day"),0, IF($I14+$I15>=8,IF($I14>=8,8,$I14),$I14) )))+IF(MOD(ROW(),2)=0,8,0),IF(OR($C14="",$D14=""),0, IF(OR($A14="Holiday",$A15="Holiday"),0, IF(AND(NOT(OR($A14="Annual Leave",$A15="Annual Leave")),$A14="Off day"),0, IF($I14+$I15>=8,IF($I14>=8,8,$I14),$I14) )))) | N14: =IF(OR($C14="",$D14=""),0, IF(OR($A14="Holiday",$A15="Holiday"), IF(ISNUMBER(MATCH(TRIM($B14),{"Phagwah","Good Friday","Easter Monday","Labour Day","Christmas","Eid ul Azha","Romans-2","Globe-12","Neptune P1"},0)),0,$I14), IF(AND(NOT(OR($A14="Annual Leave",$A15="Annual Leave")),$A14="Off day"),$I14, MAX(0,$I14-$M14) ))) | O14: =IF(AND(OR($A14="Holiday",$A15="Holiday"), ISNUMBER(MATCH(TRIM($B14),{"Phagwah","Good Friday","Easter Monday","Labour Day","Christmas","Eid ul Azha","Romans-2","Globe-12","Neptune P1"},0))), $I14,0) | R14: =IF(OR($O$7="Canteen",$O$7="Head Office"),0,IF(OR($I14>0,$I15>0), IF( OR( AND($D14>=TIME(5,0,0),$D14<=TIME(7,0,0)), AND($D14>=TIME(14,0,0),$D14<=TIME(15,0,0)), AND($D14>=TIME(18,0,0),$D14<=TIME(19,0,0)), AND($D15>=TIME(5,0,0),$D15<=TIME(7,0,0)), AND($D15>=TIME(14,0,0),$D15<=TIME(15,0,0)), AND($D15>=TIME(18,0,0),$D15<=TIME(19,0,0)) ), IF($I14>0,1,0), 0 ), 0)) | S14: =IF(OR($A14="Annual Leave",$A15="Annual Leave"),IF($A14="Annual Leave",8,0),0)
A15: On Day | C15: =C14 | E15: =IF(D15=0, 0, IF(AND(D15>=TIME(0,0,1), D15<=TIME(2,0,0)), TIME(7,0,0), IF(AND(D15>=TIME(5,0,0), D15<=TIME(8,0,0)), TIME(12,0,0), IF(AND(D15>TIME(8,0,0), D15<=TIME(13,59,0)), TIME(15,0,0), IF(AND(D15>=TIME(14,0,0), D15<=TIME(17,59,0)), TIME(21,0,0), IF(AND(D15>=TIME(18,0,0), D15<=TIME(21,59,0)), TIME(0,0,0), IF(AND(D15>=TIME(22,0,0), D15<=TIME(23,59,59)), TIME(7,0,0), ""))))))) | G15: =E15 | I15: =ROUND(IF(OR(D15="",E15="",E15=0),0,IF(H15="",MOD(E15-D15,1)*24,MOD(H15-D15,1)*24)),2) | M15: =IF(OR($A15="Holiday",$A14="Holiday"),IF(OR($C15="",$D15=""),0, IF(OR($A14="Holiday",$A15="Holiday"),0, IF(AND(NOT(OR($A14="Annual Leave",$A15="Annual Leave")),$A15="Off day"),0, IF($I14+$I15>=8,IF($I14>=8,0,8-$I14),$I15) )))+IF(MOD(ROW(),2)=0,8,0),IF(OR($C15="",$D15=""),0, IF(OR($A14="Holiday",$A15="Holiday"),0, IF(AND(NOT(OR($A14="Annual Leave",$A15="Annual Leave")),$A15="Off day"),0, IF($I14+$I15>=8,IF($I14>=8,0,8-$I14),$I15) )))) | N15: =IF(OR($C15="",$D15=""),0, IF(OR($A14="Holiday",$A15="Holiday"), IF(ISNUMBER(MATCH(TRIM($B15),{"Phagwah","Good Friday","Easter Monday","Labour Day","Christmas","Eid ul Azha","Romans-2","Globe-12","Neptune P1"},0)),0,$I15), IF(AND(NOT(OR($A14="Annual Leave",$A15="Annual Leave")),$A15="Off day"),$I15, MAX(0,$I15-$M15) ))) | O15: =IF(AND(OR($A14="Holiday",$A15="Holiday"), ISNUMBER(MATCH(TRIM($B15),{"Phagwah","Good Friday","Easter Monday","Labour Day","Christmas","Eid ul Azha","Romans-2","Globe-12","Neptune P1"},0))), $I15,0) | R15: =IF(OR($O$7="Canteen",$O$7="Head Office"),0,IF(OR($I14>0,$I15>0), IF( OR( AND($D14>=TIME(5,0,0),$D14<=TIME(7,0,0)), AND($D14>=TIME(14,0,0),$D14<=TIME(15,0,0)), AND($D14>=TIME(18,0,0),$D14<=TIME(19,0,0)), AND($D15>=TIME(5,0,0),$D15<=TIME(7,0,0)), AND($D15>=TIME(14,0,0),$D15<=TIME(15,0,0)), AND($D15>=TIME(18,0,0),$D15<=TIME(19,0,0)) ), IF(AND($I14=0,$I15>0),1,0), 0 ), 0)) | S15: =IF(OR($A14="Annual Leave",$A15="Annual Leave"),IF(AND($A14<>"Annual Leave",$A15="Annual Leave"),8,0),0)
A16: On Day | C16: =C14+1 | E16: =IF(D16=0, 0, IF(AND(D16>=TIME(0,0,1), D16<=TIME(2,0,0)), TIME(7,0,0), IF(AND(D16>=TIME(5,0,0), D16<=TIME(8,0,0)), TIME(12,0,0), IF(AND(D16>TIME(8,0,0), D16<=TIME(13,59,0)), TIME(15,0,0), IF(AND(D16>=TIME(14,0,0), D16<=TIME(17,59,0)), TIME(21,0,0), IF(AND(D16>=TIME(18,0,0), D16<=TIME(21,59,0)), TIME(0,0,0), IF(AND(D16>=TIME(22,0,0), D16<=TIME(23,59,59)), TIME(7,0,0), ""))))))) | G16: =E16 | I16: =ROUND(IF(OR(D16="",E16="",E16=0),0,IF(H16="",MOD(E16-D16,1)*24,MOD(H16-D16,1)*24)),2) | M16: =IF(OR($A16="Holiday",$A17="Holiday"),IF(OR($C16="",$D16=""),0, IF(OR($A16="Holiday",$A17="Holiday"),0, IF(AND(NOT(OR($A16="Annual Leave",$A17="Annual Leave")),$A16="Off day"),0, IF($I16+$I17>=8,IF($I16>=8,8,$I16),$I16) )))+IF(MOD(ROW(),2)=0,8,0),IF(OR($C16="",$D16=""),0, IF(OR($A16="Holiday",$A17="Holiday"),0, IF(AND(NOT(OR($A16="Annual Leave",$A17="Annual Leave")),$A16="Off day"),0, IF($I16+$I17>=8,IF($I16>=8,8,$I16),$I16) )))) | N16: =IF(OR($C16="",$D16=""),0, IF(OR($A16="Holiday",$A17="Holiday"), IF(ISNUMBER(MATCH(TRIM($B16),{"Phagwah","Good Friday","Easter Monday","Labour Day","Christmas","Eid ul Azha","Romans-2","Globe-12","Neptune P1"},0)),0,$I16), IF(AND(NOT(OR($A16="Annual Leave",$A17="Annual Leave")),$A16="Off day"),$I16, MAX(0,$I16-$M16) ))) | O16: =IF(AND(OR($A16="Holiday",$A17="Holiday"), ISNUMBER(MATCH(TRIM($B16),{"Phagwah","Good Friday","Easter Monday","Labour Day","Christmas","Eid ul Azha","Romans-2","Globe-12","Neptune P1"},0))), $I16,0) | R16: =IF(OR($O$7="Canteen",$O$7="Head Office"),0,IF(OR($I16>0,$I17>0), IF( OR( AND($D16>=TIME(5,0,0),$D16<=TIME(7,0,0)), AND($D16>=TIME(14,0,0),$D16<=TIME(15,0,0)), AND($D16>=TIME(18,0,0),$D16<=TIME(19,0,0)), AND($D17>=TIME(5,0,0),$D17<=TIME(7,0,0)), AND($D17>=TIME(14,0,0),$D17<=TIME(15,0,0)), AND($D17>=TIME(18,0,0),$D17<=TIME(19,0,0)) ), IF($I16>0,1,0), 0 ), 0)) | S16: =IF(OR($A16="Annual Leave",$A17="Annual Leave"),IF($A16="Annual Leave",8,0),0)
A17: On Day | C17: =C16 | E17: =IF(D17=0, 0, IF(AND(D17>=TIME(0,0,1), D17<=TIME(2,0,0)), TIME(7,0,0), IF(AND(D17>=TIME(5,0,0), D17<=TIME(8,0,0)), TIME(12,0,0), IF(AND(D17>TIME(8,0,0), D17<=TIME(13,59,0)), TIME(15,0,0), IF(AND(D17>=TIME(14,0,0), D17<=TIME(17,59,0)), TIME(21,0,0), IF(AND(D17>=TIME(18,0,0), D17<=TIME(21,59,0)), TIME(0,0,0), IF(AND(D17>=TIME(22,0,0), D17<=TIME(23,59,59)), TIME(7,0,0), ""))))))) | G17: =E17 | I17: =ROUND(IF(OR(D17="",E17="",E17=0),0,IF(H17="",MOD(E17-D17,1)*24,MOD(H17-D17,1)*24)),2) | M17: =IF(OR($A17="Holiday",$A16="Holiday"),IF(OR($C17="",$D17=""),0, IF(OR($A16="Holiday",$A17="Holiday"),0, IF(AND(NOT(OR($A16="Annual Leave",$A17="Annual Leave")),$A17="Off day"),0, IF($I16+$I17>=8,IF($I16>=8,0,8-$I16),$I17) )))+IF(MOD(ROW(),2)=0,8,0),IF(OR($C17="",$D17=""),0, IF(OR($A16="Holiday",$A17="Holiday"),0, IF(AND(NOT(OR($A16="Annual Leave",$A17="Annual Leave")),$A17="Off day"),0, IF($I16+$I17>=8,IF($I16>=8,0,8-$I16),$I17) )))) | N17: =IF(OR($C17="",$D17=""),0, IF(OR($A16="Holiday",$A17="Holiday"), IF(ISNUMBER(MATCH(TRIM($B17),{"Phagwah","Good Friday","Easter Monday","Labour Day","Christmas","Eid ul Azha","Romans-2","Globe-12","Neptune P1"},0)),0,$I17), IF(AND(NOT(OR($A16="Annual Leave",$A17="Annual Leave")),$A17="Off day"),$I17, MAX(0,$I17-$M17) ))) | O17: =IF(AND(OR($A16="Holiday",$A17="Holiday"), ISNUMBER(MATCH(TRIM($B17),{"Phagwah","Good Friday","Easter Monday","Labour Day","Christmas","Eid ul Azha","Romans-2","Globe-12","Neptune P1"},0))), $I17,0) | R17: =IF(OR($O$7="Canteen",$O$7="Head Office"),0,IF(OR($I16>0,$I17>0), IF( OR( AND($D16>=TIME(5,0,0),$D16<=TIME(7,0,0)), AND($D16>=TIME(14,0,0),$D16<=TIME(15,0,0)), AND($D16>=TIME(18,0,0),$D16<=TIME(19,0,0)), AND($D17>=TIME(5,0,0),$D17<=TIME(7,0,0)), AND($D17>=TIME(14,0,0),$D17<=TIME(15,0,0)), AND($D17>=TIME(18,0,0),$D17<=TIME(19,0,0)) ), IF(AND($I16=0,$I17>0),1,0), 0 ), 0)) | S17: =IF(OR($A16="Annual Leave",$A17="Annual Leave"),IF(AND($A16<>"Annual Leave",$A17="Annual Leave"),8,0),0)
A18: On Day | C18: =C16+1 | E18: =IF(D18=0, 0, IF(AND(D18>=TIME(0,0,1), D18<=TIME(2,0,0)), TIME(7,0,0), IF(AND(D18>=TIME(5,0,0), D18<=TIME(8,0,0)), TIME(12,0,0), IF(AND(D18>TIME(8,0,0), D18<=TIME(13,59,0)), TIME(15,0,0), IF(AND(D18>=TIME(14,0,0), D18<=TIME(17,59,0)), TIME(21,0,0), IF(AND(D18>=TIME(18,0,0), D18<=TIME(21,59,0)), TIME(0,0,0), IF(AND(D18>=TIME(22,0,0), D18<=TIME(23,59,59)), TIME(7,0,0), ""))))))) | G18: =E18 | I18: =ROUND(IF(OR(D18="",E18="",E18=0),0,IF(H18="",MOD(E18-D18,1)*24,MOD(H18-D18,1)*24)),2) | M18: =IF(OR($A18="Holiday",$A19="Holiday"),IF(OR($C18="",$D18=""),0, IF(OR($A18="Holiday",$A19="Holiday"),0, IF(AND(NOT(OR($A18="Annual Leave",$A19="Annual Leave")),$A18="Off day"),0, IF($I18+$I19>=8,IF($I18>=8,8,$I18),$I18) )))+IF(MOD(ROW(),2)=0,8,0),IF(OR($C18="",$D18=""),0, IF(OR($A18="Holiday",$A19="Holiday"),0, IF(AND(NOT(OR($A18="Annual Leave",$A19="Annual Leave")),$A18="Off day"),0, IF($I18+$I19>=8,IF($I18>=8,8,$I18),$I18) )))) | N18: =IF(OR($C18="",$D18=""),0, IF(OR($A18="Holiday",$A19="Holiday"), IF(ISNUMBER(MATCH(TRIM($B18),{"Phagwah","Good Friday","Easter Monday","Labour Day","Christmas","Eid ul Azha","Romans-2","Globe-12","Neptune P1"},0)),0,$I18), IF(AND(NOT(OR($A18="Annual Leave",$A19="Annual Leave")),$A18="Off day"),$I18, MAX(0,$I18-$M18) ))) | O18: =IF(AND(OR($A18="Holiday",$A19="Holiday"), ISNUMBER(MATCH(TRIM($B18),{"Phagwah","Good Friday","Easter Monday","Labour Day","Christmas","Eid ul Azha","Romans-2","Globe-12","Neptune P1"},0))), $I18,0) | R18: =IF(OR($O$7="Canteen",$O$7="Head Office"),0,IF(OR($I18>0,$I19>0), IF( OR( AND($D18>=TIME(5,0,0),$D18<=TIME(7,0,0)), AND($D18>=TIME(14,0,0),$D18<=TIME(15,0,0)), AND($D18>=TIME(18,0,0),$D18<=TIME(19,0,0)), AND($D19>=TIME(5,0,0),$D19<=TIME(7,0,0)), AND($D19>=TIME(14,0,0),$D19<=TIME(15,0,0)), AND($D19>=TIME(18,0,0),$D19<=TIME(19,0,0)) ), IF($I18>0,1,0), 0 ), 0)) | S18: =IF(OR($A18="Annual Leave",$A19="Annual Leave"),IF($A18="Annual Leave",8,0),0)
