Workbook
Name valuevx: 42.314159
Name LocationList: '_Locations'!$A$1:$A$37

Sheet Work Hours Summary
A1: 📊 WORK HOURS SUMMARY
A2: Pay Period: 1-15/16 Jan 2026 | Total Employees: 29
A4: # | B4: Employee Name | C4: Emp # | D4: Total Hrs | E4: Days Wkd | F4: Daily >12 | G4: Wkly >60 | H4: 7+ Days | I4: OT >40 | J4: Wkly <40 | K4: Daily <8 | L4: Days <5 | M4: Period <80 | N4: STATUS
A5: 1 | B5: Abel, Natalie | C5: 4469 | D5: ='Abel, Natalie'!I49 | E5: ='Abel, Natalie'!Q50 | F5: =SUMPRODUCT((('Abel, Natalie'!I14+'Abel, Natalie'!I15)>12)*1)+SUMPRODUCT((('Abel, Natalie'!I16+'Abel, Natalie'!I17)>12)*1)+SUMPRODUCT((('Abel, Natalie'!I18+'Abel, Natalie'!I19)>12)*1)+SUMPRODUCT((('Abel, Natalie'!I20+'Abel, Natalie'!I21)>12)*1)+SUMPRODUCT((('Abel, Natalie'!I22+'Abel, Natalie'!I23)>12)*1)+SUMPRODUCT((('Abel, Natalie'!I24+'Abel, Natalie'!I25)>12)*1)+SUMPRODUCT((('Abel, Natalie'!I26+'Abel, Natalie'!I27)>12)*1)+SUMPRODUCT((('Abel, Natalie'!I30+'Abel, Natalie'!I31)>12)*1)+SUMPRODUCT((('Abel, Natalie'!I32+'Abel, Natalie'!I33)>12)*1)+SUMPRODUCT((('Abel, Natalie'!I34+'Abel, Natalie'!I35)>12)*1)+SUMPRODUCT((('Abel, Natalie'!I36+'Abel, Natalie'!I37)>12)*1)+SUMPRODUCT((('Abel, Natalie'!I38+'Abel, Natalie'!I39)>12)*1)+SUMPRODUCT((('Abel, Natalie'!I40+'Abel, Natalie'!I41)>12)*1)+SUMPRODUCT((('Abel, Natalie'!I42+'Abel, Natalie'!I43)>12)*1)+SUMPRODUCT((('Abel, Natalie'!I45+'Abel, Natalie'!I46)>12)*1)+SUMPRODUCT((('Abel, Natalie'!I47+'Abel, Natalie'!I48)>12)*1) | G5: =IF(MAX(SUM('Abel, Natalie'!I14:I27),SUM('Abel, Natalie'!I30:I43))>60,"Yes","") | H5: =IF(OR(AND(('Abel, Natalie'!I14+'Abel, Natalie'!I15)>0,('Abel, Natalie'!I16+'Abel, Natalie'!I17)>0,('Abel, Natalie'!I18+'Abel, Natalie'!I19)>0,('Abel, Natalie'!I20+'Abel, Natalie'!I21)>0,('Abel, Natalie'!I22+'Abel, Natalie'!I23)>0,('Abel, Natalie'!I24+'Abel, Natalie'!I25)>0,('Abel, Natalie'!I26+'Abel, Natalie'!I27)>0),AND(('Abel, Natalie'!I30+'Abel, Natalie'!I31)>0,('Abel, Natalie'!I32+'Abel, Natalie'!I33)>0,('Abel, Natalie'!I34+'Abel, Natalie'!I35)>0,('Abel, Natalie'!I36+'Abel, Natalie'!I37)>0,('Abel, Natalie'!I38+'Abel, Natalie'!I39)>0,('Abel, Natalie'!I40+'Abel, Natalie'!I41)>0,('Abel, Natalie'!I42+'Abel, Natalie'!I43)>0)),"Yes","") | I5: =IF('Abel, Natalie'!N49>40,"Yes","") | J5: =IF(OR(AND(SUM('Abel, Natalie'!I14:I27)>0,SUM('Abel, Natalie'!I14:I27)<40),AND(SUM('Abel, Natalie'!I30:I43)>0,SUM('Abel, Natalie'!I30:I43)<40)),"Yes","") | K5: =SUMPRODUCT(('Abel, Natalie'!I14:I48>0)*('Abel, Natalie'!I14:I48<8)) | L5: =IF('Abel, Natalie'!Q50<5,"Yes","") | M5: =IF(AND('Abel, Natalie'!I49>0,'Abel, Natalie'!I49<80),"Yes","") | N5: =IF(OR(F5>0,G5="Yes",H5="Yes",I5="Yes"),"⚠️ OVERWORK",IF(OR(J5="Yes",K5>0,L5="Yes",M5="Yes"),"🔻 UNDERWORK","✓ OK"))
A6: 2 | B6: April, Candica Alicia | C6: 5255 | D6: ='April, Candica'!I49 | E6: ='April, Candica'!Q50 | F6: =SUMPRODUCT((('April, Candica'!I14+'April, Candica'!I15)>12)*1)+SUMPRODUCT((('April, Candica'!I16+'April, Candica'!I17)>12)*1)+SUMPRODUCT((('April, Candica'!I18+'April, Candica'!I19)>12)*1)+SUMPRODUCT((('April, Candica'!I20+'April, Candica'!I21)>12)*1)+SUMPRODUCT((('April, Candica'!I22+'April, Candica'!I23)>12)*1)+SUMPRODUCT((('April, Candica'!I24+'April, Candica'!I25)>12)*1)+SUMPRODUCT((('April, Candica'!I26+'April, Candica'!I27)>12)*1)+SUMPRODUCT((('April, Candica'!I30+'April, Candica'!I31)>12)*1)+SUMPRODUCT((('April, Candica'!I32+'April, Candica'!I33)>12)*1)+SUMPRODUCT((('April, Candica'!I34+'April, Candica'!I35)>12)*1)+SUMPRODUCT((('April, Candica'!I36+'April, Candica'!I37)>12)*1)+SUMPRODUCT((('April, Candica'!I38+'April, Candica'!I39)>12)*1)+SUMPRODUCT((('April, Candica'!I40+'April, Candica'!I41)>12)*1)+SUMPRODUCT((('April, Candica'!I42+'April, Candica'!I43)>12)*1)+SUMPRODUCT((('April, Candica'!I45+'April, Candica'!I46)>12)*1)+SUMPRODUCT((('April, Candica'!I47+'April, Candica'!I48)>12)*1) | G6: =IF(MAX(SUM('April, Candica'!I14:I27),SUM('April, Candica'!I30:I43))>60,"Yes","") | H6: =IF(OR(AND(('April, Candica'!I14+'April, Candica'!I15)>0,('April, Candica'!I16+'April, Candica'!I17)>0,('April, Candica'!I18+'April, Candica'!I19)>0,('April, Candica'!I20+'April, Candica'!I21)>0,('April, Candica'!I22+'April, Candica'!I23)>0,('April, Candica'!I24+'April, Candica'!I25)>0,('April, Candica'!I26+'April, Candica'!I27)>0),AND(('April, Candica'!I30+'April, Candica'!I31)>0,('April, Candica'!I32+'April, Candica'!I33)>0,('April, Candica'!I34+'April, Candica'!I35)>0,('April, Candica'!I36+'April, Candica'!I37)>0,('April, Candica'!I38+'April, Candica'!I39)>0,('April, Candica'!I40+'April, Candica'!I41)>0,('April, Candica'!I42+'April, Candica'!I43)>0)),"Yes","") | I6: =IF('April, Candica'!N49>40,"Yes","") | J6: =IF(OR(AND(SUM('April, Candica'!I14:I27)>0,SUM('April, Candica'!I14:I27)<40),AND(SUM('April, Candica'!I30:I43)>0,SUM('April, Candica'!I30:I43)<40)),"Yes","") | K6: =SUMPRODUCT(('April, Candica'!I14:I48>0)*('April, Candica'!I14:I48<8)) | L6: =IF('April, Candica'!Q50<5,"Yes","") | M6: =IF(AND('April, Candica'!I49>0,'April, Candica'!I49<80),"Yes","") | N6: =IF(OR(F6>0,G6="Yes",H6="Yes",I6="Yes"),"⚠️ OVERWORK",IF(OR(J6="Yes",K6>0,L6="Yes",M6="Yes"),"🔻 UNDERWORK","✓ OK"))
A7: 3 | B7: Ash, Carol Veronica | C7: 1105 | D7: ='Ash, Carol'!I49 | E7: ='Ash, Carol'!Q50 | F7: =SUMPRODUCT((('Ash, Carol'!I14+'Ash, Carol'!I15)>12)*1)+SUMPRODUCT((('Ash, Carol'!I16+'Ash, Carol'!I17)>12)*1)+SUMPRODUCT((('Ash, Carol'!I18+'Ash, Carol'!I19)>12)*1)+SUMPRODUCT((('Ash, Carol'!I20+'Ash, Carol'!I21)>12)*1)+SUMPRODUCT((('Ash, Carol'!I22+'Ash, Carol'!I23)>12)*1)+SUMPRODUCT((('Ash, Carol'!I24+'Ash, Carol'!I25)>12)*1)+SUMPRODUCT((('Ash, Carol'!I26+'Ash, Carol'!I27)>12)*1)+SUMPRODUCT((('Ash, Carol'!I30+'Ash, Carol'!I31)>12)*1)+SUMPRODUCT((('Ash, Carol'!I32+'Ash, Carol'!I33)>12)*1)+SUMPRODUCT((('Ash, Carol'!I34+'Ash, Carol'!I35)>12)*1)+SUMPRODUCT((('Ash, Carol'!I36+'Ash, Carol'!I37)>12)*1)+SUMPRODUCT((('Ash, Carol'!I38+'Ash, Carol'!I39)>12)*1)+SUMPRODUCT((('Ash, Carol'!I40+'Ash, Carol'!I41)>12)*1)+SUMPRODUCT((('Ash, Carol'!I42+'Ash, Carol'!I43)>12)*1)+SUMPRODUCT((('Ash, Carol'!I45+'Ash, Carol'!I46)>12)*1)+SUMPRODUCT((('Ash, Carol'!I47+'Ash, Carol'!I48)>12)*1) | G7: =IF(MAX(SUM('Ash, Carol'!I14:I27),SUM('Ash, Carol'!I30:I43))>60,"Yes","") | H7: =IF(OR(AND(('Ash, Carol'!I14+'Ash, Carol'!I15)>0,('Ash, Carol'!I16+'Ash, Carol'!I17)>0,('Ash, Carol'!I18+'Ash, Carol'!I19)>0,('Ash, Carol'!I20+'Ash, Carol'!I21)>0,('Ash, Carol'!I22+'Ash, Carol'!I23)>0,('Ash, Carol'!I24+'Ash, Carol'!I25)>0,('Ash, Carol'!I26+'Ash, Carol'!I27)>0),AND(('Ash, Carol'!I30+'Ash, Carol'!I31)>0,('Ash, Carol'!I32+'Ash, Carol'!I33)>0,('Ash, Carol'!I34+'Ash, Carol'!I35)>0,('Ash, Carol'!I36+'Ash, Carol'!I37)>0,('Ash, Carol'!I38+'Ash, Carol'!I39)>0,('Ash, Carol'!I40+'Ash, Carol'!I41)>0,('Ash, Carol'!I42+'Ash, Carol'!I43)>0)),"Yes","") | I7: =IF('Ash, Carol'!N49>40,"Yes","") | J7: =IF(OR(AND(SUM('Ash, Carol'!I14:I27)>0,SUM('Ash, Carol'!I14:I27)<40),AND(SUM('Ash, Carol'!I30:I43)>0,SUM('Ash, Carol'!I30:I43)<40)),"Yes","") | K7: =SUMPRODUCT(('Ash, Carol'!I14:I48>0)*('Ash, Carol'!I14:I48<8)) | L7: =IF('Ash, Carol'!Q50<5,"Yes","") | M7: =IF(AND('Ash, Carol'!I49>0,'Ash, Carol'!I49<80),"Yes","") | N7: =IF(OR(F7>0,G7="Yes",H7="Yes",I7="Yes"),"⚠️ OVERWORK",IF(OR(J7="Yes",K7>0,L7="Yes",M7="Yes"),"🔻 UNDERWORK","✓ OK"))
A8: 4 | B8: Beharry, Akeela Ashanti | C8: 5520 | D8: ='Beharry, Akeela'!I49 | E8: ='Beharry, Akeela'!Q50 | F8: =SUMPRODUCT((('Beharry, Akeela'!I14+'Beharry, Akeela'!I15)>12)*1)+SUMPRODUCT((('Beharry, Akeela'!I16+'Beharry, Akeela'!I17)>12)*1)+SUMPRODUCT((('Beharry, Akeela'!I18+'Beharry, Akeela'!I19)>12)*1)+SUMPRODUCT((('Beharry, Akeela'!I20+'Beharry, Akeela'!I21)>12)*1)+SUMPRODUCT((('Beharry, Akeela'!I22+'Beharry, Akeela'!I23)>12)*1)+SUMPRODUCT((('Beharry, Akeela'!I24+'Beharry, Akeela'!I25)>12)*1)+SUMPRODUCT((('Beharry, Akeela'!I26+'Beharry, Akeela'!I27)>12)*1)+SUMPRODUCT((('Beharry, Akeela'!I30+'Beharry, Akeela'!I31)>12)*1)+SUMPRODUCT((('Beharry, Akeela'!I32+'Beharry, Akeela'!I33)>12)*1)+SUMPRODUCT((('Beharry, Akeela'!I34+'Beharry, Akeela'!I35)>12)*1)+SUMPRODUCT((('Beharry, Akeela'!I36+'Beharry, Akeela'!I37)>12)*1)+SUMPRODUCT((('Beharry, Akeela'!I38+'Beharry, Akeela'!I39)>12)*1)+SUMPRODUCT((('Beharry, Akeela'!I40+'Beharry, Akeela'!I41)>12)*1)+SUMPRODUCT((('Beharry, Akeela'!I42+'Beharry, Akeela'!I43)>12)*1)+SUMPRODUCT((('Beharry, Akeela'!I45+'Beharry, Akeela'!I46)>12)*1)+SUMPRODUCT((('Beharry, Akeela'!I47+'Beharry, Akeela'!I48)>12)*1) | G8: =IF(MAX(SUM('Beharry, Akeela'!I14:I27),SUM('Beharry, Akeela'!I30:I43))>60,"Yes","") | H8: =IF(OR(AND(('Beharry, Akeela'!I14+'Beharry, Akeela'!I15)>0,('Beharry, Akeela'!I16+'Beharry, Akeela'!I17)>0,('Beharry, Akeela'!I18+'Beharry, Akeela'!I19)>0,('Beharry, Akeela'!I20+'Beharry, Akeela'!I21)>0,('Beharry, Akeela'!I22+'Beharry, Akeela'!I23)>0,('Beharry, Akeela'!I24+'Beharry, Akeela'!I25)>0,('Beharry, Akeela'!I26+'Beharry, Akeela'!I27)>0),AND(('Beharry, Akeela'!I30+'Beharry, Akeela'!I31)>0,('Beharry, Akeela'!I32+'Beharry, Akeela'!I33)>0,('Beharry, Akeela'!I34+'Beharry, Akeela'!I35)>0,('Beharry, Akeela'!I36+'Beharry, Akeela'!I37)>0,('Beharry, Akeela'!I38+'Beharry, Akeela'!I39)>0,('Beharry, Akeela'!I40+'Beharry, Akeela'!I41)>0,('Beharry, Akeela'!I42+'Beharry, Akeela'!I43)>0)),"Yes","") | I8: =IF('Beharry, Akeela'!N49>40,"Yes","") | J8: =IF(OR(AND(SUM('Beharry, Akeela'!I14:I27)>0,SUM('Beharry, Akeela'!I14:I27)<40),AND(SUM('Beharry, Akeela'!I30:I43)>0,SUM('Beharry, Akeela'!I30:I43)<40)),"Yes","") | K8: =SUMPRODUCT(('Beharry, Akeela'!I14:I48>0)*('Beharry, Akeela'!I14:I48<8)) | L8: =IF('Beharry, Akeela'!Q50<5,"Yes","") | M8: =IF(AND('Beharry, Akeela'!I49>0,'Beharry, Akeela'!I49<80),"Yes","") | N8: =IF(OR(F8>0,G8="Yes",H8="Yes",I8="Yes"),"⚠️ OVERWORK",IF(OR(J8="Yes",K8>0,L8="Yes",M8="Yes"),"🔻 UNDERWORK","✓ OK"))
A9: 5 | B9: Blake, Bevon Natifa | C9: 5113 | D9: ='Blake, Bevon'!I49 | E9: ='Blake, Bevon'!Q50 | F9: =SUMPRODUCT((('Blake, Bevon'!I14+'Blake, Bevon'!I15)>12)*1)+SUMPRODUCT((('Blake, Bevon'!I16+'Blake, Bevon'!I17)>12)*1)+SUMPRODUCT((('Blake, Bevon'!I18+'Blake, Bevon'!I19)>12)*1)+SUMPRODUCT((('Blake, Bevon'!I20+'Blake, Bevon'!I21)>12)*1)+SUMPRODUCT((('Blake, Bevon'!I22+'Blake, Bevon'!I23)>12)*1)+SUMPRODUCT((('Blake, Bevon'!I24+'Blake, Bevon'!I25)>12)*1)+SUMPRODUCT((('Blake, Bevon'!I26+'Blake, Bevon'!I27)>12)*1)+SUMPRODUCT((('Blake, Bevon'!I30+'Blake, Bevon'!I31)>12)*1)+SUMPRODUCT((('Blake, Bevon'!I32+'Blake, Bevon'!I33)>12)*1)+SUMPRODUCT((('Blake, Bevon'!I34+'Blake, Bevon'!I35)>12)*1)+SUMPRODUCT((('Blake, Bevon'!I36+'Blake, Bevon'!I37)>12)*1)+SUMPRODUCT((('Blake, Bevon'!I38+'Blake, Bevon'!I39)>12)*1)+SUMPRODUCT((('Blake, Bevon'!I40+'Blake, Bevon'!I41)>12)*1)+SUMPRODUCT((('Blake, Bevon'!I42+'Blake, Bevon'!I43)>12)*1)+SUMPRODUCT((('Blake, Bevon'!I45+'Blake, Bevon'!I46)>12)*1)+SUMPRODUCT((('Blake, Bevon'!I47+'Blake, Bevon'!I48)>12)*1) | G9: =IF(MAX(SUM('Blake, Bevon'!I14:I27),SUM('Blake, Bevon'!I30:I43))>60,"Yes","") | H9: =IF(OR(AND(('Blake, Bevon'!I14+'Blake, Bevon'!I15)>0,('Blake, Bevon'!I16+'Blake, Bevon'!I17)>0,('Blake, Bevon'!I18+'Blake, Bevon'!I19)>0,('Blake, Bevon'!I20+'Blake, Bevon'!I21)>0,('Blake, Bevon'!I22+'Blake, Bevon'!I23)>0,('Blake, Bevon'!I24+'Blake, Bevon'!I25)>0,('Blake, Bevon'!I26+'Blake, Bevon'!I27)>0),AND(('Blake, Bevon'!I30+'Blake, Bevon'!I31)>0,('Blake, Bevon'!I32+'Blake, Bevon'!I33)>0,('Blake, Bevon'!I34+'Blake, Bevon'!I35)>0,('Blake, Bevon'!I36+'Blake, Bevon'!I37)>0,('Blake, Bevon'!I38+'Blake, Bevon'!I39)>0,('Blake, Bevon'!I40+'Blake, Bevon'!I41)>0,('Blake, Bevon'!I42+'Blake, Bevon'!I43)>0)),"Yes","") | I9: =IF('Blake, Bevon'!N49>40,"Yes","") | J9: =IF(OR(AND(SUM('Blake, Bevon'!I14:I27)>0,SUM('Blake, Bevon'!I14:I27)<40),AND(SUM('Blake, Bevon'!I30:I43)>0,SUM('Blake, Bevon'!I30:I43)<40)),"Yes","") | K9: =SUMPRODUCT(('Blake, Bevon'!I14:I48>0)*('Blake, Bevon'!I14:I48<8)) | L9: =IF('Blake, Bevon'!Q50<5,"Yes","") | M9: =IF(AND('Blake, Bevon'!I49>0,'Blake, Bevon'!I49<80),"Yes","") | N9: =IF(OR(F9>0,G9="Yes",H9="Yes",I9="Yes"),"⚠️ OVERWORK",IF(OR(J9="Yes",K9>0,L9="Yes",M9="Yes"),"🔻 UNDERWORK","✓ OK"))
A10: 6 | B10: Charles, Maisha Renitta | C10: 4031 | D10: ='Charles, Maisha'!I49 | E10: ='Charles, Maisha'!Q50 | F10: =SUMPRODUCT((('Charles, Maisha'!I14+'Charles, Maisha'!I15)>12)*1)+SUMPRODUCT((('Charles, Maisha'!I16+'Charles, Maisha'!I17)>12)*1)+SUMPRODUCT((('Charles, Maisha'!I18+'Charles, Maisha'!I19)>12)*1)+SUMPRODUCT((('Charles, Maisha'!I20+'Charles, Maisha'!I21)>12)*1)+SUMPRODUCT((('Charles, Maisha'!I22+'Charles, Maisha'!I23)>12)*1)+SUMPRODUCT((('Charles, Maisha'!I24+'Charles, Maisha'!I25)>12)*1)+SUMPRODUCT((('Charles, Maisha'!I26+'Charles, Maisha'!I27)>12)*1)+SUMPRODUCT((('Charles, Maisha'!I30+'Charles, Maisha'!I31)>12)*1)+SUMPRODUCT((('Charles, Maisha'!I32+'Charles, Maisha'!I33)>12)*1)+SUMPRODUCT((('Charles, Maisha'!I34+'Charles, Maisha'!I35)>12)*1)+SUMPRODUCT((('Charles, Maisha'!I36+'Charles, Maisha'!I37)>12)*1)+SUMPRODUCT((('Charles, Maisha'!I38+'Charles, Maisha'!I39)>12)*1)+SUMPRODUCT((('Charles, Maisha'!I40+'Charles, Maisha'!I41)>12)*1)+SUMPRODUCT((('Charles, Maisha'!I42+'Charles, Maisha'!I43)>12)*1)+SUMPRODUCT((('Charles, Maisha'!I45+'Charles, Maisha'!I46)>12)*1)+SUMPRODUCT((('Charles, Maisha'!I47+'Charles, Maisha'!I48)>12)*1) | G10: =IF(MAX(SUM('Charles, Maisha'!I14:I27),SUM('Charles, Maisha'!I30:I43))>60,"Yes","") | H10: =IF(OR(AND(('Charles, Maisha'!I14+'Charles, Maisha'!I15)>0,('Charles, Maisha'!I16+'Charles, Maisha'!I17)>0,('Charles, Maisha'!I18+'Charles, Maisha'!I19)>0,('Charles, Maisha'!I20+'Charles, Maisha'!I21)>0,('Charles, Maisha'!I22+'Charles, Maisha'!I23)>0,('Charles, Maisha'!I24+'Charles, Maisha'!I25)>0,('Charles, Maisha'!I26+'Charles, Maisha'!I27)>0),AND(('Charles, Maisha'!I30+'Charles, Maisha'!I31)>0,('Charles, Maisha'!I32+'Charles, Maisha'!I33)>0,('Charles, Maisha'!I34+'Charles, Maisha'!I35)>0,('Charles, Maisha'!I36+'Charles, Maisha'!I37)>0,('Charles, Maisha'!I38+'Charles, Maisha'!I39)>0,('Charles, Maisha'!I40+'Charles, Maisha'!I41)>0,('Charles, Maisha'!I42+'Charles, Maisha'!I43)>0)),"Yes","") | I10: =IF('Charles, Maisha'!N49>40,"Yes","") | J10: =IF(OR(AND(SUM('Charles, Maisha'!I14:I27)>0,SUM('Charles, Maisha'!I14:I27)<40),AND(SUM('Charles, Maisha'!I30:I43)>0,SUM('Charles, Maisha'!I30:I43)<40)),"Yes","") | K10: =SUMPRODUCT(('Charles, Maisha'!I14:I48>0)*('Charles, Maisha'!I14:I48<8)) | L10: =IF('Charles, Maisha'!Q50<5,"Yes","") | M10: =IF(AND('Charles, Maisha'!I49>0,'Charles, Maisha'!I49<80),"Yes","") | N10: =IF(OR(F10>0,G10="Yes",H10="Yes",I10="Yes"),"⚠️ OVERWORK",IF(OR(J10="Yes",K10>0,L10="Yes",M10="Yes"),"🔻 UNDERWORK","✓ OK"))
A11: 7 | B11: Cromwell, Dexter Oliver | C11: 2425 | D11: ='Cromwell, Dexter'!I49 | E11: ='Cromwell, Dexter'!Q50 | F11: =SUMPRODUCT((('Cromwell, Dexter'!I14+'Cromwell, Dexter'!I15)>12)*1)+SUMPRODUCT((('Cromwell, Dexter'!I16+'Cromwell, Dexter'!I17)>12)*1)+SUMPRODUCT((('Cromwell, Dexter'!I18+'Cromwell, Dexter'!I19)>12)*1)+SUMPRODUCT((('Cromwell, Dexter'!I20+'Cromwell, Dexter'!I21)>12)*1)+SUMPRODUCT((('Cromwell, Dexter'!I22+'Cromwell, Dexter'!I23)>12)*1)+SUMPRODUCT((('Cromwell, Dexter'!I24+'Cromwell, Dexter'!I25)>12)*1)+SUMPRODUCT((('Cromwell, Dexter'!I26+'Cromwell, Dexter'!I27)>12)*1)+SUMPRODUCT((('Cromwell, Dexter'!I30+'Cromwell, Dexter'!I31)>12)*1)+SUMPRODUCT((('Cromwell, Dexter'!I32+'Cromwell, Dexter'!I33)>12)*1)+SUMPRODUCT((('Cromwell, Dexter'!I34+'Cromwell, Dexter'!I35)>12)*1)+SUMPRODUCT((('Cromwell, Dexter'!I36+'Cromwell, Dexter'!I37)>12)*1)+SUMPRODUCT((('Cromwell, Dexter'!I38+'Cromwell, Dexter'!I39)>12)*1)+SUMPRODUCT((('Cromwell, Dexter'!I40+'Cromwell, Dexter'!I41)>12)*1)+SUMPRODUCT((('Cromwell, Dexter'!I42+'Cromwell, Dexter'!I43)>12)*1)+SUMPRODUCT((('Cromwell, Dexter'!I45+'Cromwell, Dexter'!I46)>12)*1)+SUMPRODUCT((('Cromwell, Dexter'!I47+'Cromwell, Dexter'!I48)>12)*1) | G11: =IF(MAX(SUM('Cromwell, Dexter'!I14:I27),SUM('Cromwell, Dexter'!I30:I43))>60,"Yes","") | H11: =IF(OR(AND(('Cromwell, Dexter'!I14+'Cromwell, Dexter'!I15)>0,('Cromwell, Dexter'!I16+'Cromwell, Dexter'!I17)>0,('Cromwell, Dexter'!I18+'Cromwell, Dexter'!I19)>0,('Cromwell, Dexter'!I20+'Cromwell, Dexter'!I21)>0,('Cromwell, Dexter'!I22+'Cromwell, Dexter'!I23)>0,('Cromwell, Dexter'!I24+'Cromwell, Dexter'!I25)>0,('Cromwell, Dexter'!I26+'Cromwell, Dexter'!I27)>0),AND(('Cromwell, Dexter'!I30+'Cromwell, Dexter'!I31)>0,('Cromwell, Dexter'!I32+'Cromwell, Dexter'!I33)>0,('Cromwell, Dexter'!I34+'Cromwell, Dexter'!I35)>0,('Cromwell, Dexter'!I36+'Cromwell, Dexter'!I37)>0,('Cromwell, Dexter'!I38+'Cromwell, Dexter'!I39)>0,('Cromwell, Dexter'!I40+'Cromwell, Dexter'!I41)>0,('Cromwell, Dexter'!I42+'Cromwell, Dexter'!I43)>0)),"Yes","") | I11: =IF('Cromwell, Dexter'!N49>40,"Yes","") | J11: =IF(OR(AND(SUM('Cromwell, Dexter'!I14:I27)>0,SUM('Cromwell, Dexter'!I14:I27)<40),AND(SUM('Cromwell, Dexter'!I30:I43)>0,SUM('Cromwell, Dexter'!I30:I43)<40)),"Yes","") | K11: =SUMPRODUCT(('Cromwell, Dexter'!I14:I48>0)*('Cromwell, Dexter'!I14:I48<8)) | L11: =IF('Cromwell, Dexter'!Q50<5,"Yes","") | M11: =IF(AND('Cromwell, Dexter'!I49>0,'Cromwell, Dexter'!I49<80),"Yes","") | N11: =IF(OR(F11>0,G11="Yes",H11="Yes",I11="Yes"),"⚠️ OVERWORK",IF(OR(J11="Yes",K11>0,L11="Yes",M11="Yes"),"🔻 UNDERWORK","✓ OK"))
A12: 8 | B12: Eastman, Dennis Rickford | C12: 5367 | D12: ='Eastman, Dennis'!I49 | E12: ='Eastman, Dennis'!Q50 | F12: =SUMPRODUCT((('Eastman, Dennis'!I14+'Eastman, Dennis'!I15)>12)*1)+SUMPRODUCT((('Eastman, Dennis'!I16+'Eastman, Dennis'!I17)>12)*1)+SUMPRODUCT((('Eastman, Dennis'!I18+'Eastman, Dennis'!I19)>12)*1)+SUMPRODUCT((('Eastman, Dennis'!I20+'Eastman, Dennis'!I21)>12)*1)+SUMPRODUCT((('Eastman, Dennis'!I22+'Eastman, Dennis'!I23)>12)*1)+SUMPRODUCT((('Eastman, Dennis'!I24+'Eastman, Dennis'!I25)>12)*1)+SUMPRODUCT((('Eastman, Dennis'!I26+'Eastman, Dennis'!I27)>12)*1)+SUMPRODUCT((('Eastman, Dennis'!I30+'Eastman, Dennis'!I31)>12)*1)+SUMPRODUCT((('Eastman, Dennis'!I32+'Eastman, Dennis'!I33)>12)*1)+SUMPRODUCT((('Eastman, Dennis'!I34+'Eastman, Dennis'!I35)>12)*1)+SUMPRODUCT((('Eastman, Dennis'!I36+'Eastman, Dennis'!I37)>12)*1)+SUMPRODUCT((('Eastman, Dennis'!I38+'Eastman, Dennis'!I39)>12)*1)+SUMPRODUCT((('Eastman, Dennis'!I40+'Eastman, Dennis'!I41)>12)*1)+SUMPRODUCT((('Eastman, Dennis'!I42+'Eastman, Dennis'!I43)>12)*1)+SUMPRODUCT((('Eastman, Dennis'!I45+'Eastman, Dennis'!I46)>12)*1)+SUMPRODUCT((('Eastman, Dennis'!I47+'Eastman, Dennis'!I48)>12)*1) | G12: =IF(MAX(SUM('Eastman, Dennis'!I14:I27),SUM('Eastman, Dennis'!I30:I43))>60,"Yes","") | H12: =IF(OR(AND(('Eastman, Dennis'!I14+'Eastman, Dennis'!I15)>0,('Eastman, Dennis'!I16+'Eastman, Dennis'!I17)>0,('Eastman, Dennis'!I18+'Eastman, Dennis'!I19)>0,('Eastman, Dennis'!I20+'Eastman, Dennis'!I21)>0,('Eastman, Dennis'!I22+'Eastman, Dennis'!I23)>0,('Eastman, Dennis'!I24+'Eastman, Dennis'!I25)>0,('Eastman, Dennis'!I26+'Eastman, Dennis'!I27)>0),AND(('Eastman, Dennis'!I30+'Eastman, Dennis'!I31)>0,('Eastman, Dennis'!I32+'Eastman, Dennis'!I33)>0,('Eastman, Dennis'!I34+'Eastman, Dennis'!I35)>0,('Eastman, Dennis'!I36+'Eastman, Dennis'!I37)>0,('Eastman, Dennis'!I38+'Eastman, Dennis'!I39)>0,('Eastman, Dennis'!I40+'Eastman, Dennis'!I41)>0,('Eastman, Dennis'!I42+'Eastman, Dennis'!I43)>0)),"Yes","") | I12: =IF('Eastman, Dennis'!N49>40,"Yes","") | J12: =IF(OR(AND(SUM('Eastman, Dennis'!I14:I27)>0,SUM('Eastman, Dennis'!I14:I27)<40),AND(SUM('Eastman, Dennis'!I30:I43)>0,SUM('Eastman, Dennis'!I30:I43)<40)),"Yes","") | K12: =SUMPRODUCT(('Eastman, Dennis'!I14:I48>0)*('Eastman, Dennis'!I14:I48<8)) | L12: =IF('Eastman, Dennis'!Q50<5,"Yes","") | M12: =IF(AND('Eastman, Dennis'!I49>0,'Eastman, Dennis'!I49<80),"Yes","") | N12: =IF(OR(F12>0,G12="Yes",H12="Yes",I12="Yes"),"⚠️ OVERWORK",IF(OR(J12="Yes",K12>0,L12="Yes",M12="Yes"),"🔻 UNDERWORK","✓ OK"))
A13: 9 | B13: Eastman, Dorritte Anita | C13: 5062 | D13: ='Eastman, Dorritte'!I49 | E13: ='Eastman, Dorritte'!Q50 | F13: =SUMPRODUCT((('Eastman, Dorritte'!I14+'Eastman, Dorritte'!I15)>12)*1)+SUMPRODUCT((('Eastman, Dorritte'!I16+'Eastman, Dorritte'!I17)>12)*1)+SUMPRODUCT((('Eastman, Dorritte'!I18+'Eastman, Dorritte'!I19)>12)*1)+SUMPRODUCT((('Eastman, Dorritte'!I20+'Eastman, Dorritte'!I21)>12)*1)+SUMPRODUCT((('Eastman, Dorritte'!I22+'Eastman, Dorritte'!I23)>12)*1)+SUMPRODUCT((('Eastman, Dorritte'!I24+'Eastman, Dorritte'!I25)>12)*1)+SUMPRODUCT((('Eastman, Dorritte'!I26+'Eastman, Dorritte'!I27)>12)*1)+SUMPRODUCT((('Eastman, Dorritte'!I30+'Eastman, Dorritte'!I31)>12)*1)+SUMPRODUCT((('Eastman, Dorritte'!I32+'Eastman, Dorritte'!I33)>12)*1)+SUMPRODUCT((('Eastman, Dorritte'!I34+'Eastman, Dorritte'!I35)>12)*1)+SUMPRODUCT((('Eastman, Dorritte'!I36+'Eastman, Dorritte'!I37)>12)*1)+SUMPRODUCT((('Eastman, Dorritte'!I38+'Eastman, Dorritte'!I39)>12)*1)+SUMPRODUCT((('Eastman, Dorritte'!I40+'Eastman, Dorritte'!I41)>12)*1)+SUMPRODUCT((('Eastman, Dorritte'!I42+'Eastman, Dorritte'!I43)>12)*1)+SUMPRODUCT((('Eastman, Dorritte'!I45+'Eastman, Dorritte'!I46)>12)*1)+SUMPRODUCT((('Eastman, Dorritte'!I47+'Eastman, Dorritte'!I48)>12)*1) | G13: =IF(MAX(SUM('Eastman, Dorritte'!I14:I27),SUM('Eastman, Dorritte'!I30:I43))>60,"Yes","") | H13: =IF(OR(AND(('Eastman, Dorritte'!I14+'Eastman, Dorritte'!I15)>0,('Eastman, Dorritte'!I16+'Eastman, Dorritte'!I17)>0,('Eastman, Dorritte'!I18+'Eastman, Dorritte'!I19)>0,('Eastman, Dorritte'!I20+'Eastman, Dorritte'!I21)>0,('Eastman, Dorritte'!I22+'Eastman, Dorritte'!I23)>0,('Eastman, Dorritte'!I24+'Eastman, Dorritte'!I25)>0,('Eastman, Dorritte'!I26+'Eastman, Dorritte'!I27)>0),AND(('Eastman, Dorritte'!I30+'Eastman, Dorritte'!I31)>0,('Eastman, Dorritte'!I32+'Eastman, Dorritte'!I33)>0,('Eastman, Dorritte'!I34+'Eastman, Dorritte'!I35)>0,('Eastman, Dorritte'!I36+'Eastman, Dorritte'!I37)>0,('Eastman, Dorritte'!I38+'Eastman, Dorritte'!I39)>0,('Eastman, Dorritte'!I40+'Eastman, Dorritte'!I41)>0,('Eastman, Dorritte'!I42+'Eastman, Dorritte'!I43)>0)),"Yes","") | I13: =IF('Eastman, Dorritte'!N49>40,"Yes","") | J13: =IF(OR(AND(SUM('Eastman, Dorritte'!I14:I27)>0,SUM('Eastman, Dorritte'!I14:I27)<40),AND(SUM('Eastman, Dorritte'!I30:I43)>0,SUM('Eastman, Dorritte'!I30:I43)<40)),"Yes","") | K13: =SUMPRODUCT(('Eastman, Dorritte'!I14:I48>0)*('Eastman, Dorritte'!I14:I48<8)) | L13: =IF('Eastman, Dorritte'!Q50<5,"Yes","") | M13: =IF(AND('Eastman, Dorritte'!I49>0,'Eastman, Dorritte'!I49<80),"Yes","") | N13: =IF(OR(F13>0,G13="Yes",H13="Yes",I13="Yes"),"⚠️ OVERWORK",IF(OR(J13="Yes",K13>0,L13="Yes",M13="Yes"),"🔻 UNDERWORK","✓ OK"))
A14: 10 | B14: Grant, Earl | C14: 4087 | D14: ='Grant, Earl'!I49 | E14: ='Grant, Earl'!Q50 | F14: =SUMPRODUCT((('Grant, Earl'!I14+'Grant, Earl'!I15)>12)*1)+SUMPRODUCT((('Grant, Earl'!I16+'Grant, Earl'!I17)>12)*1)+SUMPRODUCT((('Grant, Earl'!I18+'Grant, Earl'!I19)>12)*1)+SUMPRODUCT((('Grant, Earl'!I20+'Grant, Earl'!I21)>12)*1)+SUMPRODUCT((('Grant, Earl'!I22+'Grant, Earl'!I23)>12)*1)+SUMPRODUCT((('Grant, Earl'!I24+'Grant, Earl'!I25)>12)*1)+SUMPRODUCT((('Grant, Earl'!I26+'Grant, Earl'!I27)>12)*1)+SUMPRODUCT((('Grant, Earl'!I30+'Grant, Earl'!I31)>12)*1)+SUMPRODUCT((('Grant, Earl'!I32+'Grant, Earl'!I33)>12)*1)+SUMPRODUCT((('Grant, Earl'!I34+'Grant, Earl'!I35)>12)*1)+SUMPRODUCT((('Grant, Earl'!I36+'Grant, Earl'!I37)>12)*1)+SUMPRODUCT((('Grant, Earl'!I38+'Grant, Earl'!I39)>12)*1)+SUMPRODUCT((('Grant, Earl'!I40+'Grant, Earl'!I41)>12)*1)+SUMPRODUCT((('Grant, Earl'!I42+'Grant, Earl'!I43)>12)*1)+SUMPRODUCT((('Grant, Earl'!I45+'Grant, Earl'!I46)>12)*1)+SUMPRODUCT((('Grant, Earl'!I47+'Grant, Earl'!I48)>12)*1) | G14: =IF(MAX(SUM('Grant, Earl'!I14:I27),SUM('Grant, Earl'!I30:I43))>60,"Yes","") | H14: =IF(OR(AND(('Grant, Earl'!I14+'Grant, Earl'!I15)>0,('Grant, Earl'!I16+'Grant, Earl'!I17)>0,('Grant, Earl'!I18+'Grant, Earl'!I19)>0,('Grant, Earl'!I20+'Grant, Earl'!I21)>0,('Grant, Earl'!I22+'Grant, Earl'!I23)>0,('Grant, Earl'!I24+'Grant, Earl'!I25)>0,('Grant, Earl'!I26+'Grant, Earl'!I27)>0),AND(('Grant, Earl'!I30+'Grant, Earl'!I31)>0,('Grant, Earl'!I32+'Grant, Earl'!I33)>0,('Grant, Earl'!I34+'Grant, Earl'!I35)>0,('Grant, Earl'!I36+'Grant, Earl'!I37)>0,('Grant, Earl'!I38+'Grant, Earl'!I39)>0,('Grant, Earl'!I40+'Grant, Earl'!I41)>0,('Grant, Earl'!I42+'Grant, Earl'!I43)>0)),"Yes","") | I14: =IF('Grant, Earl'!N49>40,"Yes","") | J14: =IF(OR(AND(SUM('Grant, Earl'!I14:I27)>0,SUM('Grant, Earl'!I14:I27)<40),AND(SUM('Grant, Earl'!I30:I43)>0,SUM('Grant, Earl'!I30:I43)<40)),"Yes","") | K14: =SUMPRODUCT(('Grant, Earl'!I14:I48>0)*('Grant, Earl'!I14:I48<8)) | L14: =IF('Grant, Earl'!Q50<5,"Yes","") | M14: =IF(AND('Grant, Earl'!I49>0,'Grant, Earl'!I49<80),"Yes","") | N14: =IF(OR(F14>0,G14="Yes",H14="Yes",I14="Yes"),"⚠️ OVERWORK",IF(OR(J14="Yes",K14>0,L14="Yes",M14="Yes"),"🔻 UNDERWORK","✓ OK"))
A15: 11 | B15: Harry, Dennis Eleazar | C15: 2697 | D15: ='Harry, Dennis'!I49 | E15: ='Harry, Dennis'!Q50 | F15: =SUMPRODUCT((('Harry, Dennis'!I14+'Harry, Dennis'!I15)>12)*1)+SUMPRODUCT((('Harry, Dennis'!I16+'Harry, Dennis'!I17)>12)*1)+SUMPRODUCT((('Harry, Dennis'!I18+'Harry, Dennis'!I19)>12)*1)+SUMPRODUCT((('Harry, Dennis'!I20+'Harry, Dennis'!I21)>12)*1)+SUMPRODUCT((('Harry, Dennis'!I22+'Harry, Dennis'!I23)>12)*1)+SUMPRODUCT((('Harry, Dennis'!I24+'Harry, Dennis'!I25)>12)*1)+SUMPRODUCT((('Harry, Dennis'!I26+'Harry, Dennis'!I27)>12)*1)+SUMPRODUCT((('Harry, Dennis'!I30+'Harry, Dennis'!I31)>12)*1)+SUMPRODUCT((('Harry, Dennis'!I32+'Harry, Dennis'!I33)>12)*1)+SUMPRODUCT((('Harry, Dennis'!I34+'Harry, Dennis'!I35)>12)*1)+SUMPRODUCT((('Harry, Dennis'!I36+'Harry, Dennis'!I37)>12)*1)+SUMPRODUCT((('Harry, Dennis'!I38+'Harry, Dennis'!I39)>12)*1)+SUMPRODUCT((('Harry, Dennis'!I40+'Harry, Dennis'!I41)>12)*1)+SUMPRODUCT((('Harry, Dennis'!I42+'Harry, Dennis'!I43)>12)*1)+SUMPRODUCT((('Harry, Dennis'!I45+'Harry, Dennis'!I46)>12)*1)+SUMPRODUCT((('Harry, Dennis'!I47+'Harry, Dennis'!I48)>12)*1) | G15: =IF(MAX(SUM('Harry, Dennis'!I14:I27),SUM('Harry, Dennis'!I30:I43))>60,"Yes","") | H15: =IF(OR(AND(('Harry, Dennis'!I14+'Harry, Dennis'!I15)>0,('Harry, Dennis'!I16+'Harry, Dennis'!I17)>0,('Harry, Dennis'!I18+'Harry, Dennis'!I19)>0,('Harry, Dennis'!I20+'Harry, Dennis'!I21)>0,('Harry, Dennis'!I22+'Harry, Dennis'!I23)>0,('Harry, Dennis'!I24+'Harry, Dennis'!I25)>0,('Harry, Dennis'!I26+'Harry, Dennis'!I27)>0),AND(('Harry, Dennis'!I30+'Harry, Dennis'!I31)>0,('Harry, Dennis'!I32+'Harry, Dennis'!I33)>0,('Harry, Dennis'!I34+'Harry, Dennis'!I35)>0,('Harry, Dennis'!I36+'Harry, Dennis'!I37)>0,('Harry, Dennis'!I38+'Harry, Dennis'!I39)>0,('Harry, Dennis'!I40+'Harry, Dennis'!I41)>0,('Harry, Dennis'!I42+'Harry, Dennis'!I43)>0)),"Yes","") | I15: =IF('Harry, Dennis'!N49>40,"Yes","") | J15: =IF(OR(AND(SUM('Harry, Dennis'!I14:I27)>0,SUM('Harry, Dennis'!I14:I27)<40),AND(SUM('Harry, Dennis'!I30:I43)>0,SUM('Harry, Dennis'!I30:I43)<40)),"Yes","") | K15: =SUMPRODUCT(('Harry, Dennis'!I14:I48>0)*('Harry, Dennis'!I14:I48<8)) | L15: =IF('Harry, Dennis'!Q50<5,"Yes","") | M15: =IF(AND('Harry, Dennis'!I49>0,'Harry, Dennis'!I49<80),"Yes","") | N15: =IF(OR(F15>0,G15="Yes",H15="Yes",I15="Yes"),"⚠️ OVERWORK",IF(OR(J15="Yes",K15>0,L15="Yes",M15="Yes"),"🔻 UNDERWORK","✓ OK"))
A16: 12 | B16: Hector, Aaliyah Anastacia | C16: 5509 | D16: ='Hector, Aaliyah'!I49 | E16: ='Hector, Aaliyah'!Q50 | F16: =SUMPRODUCT((('Hector, Aaliyah'!I14+'Hector, Aaliyah'!I15)>12)*1)+SUMPRODUCT((('Hector, Aaliyah'!I16+'Hector, Aaliyah'!I17)>12)*1)+SUMPRODUCT((('Hector, Aaliyah'!I18+'Hector, Aaliyah'!I19)>12)*1)+SUMPRODUCT((('Hector, Aaliyah'!I20+'Hector, Aaliyah'!I21)>12)*1)+SUMPRODUCT((('Hector, Aaliyah'!I22+'Hector, Aaliyah'!I23)>12)*1)+SUMPRODUCT((('Hector, Aaliyah'!I24+'Hector, Aaliyah'!I25)>12)*1)+SUMPRODUCT((('Hector, Aaliyah'!I26+'Hector, Aaliyah'!I27)>12)*1)+SUMPRODUCT((('Hector, Aaliyah'!I30+'Hector, Aaliyah'!I31)>12)*1)+SUMPRODUCT((('Hector, Aaliyah'!I32+'Hector, Aaliyah'!I33)>12)*1)+SUMPRODUCT((('Hector, Aaliyah'!I34+'Hector, Aaliyah'!I35)>12)*1)+SUMPRODUCT((('Hector, Aaliyah'!I36+'Hector, Aaliyah'!I37)>12)*1)+SUMPRODUCT((('Hector, Aaliyah'!I38+'Hector, Aaliyah'!I39)>12)*1)+SUMPRODUCT((('Hector, Aaliyah'!I40+'Hector, Aaliyah'!I41)>12)*1)+SUMPRODUCT((('Hector, Aaliyah'!I42+'Hector, Aaliyah'!I43)>12)*1)+SUMPRODUCT((('Hector, Aaliyah'!I45+'Hector, Aaliyah'!I46)>12)*1)+SUMPRODUCT((('Hector, Aaliyah'!I47+'Hector, Aaliyah'!I48)>12)*1) | G16: =IF(MAX(SUM('Hector, Aaliyah'!I14:I27),SUM('Hector, Aaliyah'!I30:I43))>60,"Yes","") | H16: =IF(OR(AND(('Hector, Aaliyah'!I14+'Hector, Aaliyah'!I15)>0,('Hector, Aaliyah'!I16+'Hector, Aaliyah'!I17)>0,('Hector, Aaliyah'!I18+'Hector, Aaliyah'!I19)>0,('Hector, Aaliyah'!I20+'Hector, Aaliyah'!I21)>0,('Hector, Aaliyah'!I22+'Hector, Aaliyah'!I23)>0,('Hector, Aaliyah'!I24+'Hector, Aaliyah'!I25)>0,('Hector, Aaliyah'!I26+'Hector, Aaliyah'!I27)>0),AND(('Hector, Aaliyah'!I30+'Hector, Aaliyah'!I31)>0,('Hector, Aaliyah'!I32+'Hector, Aaliyah'!I33)>0,('Hector, Aaliyah'!I34+'Hector, Aaliyah'!I35)>0,('Hector, Aaliyah'!I36+'Hector, Aaliyah'!I37)>0,('Hector, Aaliyah'!I38+'Hector, Aaliyah'!I39)>0,('Hector, Aaliyah'!I40+'Hector, Aaliyah'!I41)>0,('Hector, Aaliyah'!I42+'Hector, Aaliyah'!I43)>0)),"Yes","") | I16: =IF('Hector, Aaliyah'!N49>40,"Yes","") | J16: =IF(OR(AND(SUM('Hector, Aaliyah'!I14:I27)>0,SUM('Hector, Aaliyah'!I14:I27)<40),AND(SUM('Hector, Aaliyah'!I30:I43)>0,SUM('Hector, Aaliyah'!I30:I43)<40)),"Yes","") | K16: =SUMPRODUCT(('Hector, Aaliyah'!I14:I48>0)*('Hector, Aaliyah'!I14:I48<8)) | L16: =IF('Hector, Aaliyah'!Q50<5,"Yes","") | M16: =IF(AND('Hector, Aaliyah'!I49>0,'Hector, Aaliyah'!I49<80),"Yes","") | N16: =IF(OR(F16>0,G16="Yes",H16="Yes",I16="Yes"),"⚠️ OVERWORK",IF(OR(J16="Yes",K16>0,L16="Yes",M16="Yes"),"🔻 UNDERWORK","✓ OK"))
A17: 13 | B17: Hector, Onicka Felicity | C17: 5508 | D17: ='Hector, Onicka'!I49 | E17: ='Hector, Onicka'!Q50 | F17: =SUMPRODUCT((('Hector, Onicka'!I14+'Hector, Onicka'!I15)>12)*1)+SUMPRODUCT((('Hector, Onicka'!I16+'Hector, Onicka'!I17)>12)*1)+SUMPRODUCT((('Hector, Onicka'!I18+'Hector, Onicka'!I19)>12)*1)+SUMPRODUCT((('Hector, Onicka'!I20+'Hector, Onicka'!I21)>12)*1)+SUMPRODUCT((('Hector, Onicka'!I22+'Hector, Onicka'!I23)>12)*1)+SUMPRODUCT((('Hector, Onicka'!I24+'Hector, Onicka'!I25)>12)*1)+SUMPRODUCT((('Hector, Onicka'!I26+'Hector, Onicka'!I27)>12)*1)+SUMPRODUCT((('Hector, Onicka'!I30+'Hector, Onicka'!I31)>12)*1)+SUMPRODUCT((('Hector, Onicka'!I32+'Hector, Onicka'!I33)>12)*1)+SUMPRODUCT((('Hector, Onicka'!I34+'Hector, Onicka'!I35)>12)*1)+SUMPRODUCT((('Hector, Onicka'!I36+'Hector, Onicka'!I37)>12)*1)+SUMPRODUCT((('Hector, Onicka'!I38+'Hector, Onicka'!I39)>12)*1)+SUMPRODUCT((('Hector, Onicka'!I40+'Hector, Onicka'!I41)>12)*1)+SUMPRODUCT((('Hector, Onicka'!I42+'Hector, Onicka'!I43)>12)*1)+SUMPRODUCT((('Hector, Onicka'!I45+'Hector, Onicka'!I46)>12)*1)+SUMPRODUCT((('Hector, Onicka'!I47+'Hector, Onicka'!I48)>12)*1) | G17: =IF(MAX(SUM('Hector, Onicka'!I14:I27),SUM('Hector, Onicka'!I30:I43))>60,"Yes","") | H17: =IF(OR(AND(('Hector, Onicka'!I14+'Hector, Onicka'!I15)>0,('Hector, Onicka'!I16+'Hector, Onicka'!I17)>0,('Hector, Onicka'!I18+'Hector, Onicka'!I19)>0,('Hector, Onicka'!I20+'Hector, Onicka'!I21)>0,('Hector, Onicka'!I22+'Hector, Onicka'!I23)>0,('Hector, Onicka'!I24+'Hector, Onicka'!I25)>0,('Hector, Onicka'!I26+'Hector, Onicka'!I27)>0),AND(('Hector, Onicka'!I30+'Hector, Onicka'!I31)>0,('Hector, Onicka'!I32+'Hector, Onicka'!I33)>0,('Hector, Onicka'!I34+'Hector, Onicka'!I35)>0,('Hector, Onicka'!I36+'Hector, Onicka'!I37)>0,('Hector, Onicka'!I38+'Hector, Onicka'!I39)>0,('Hector, Onicka'!I40+'Hector, Onicka'!I41)>0,('Hector, Onicka'!I42+'Hector, Onicka'!I43)>0)),"Yes","") | I17: =IF('Hector, Onicka'!N49>40,"Yes","") | J17: =IF(OR(AND(SUM('Hector, Onicka'!I14:I27)>0,SUM('Hector, Onicka'!I14:I27)<40),AND(SUM('Hector, Onicka'!I30:I43)>0,SUM('Hector, Onicka'!I30:I43)<40)),"Yes","") | K17: =SUMPRODUCT(('Hector, Onicka'!I14:I48>0)*('Hector, Onicka'!I14:I48<8)) | L17: =IF('Hector, Onicka'!Q50<5,"Yes","") | M17: =IF(AND('Hector, Onicka'!I49>0,'Hector, Onicka'!I49<80),"Yes","") | N17: =IF(OR(F17>0,G17="Yes",H17="Yes",I17="Yes"),"⚠️ OVERWORK",IF(OR(J17="Yes",K17>0,L17="Yes",M17="Yes"),"🔻 UNDERWORK","✓ OK"))
A18: 14 | B18: Inniss, Euci Patrice | C18: 4959 | D18: ='Inniss, Euci'!I49 | E18: ='Inniss, Euci'!Q50 | F18: =SUMPRODUCT((('Inniss, Euci'!I14+'Inniss, Euci'!I15)>12)*1)+SUMPRODUCT((('Inniss, Euci'!I16+'Inniss, Euci'!I17)>12)*1)+SUMPRODUCT((('Inniss, Euci'!I18+'Inniss, Euci'!I19)>12)*1)+SUMPRODUCT((('Inniss, Euci'!I20+'Inniss, Euci'!I21)>12)*1)+SUMPRODUCT((('Inniss, Euci'!I22+'Inniss, Euci'!I23)>12)*1)+SUMPRODUCT((('Inniss, Euci'!I24+'Inniss, Euci'!I25)>12)*1)+SUMPRODUCT((('Inniss, Euci'!I26+'Inniss, Euci'!I27)>12)*1)+SUMPRODUCT((('Inniss, Euci'!I30+'Inniss, Euci'!I31)>12)*1)+SUMPRODUCT((('Inniss, Euci'!I32+'Inniss, Euci'!I33)>12)*1)+SUMPRODUCT((('Inniss, Euci'!I34+'Inniss, Euci'!I35)>12)*1)+SUMPRODUCT((('Inniss, Euci'!I36+'Inniss, Euci'!I37)>12)*1)+SUMPRODUCT((('Inniss, Euci'!I38+'Inniss, Euci'!I39)>12)*1)+SUMPRODUCT((('Inniss, Euci'!I40+'Inniss, Euci'!I41)>12)*1)+SUMPRODUCT((('Inniss, Euci'!I42+'Inniss, Euci'!I43)>12)*1)+SUMPRODUCT((('Inniss, Euci'!I45+'Inniss, Euci'!I46)>12)*1)+SUMPRODUCT((('Inniss, Euci'!I47+'Inniss, Euci'!I48)>12)*1) | G18: =IF(MAX(SUM('Inniss, Euci'!I14:I27),SUM('Inniss, Euci'!I30:I43))>60,"Yes","") | H18: =IF(OR(AND(('Inniss, Euci'!I14+'Inniss, Euci'!I15)>0,('Inniss, Euci'!I16+'Inniss, Euci'!I17)>0,('Inniss, Euci'!I18+'Inniss, Euci'!I19)>0,('Inniss, Euci'!I20+'Inniss, Euci'!I21)>0,('Inniss, Euci'!I22+'Inniss, Euci'!I23)>0,('Inniss, Euci'!I24+'Inniss, Euci'!I25)>0,('Inniss, Euci'!I26+'Inniss, Euci'!I27)>0),AND(('Inniss, Euci'!I30+'Inniss, Euci'!I31)>0,('Inniss, Euci'!I32+'Inniss, Euci'!I33)>0,('Inniss, Euci'!I34+'Inniss, Euci'!I35)>0,('Inniss, Euci'!I36+'Inniss, Euci'!I37)>0,('Inniss, Euci'!I38+'Inniss, Euci'!I39)>0,('Inniss, Euci'!I40+'Inniss, Euci'!I41)>0,('Inniss, Euci'!I42+'Inniss, Euci'!I43)>0)),"Yes","") | I18: =IF('Inniss, Euci'!N49>40,"Yes","") | J18: =IF(OR(AND(SUM('Inniss, Euci'!I14:I27)>0,SUM('Inniss, Euci'!I14:I27)<40),AND(SUM('Inniss, Euci'!I30:I43)>0,SUM('Inniss, Euci'!I30:I43)<40)),"Yes","") | K18: =SUMPRODUCT(('Inniss, Euci'!I14:I48>0)*('Inniss, Euci'!I14:I48<8)) | L18: =IF('Inniss, Euci'!Q50<5,"Yes","") | M18: =IF(AND('Inniss, Euci'!I49>0,'Inniss, Euci'!I49<80),"Yes","") | N18: =IF(OR(F18>0,G18="Yes",H18="Yes",I18="Yes"),"⚠️ OVERWORK",IF(OR(J18="Yes",K18>0,L18="Yes",M18="Yes"),"🔻 UNDERWORK","✓ OK"))
A19: 15 | B19: Khan, Ahmad | C19: 3219 | D19: ='Khan, Ahmad'!I49 | E19: ='Khan, Ahmad'!Q50 | F19: =SUMPRODUCT((('Khan, Ahmad'!I14+'Khan, Ahmad'!I15)>12)*1)+SUMPRODUCT((('Khan, Ahmad'!I16+'Khan, Ahmad'!I17)>12)*1)+SUMPRODUCT((('Khan, Ahmad'!I18+'Khan, Ahmad'!I19)>12)*1)+SUMPRODUCT((('Khan, Ahmad'!I20+'Khan, Ahmad'!I21)>12)*1)+SUMPRODUCT((('Khan, Ahmad'!I22+'Khan, Ahmad'!I23)>12)*1)+SUMPRODUCT((('Khan, Ahmad'!I24+'Khan, Ahmad'!I25)>12)*1)+SUMPRODUCT((('Khan, Ahmad'!I26+'Khan, Ahmad'!I27)>12)*1)+SUMPRODUCT((('Khan, Ahmad'!I30+'Khan, Ahmad'!I31)>12)*1)+SUMPRODUCT((('Khan, Ahmad'!I32+'Khan, Ahmad'!I33)>12)*1)+SUMPRODUCT((('Khan, Ahmad'!I34+'Khan, Ahmad'!I35)>12)*1)+SUMPRODUCT((('Khan, Ahmad'!I36+'Khan, Ahmad'!I37)>12)*1)+SUMPRODUCT((('Khan, Ahmad'!I38+'Khan, Ahmad'!I39)>12)*1)+SUMPRODUCT((('Khan, Ahmad'!I40+'Khan, Ahmad'!I41)>12)*1)+SUMPRODUCT((('Khan, Ahmad'!I42+'Khan, Ahmad'!I43)>12)*1)+SUMPRODUCT((('Khan, Ahmad'!I45+'Khan, Ahmad'!I46)>12)*1)+SUMPRODUCT((('Khan, Ahmad'!I47+'Khan, Ahmad'!I48)>12)*1) | G19: =IF(MAX(SUM('Khan, Ahmad'!I14:I27),SUM('Khan, Ahmad'!I30:I43))>60,"Yes","") | H19: =IF(OR(AND(('Khan, Ahmad'!I14+'Khan, Ahmad'!I15)>0,('Khan, Ahmad'!I16+'Khan, Ahmad'!I17)>0,('Khan, Ahmad'!I18+'Khan, Ahmad'!I19)>0,('Khan, Ahmad'!I20+'Khan, Ahmad'!I21)>0,('Khan, Ahmad'!I22+'Khan, Ahmad'!I23)>0,('Khan, Ahmad'!I24+'Khan, Ahmad'!I25)>0,('Khan, Ahmad'!I26+'Khan, Ahmad'!I27)>0),AND(('Khan, Ahmad'!I30+'Khan, Ahmad'!I31)>0,('Khan, Ahmad'!I32+'Khan, Ahmad'!I33)>0,('Khan, Ahmad'!I34+'Khan, Ahmad'!I35)>0,('Khan, Ahmad'!I36+'Khan, Ahmad'!I37)>0,('Khan, Ahmad'!I38+'Khan, Ahmad'!I39)>0,('Khan, Ahmad'!I40+'Khan, Ahmad'!I41)>0,('Khan, Ahmad'!I42+'Khan, Ahmad'!I43)>0)),"Yes","") | I19: =IF('Khan, Ahmad'!N49>40,"Yes","") | J19: =IF(OR(AND(SUM('Khan, Ahmad'!I14:I27)>0,SUM('Khan, Ahmad'!I14:I27)<40),AND(SUM('Khan, Ahmad'!I30:I43)>0,SUM('Khan, Ahmad'!I30:I43)<40)),"Yes","") | K19: =SUMPRODUCT(('Khan, Ahmad'!I14:I48>0)*('Khan, Ahmad'!I14:I48<8)) | L19: =IF('Khan, Ahmad'!Q50<5,"Yes","") | M19: =IF(AND('Khan, Ahmad'!I49>0,'Khan, Ahmad'!I49<80),"Yes","") | N19: =IF(OR(F19>0,G19="Yes",H19="Yes",I19="Yes"),"⚠️ OVERWORK",IF(OR(J19="Yes",K19>0,L19="Yes",M19="Yes"),"🔻 UNDERWORK","✓ OK"))
A20: 16 | B20: Lawrence, Stephen Rawle | C20: 5134 | D20: ='Lawrence, Stephen'!I49 | E20: ='Lawrence, Stephen'!Q50 | F20: =SUMPRODUCT((('Lawrence, Stephen'!I14+'Lawrence, Stephen'!I15)>12)*1)+SUMPRODUCT((('Lawrence, Stephen'!I16+'Lawrence, Stephen'!I17)>12)*1)+SUMPRODUCT((('Lawrence, Stephen'!I18+'Lawrence, Stephen'!I19)>12)*1)+SUMPRODUCT((('Lawrence, Stephen'!I20+'Lawrence, Stephen'!I21)>12)*1)+SUMPRODUCT((('Lawrence, Stephen'!I22+'Lawrence, Stephen'!I23)>12)*1)+SUMPRODUCT((('Lawrence, Stephen'!I24+'Lawrence, Stephen'!I25)>12)*1)+SUMPRODUCT((('Lawrence, Stephen'!I26+'Lawrence, Stephen'!I27)>12)*1)+SUMPRODUCT((('Lawrence, Stephen'!I30+'Lawrence, Stephen'!I31)>12)*1)+SUMPRODUCT((('Lawrence, Stephen'!I32+'Lawrence, Stephen'!I33)>12)*1)+SUMPRODUCT((('Lawrence, Stephen'!I34+'Lawrence, Stephen'!I35)>12)*1)+SUMPRODUCT((('Lawrence, Stephen'!I36+'Lawrence, Stephen'!I37)>12)*1)+SUMPRODUCT((('Lawrence, Stephen'!I38+'Lawrence, Stephen'!I39)>12)*1)+SUMPRODUCT((('Lawrence, Stephen'!I40+'Lawrence, Stephen'!I41)>12)*1)+SUMPRODUCT((('Lawrence, Stephen'!I42+'Lawrence, Stephen'!I43)>12)*1)+SUMPRODUCT((('Lawrence, Stephen'!I45+'Lawrence, Stephen'!I46)>12)*1)+SUMPRODUCT((('Lawrence, Stephen'!I47+'Lawrence, Stephen'!I48)>12)*1) | G20: =IF(MAX(SUM('Lawrence, Stephen'!I14:I27),SUM('Lawrence, Stephen'!I30:I43))>60,"Yes","") | H20: =IF(OR(AND(('Lawrence, Stephen'!I14+'Lawrence, Stephen'!I15)>0,('Lawrence, Stephen'!I16+'Lawrence, Stephen'!I17)>0,('Lawrence, Stephen'!I18+'Lawrence, Stephen'!I19)>0,('Lawrence, Stephen'!I20+'Lawrence, Stephen'!I21)>0,('Lawrence, Stephen'!I22+'Lawrence, Stephen'!I23)>0,('Lawrence, Stephen'!I24+'Lawrence, Stephen'!I25)>0,('Lawrence, Stephen'!I26+'Lawrence, Stephen'!I27)>0),AND(('Lawrence, Stephen'!I30+'Lawrence, Stephen'!I31)>0,('Lawrence, Stephen'!I32+'Lawrence, Stephen'!I33)>0,('Lawrence, Stephen'!I34+'Lawrence, Stephen'!I35)>0,('Lawrence, Stephen'!I36+'Lawrence, Stephen'!I37)>0,('Lawrence, Stephen'!I38+'Lawrence, Stephen'!I39)>0,('Lawrence, Stephen'!I40+'Lawrence, Stephen'!I41)>0,('Lawrence, Stephen'!I42+'Lawrence, Stephen'!I43)>0)),"Yes","") | I20: =IF('Lawrence, Stephen'!N49>40,"Yes","") | J20: =IF(OR(AND(SUM('Lawrence, Stephen'!I14:I27)>0,SUM('Lawrence, Stephen'!I14:I27)<40),AND(SUM('Lawrence, Stephen'!I30:I43)>0,SUM('Lawrence, Stephen'!I30:I43)<40)),"Yes","") | K20: =SUMPRODUCT(('Lawrence, Stephen'!I14:I48>0)*('Lawrence, Stephen'!I14:I48<8)) | L20: =IF('Lawrence, Stephen'!Q50<5,"Yes","") | M20: =IF(AND('Lawrence, Stephen'!I49>0,'Lawrence, Stephen'!I49<80),"Yes","") | N20: =IF(OR(F20>0,G20="Yes",H20="Yes",I20="Yes"),"⚠️ OVERWORK",IF(OR(J20="Yes",K20>0,L20="Yes",M20="Yes"),"🔻 UNDERWORK","✓ OK"))
A21: 17 | B21: Lawson, Delicia Alicia | C21: 4465 | D21: ='Lawson, Delicia'!I49 | E21: ='Lawson, Delicia'!Q50 | F21: =SUMPRODUCT((('Lawson, Delicia'!I14+'Lawson, Delicia'!I15)>12)*1)+SUMPRODUCT((('Lawson, Delicia'!I16+'Lawson, Delicia'!I17)>12)*1)+SUMPRODUCT((('Lawson, Delicia'!I18+'Lawson, Delicia'!I19)>12)*1)+SUMPRODUCT((('Lawson, Delicia'!I20+'Lawson, Delicia'!I21)>12)*1)+SUMPRODUCT((('Lawson, Delicia'!I22+'Lawson, Delicia'!I23)>12)*1)+SUMPRODUCT((('Lawson, Delicia'!I24+'Lawson, Delicia'!I25)>12)*1)+SUMPRODUCT((('Lawson, Delicia'!I26+'Lawson, Delicia'!I27)>12)*1)+SUMPRODUCT((('Lawson, Delicia'!I30+'Lawson, Delicia'!I31)>12)*1)+SUMPRODUCT((('Lawson, Delicia'!I32+'Lawson, Delicia'!I33)>12)*1)+SUMPRODUCT((('Lawson, Delicia'!I34+'Lawson, Delicia'!I35)>12)*1)+SUMPRODUCT((('Lawson, Delicia'!I36+'Lawson, Delicia'!I37)>12)*1)+SUMPRODUCT((('Lawson, Delicia'!I38+'Lawson, Delicia'!I39)>12)*1)+SUMPRODUCT((('Lawson, Delicia'!I40+'Lawson, Delicia'!I41)>12)*1)+SUMPRODUCT((('Lawson, Delicia'!I42+'Lawson, Delicia'!I43)>12)*1)+SUMPRODUCT((('Lawson, Delicia'!I45+'Lawson, Delicia'!I46)>12)*1)+SUMPRODUCT((('Lawson, Delicia'!I47+'Lawson, Delicia'!I48)>12)*1) | G21: =IF(MAX(SUM('Lawson, Delicia'!I14:I27),SUM('Lawson, Delicia'!I30:I43))>60,"Yes","") | H21: =IF(OR(AND(('Lawson, Delicia'!I14+'Lawson, Delicia'!I15)>0,('Lawson, Delicia'!I16+'Lawson, Delicia'!I17)>0,('Lawson, Delicia'!I18+'Lawson, Delicia'!I19)>0,('Lawson, Delicia'!I20+'Lawson, Delicia'!I21)>0,('Lawson, Delicia'!I22+'Lawson, Delicia'!I23)>0,('Lawson, Delicia'!I24+'Lawson, Delicia'!I25)>0,('Lawson, Delicia'!I26+'Lawson, Delicia'!I27)>0),AND(('Lawson, Delicia'!I30+'Lawson, Delicia'!I31)>0,('Lawson, Delicia'!I32+'Lawson, Delicia'!I33)>0,('Lawson, Delicia'!I34+'Lawson, Delicia'!I35)>0,('Lawson, Delicia'!I36+'Lawson, Delicia'!I37)>0,('Lawson, Delicia'!I38+'Lawson, Delicia'!I39)>0,('Lawson, Delicia'!I40+'Lawson, Delicia'!I41)>0,('Lawson, Delicia'!I42+'Lawson, Delicia'!I43)>0)),"Yes","") | I21: =IF('Lawson, Delicia'!N49>40,"Yes","") | J21: =IF(OR(AND(SUM('Lawson, Delicia'!I14:I27)>0,SUM('Lawson, Delicia'!I14:I27)<40),AND(SUM('Lawson, Delicia'!I30:I43)>0,SUM('Lawson, Delicia'!I30:I43)<40)),"Yes","") | K21: =SUMPRODUCT(('Lawson, Delicia'!I14:I48>0)*('Lawson, Delicia'!I14:I48<8)) | L21: =IF('Lawson, Delicia'!Q50<5,"Yes","") | M21: =IF(AND('Lawson, Delicia'!I49>0,'Lawson, Delicia'!I49<80),"Yes","") | N21: =IF(OR(F21>0,G21="Yes",H21="Yes",I21="Yes"),"⚠️ OVERWORK",IF(OR(J21="Yes",K21>0,L21="Yes",M21="Yes"),"🔻 UNDERWORK","✓ OK"))
A22: 18 | B22: Lewis, Tahandica Fennela | C22: 3767 | D22: ='Lewis, Tahandica'!I49 | E22: ='Lewis, Tahandica'!Q50 | F22: =SUMPRODUCT((('Lewis, Tahandica'!I14+'Lewis, Tahandica'!I15)>12)*1)+SUMPRODUCT((('Lewis, Tahandica'!I16+'Lewis, Tahandica'!I17)>12)*1)+SUMPRODUCT((('Lewis, Tahandica'!I18+'Lewis, Tahandica'!I19)>12)*1)+SUMPRODUCT((('Lewis, Tahandica'!I20+'Lewis, Tahandica'!I21)>12)*1)+SUMPRODUCT((('Lewis, Tahandica'!I22+'Lewis, Tahandica'!I23)>12)*1)+SUMPRODUCT((('Lewis, Tahandica'!I24+'Lewis, Tahandica'!I25)>12)*1)+SUMPRODUCT((('Lewis, Tahandica'!I26+'Lewis, Tahandica'!I27)>12)*1)+SUMPRODUCT((('Lewis, Tahandica'!I30+'Lewis, Tahandica'!I31)>12)*1)+SUMPRODUCT((('Lewis, Tahandica'!I32+'Lewis, Tahandica'!I33)>12)*1)+SUMPRODUCT((('Lewis, Tahandica'!I34+'Lewis, Tahandica'!I35)>12)*1)+SUMPRODUCT((('Lewis, Tahandica'!I36+'Lewis, Tahandica'!I37)>12)*1)+SUMPRODUCT((('Lewis, Tahandica'!I38+'Lewis, Tahandica'!I39)>12)*1)+SUMPRODUCT((('Lewis, Tahandica'!I40+'Lewis, Tahandica'!I41)>12)*1)+SUMPRODUCT((('Lewis, Tahandica'!I42+'Lewis, Tahandica'!I43)>12)*1)+SUMPRODUCT((('Lewis, Tahandica'!I45+'Lewis, Tahandica'!I46)>12)*1)+SUMPRODUCT((('Lewis, Tahandica'!I47+'Lewis, Tahandica'!I48)>12)*1) | G22: =IF(MAX(SUM('Lewis, Tahandica'!I14:I27),SUM('Lewis, Tahandica'!I30:I43))>60,"Yes","") | H22: =IF(OR(AND(('Lewis, Tahandica'!I14+'Lewis, Tahandica'!I15)>0,('Lewis, Tahandica'!I16+'Lewis, Tahandica'!I17)>0,('Lewis, Tahandica'!I18+'Lewis, Tahandica'!I19)>0,('Lewis, Tahandica'!I20+'Lewis, Tahandica'!I21)>0,('Lewis, Tahandica'!I22+'Lewis, Tahandica'!I23)>0,('Lewis, Tahandica'!I24+'Lewis, Tahandica'!I25)>0,('Lewis, Tahandica'!I26+'Lewis, Tahandica'!I27)>0),AND(('Lewis, Tahandica'!I30+'Lewis, Tahandica'!I31)>0,('Lewis, Tahandica'!I32+'Lewis, Tahandica'!I33)>0,('Lewis, Tahandica'!I34+'Lewis, Tahandica'!I35)>0,('Lewis, Tahandica'!I36+'Lewis, Tahandica'!I37)>0,('Lewis, Tahandica'!I38+'Lewis, Tahandica'!I39)>0,('Lewis, Tahandica'!I40+'Lewis, Tahandica'!I41)>0,('Lewis, Tahandica'!I42+'Lewis, Tahandica'!I43)>0)),"Yes","") | I22: =IF('Lewis, Tahandica'!N49>40,"Yes","") | J22: =IF(OR(AND(SUM('Lewis, Tahandica'!I14:I27)>0,SUM('Lewis, Tahandica'!I14:I27)<40),AND(SUM('Lewis, Tahandica'!I30:I43)>0,SUM('Lewis, Tahandica'!I30:I43)<40)),"Yes","") | K22: =SUMPRODUCT(('Lewis, Tahandica'!I14:I48>0)*('Lewis, Tahandica'!I14:I48<8)) | L22: =IF('Lewis, Tahandica'!Q50<5,"Yes","") | M22: =IF(AND('Lewis, Tahandica'!I49>0,'Lewis, Tahandica'!I49<80),"Yes","") | N22: =IF(OR(F22>0,G22="Yes",H22="Yes",I22="Yes"),"⚠️ OVERWORK",IF(OR(J22="Yes",K22>0,L22="Yes",M22="Yes"),"🔻 UNDERWORK","✓ OK"))
A23: 19 | B23: Nelson, Keshia Andrea | C23: 2744 | D23: ='Nelson, Keshia'!I49 | E23: ='Nelson, Keshia'!Q50 | F23: =SUMPRODUCT((('Nelson, Keshia'!I14+'Nelson, Keshia'!I15)>12)*1)+SUMPRODUCT((('Nelson, Keshia'!I16+'Nelson, Keshia'!I17)>12)*1)+SUMPRODUCT((('Nelson, Keshia'!I18+'Nelson, Keshia'!I19)>12)*1)+SUMPRODUCT((('Nelson, Keshia'!I20+'Nelson, Keshia'!I21)>12)*1)+SUMPRODUCT((('Nelson, Keshia'!I22+'Nelson, Keshia'!I23)>12)*1)+SUMPRODUCT((('Nelson, Keshia'!I24+'Nelson, Keshia'!I25)>12)*1)+SUMPRODUCT((('Nelson, Keshia'!I26+'Nelson, Keshia'!I27)>12)*1)+SUMPRODUCT((('Nelson, Keshia'!I30+'Nelson, Keshia'!I31)>12)*1)+SUMPRODUCT((('Nelson, Keshia'!I32+'Nelson, Keshia'!I33)>12)*1)+SUMPRODUCT((('Nelson, Keshia'!I34+'Nelson, Keshia'!I35)>12)*1)+SUMPRODUCT((('Nelson, Keshia'!I36+'Nelson, Keshia'!I37)>12)*1)+SUMPRODUCT((('Nelson, Keshia'!I38+'Nelson, Keshia'!I39)>12)*1)+SUMPRODUCT((('Nelson, Keshia'!I40+'Nelson, Keshia'!I41)>12)*1)+SUMPRODUCT((('Nelson, Keshia'!I42+'Nelson, Keshia'!I43)>12)*1)+SUMPRODUCT((('Nelson, Keshia'!I45+'Nelson, Keshia'!I46)>12)*1)+SUMPRODUCT((('Nelson, Keshia'!I47+'Nelson, Keshia'!I48)>12)*1) | G23: =IF(MAX(SUM('Nelson, Keshia'!I14:I27),SUM('Nelson, Keshia'!I30:I43))>60,"Yes","") | H23: =IF(OR(AND(('Nelson, Keshia'!I14+'Nelson, Keshia'!I15)>0,('Nelson, Keshia'!I16+'Nelson, Keshia'!I17)>0,('Nelson, Keshia'!I18+'Nelson, Keshia'!I19)>0,('Nelson, Keshia'!I20+'Nelson, Keshia'!I21)>0,('Nelson, Keshia'!I22+'Nelson, Keshia'!I23)>0,('Nelson, Keshia'!I24+'Nelson, Keshia'!I25)>0,('Nelson, Keshia'!I26+'Nelson, Keshia'!I27)>0),AND(('Nelson, Keshia'!I30+'Nelson, Keshia'!I31)>0,('Nelson, Keshia'!I32+'Nelson, Keshia'!I33)>0,('Nelson, Keshia'!I34+'Nelson, Keshia'!I35)>0,('Nelson, Keshia'!I36+'Nelson, Keshia'!I37)>0,('Nelson, Keshia'!I38+'Nelson, Keshia'!I39)>0,('Nelson, Keshia'!I40+'Nelson, Keshia'!I41)>0,('Nelson, Keshia'!I42+'Nelson, Keshia'!I43)>0)),"Yes","") | I23: =IF('Nelson, Keshia'!N49>40,"Yes","") | J23: =IF(OR(AND(SUM('Nelson, Keshia'!I14:I27)>0,SUM('Nelson, Keshia'!I14:I27)<40),AND(SUM('Nelson, Keshia'!I30:I43)>0,SUM('Nelson, Keshia'!I30:I43)<40)),"Yes","") | K23: =SUMPRODUCT(('Nelson, Keshia'!I14:I48>0)*('Nelson, Keshia'!I14:I48<8)) | L23: =IF('Nelson, Keshia'!Q50<5,"Yes","") | M23: =IF(AND('Nelson, Keshia'!I49>0,'Nelson, Keshia'!I49<80),"Yes","") | N23: =IF(OR(F23>0,G23="Yes",H23="Yes",I23="Yes"),"⚠️ OVERWORK",IF(OR(J23="Yes",K23>0,L23="Yes",M23="Yes"),"🔻 UNDERWORK","✓ OK"))
A24: 20 | B24: Parris, Ceyon Nickosie | C24: 4885 | D24: ='Parris, Ceyon'!I49 | E24: ='Parris, Ceyon'!Q50 | F24: =SUMPRODUCT((('Parris, Ceyon'!I14+'Parris, Ceyon'!I15)>12)*1)+SUMPRODUCT((('Parris, Ceyon'!I16+'Parris, Ceyon'!I17)>12)*1)+SUMPRODUCT((('Parris, Ceyon'!I18+'Parris, Ceyon'!I19)>12)*1)+SUMPRODUCT((('Parris, Ceyon'!I20+'Parris, Ceyon'!I21)>12)*1)+SUMPRODUCT((('Parris, Ceyon'!I22+'Parris, Ceyon'!I23)>12)*1)+SUMPRODUCT((('Parris, Ceyon'!I24+'Parris, Ceyon'!I25)>12)*1)+SUMPRODUCT((('Parris, Ceyon'!I26+'Parris, Ceyon'!I27)>12)*1)+SUMPRODUCT((('Parris, Ceyon'!I30+'Parris, Ceyon'!I31)>12)*1)+SUMPRODUCT((('Parris, Ceyon'!I32+'Parris, Ceyon'!I33)>12)*1)+SUMPRODUCT((('Parris, Ceyon'!I34+'Parris, Ceyon'!I35)>12)*1)+SUMPRODUCT((('Parris, Ceyon'!I36+'Parris, Ceyon'!I37)>12)*1)+SUMPRODUCT((('Parris, Ceyon'!I38+'Parris, Ceyon'!I39)>12)*1)+SUMPRODUCT((('Parris, Ceyon'!I40+'Parris, Ceyon'!I41)>12)*1)+SUMPRODUCT((('Parris, Ceyon'!I42+'Parris, Ceyon'!I43)>12)*1)+SUMPRODUCT((('Parris, Ceyon'!I45+'Parris, Ceyon'!I46)>12)*1)+SUMPRODUCT((('Parris, Ceyon'!I47+'Parris, Ceyon'!I48)>12)*1) | G24: =IF(MAX(SUM('Parris, Ceyon'!I14:I27),SUM('Parris, Ceyon'!I30:I43))>60,"Yes","") | H24: =IF(OR(AND(('Parris, Ceyon'!I14+'Parris, Ceyon'!I15)>0,('Parris, Ceyon'!I16+'Parris, Ceyon'!I17)>0,('Parris, Ceyon'!I18+'Parris, Ceyon'!I19)>0,('Parris, Ceyon'!I20+'Parris, Ceyon'!I21)>0,('Parris, Ceyon'!I22+'Parris, Ceyon'!I23)>0,('Parris, Ceyon'!I24+'Parris, Ceyon'!I25)>0,('Parris, Ceyon'!I26+'Parris, Ceyon'!I27)>0),AND(('Parris, Ceyon'!I30+'Parris, Ceyon'!I31)>0,('Parris, Ceyon'!I32+'Parris, Ceyon'!I33)>0,('Parris, Ceyon'!I34+'Parris, Ceyon'!I35)>0,('Parris, Ceyon'!I36+'Parris, Ceyon'!I37)>0,('Parris, Ceyon'!I38+'Parris, Ceyon'!I39)>0,('Parris, Ceyon'!I40+'Parris, Ceyon'!I41)>0,('Parris, Ceyon'!I42+'Parris, Ceyon'!I43)>0)),"Yes","") | I24: =IF('Parris, Ceyon'!N49>40,"Yes","") | J24: =IF(OR(AND(SUM('Parris, Ceyon'!I14:I27)>0,SUM('Parris, Ceyon'!I14:I27)<40),AND(SUM('Parris, Ceyon'!I30:I43)>0,SUM('Parris, Ceyon'!I30:I43)<40)),"Yes","") | K24: =SUMPRODUCT(('Parris, Ceyon'!I14:I48>0)*('Parris, Ceyon'!I14:I48<8)) | L24: =IF('Parris, Ceyon'!Q50<5,"Yes","") | M24: =IF(AND('Parris, Ceyon'!I49>0,'Parris, Ceyon'!I49<80),"Yes","") | N24: =IF(OR(F24>0,G24="Yes",H24="Yes",I24="Yes"),"⚠️ OVERWORK",IF(OR(J24="Yes",K24>0,L24="Yes",M24="Yes"),"🔻 UNDERWORK","✓ OK"))
A25: 21 | B25: Phoenix, Ryan | C25: 2826 | D25: ='Phoenix, Ryan'!I49 | E25: ='Phoenix, Ryan'!Q50 | F25: =SUMPRODUCT((('Phoenix, Ryan'!I14+'Phoenix, Ryan'!I15)>12)*1)+SUMPRODUCT((('Phoenix, Ryan'!I16+'Phoenix, Ryan'!I17)>12)*1)+SUMPRODUCT((('Phoenix, Ryan'!I18+'Phoenix, Ryan'!I19)>12)*1)+SUMPRODUCT((('Phoenix, Ryan'!I20+'Phoenix, Ryan'!I21)>12)*1)+SUMPRODUCT((('Phoenix, Ryan'!I22+'Phoenix, Ryan'!I23)>12)*1)+SUMPRODUCT((('Phoenix, Ryan'!I24+'Phoenix, Ryan'!I25)>12)*1)+SUMPRODUCT((('Phoenix, Ryan'!I26+'Phoenix, Ryan'!I27)>12)*1)+SUMPRODUCT((('Phoenix, Ryan'!I30+'Phoenix, Ryan'!I31)>12)*1)+SUMPRODUCT((('Phoenix, Ryan'!I32+'Phoenix, Ryan'!I33)>12)*1)+SUMPRODUCT((('Phoenix, Ryan'!I34+'Phoenix, Ryan'!I35)>12)*1)+SUMPRODUCT((('Phoenix, Ryan'!I36+'Phoenix, Ryan'!I37)>12)*1)+SUMPRODUCT((('Phoenix, Ryan'!I38+'Phoenix, Ryan'!I39)>12)*1)+SUMPRODUCT((('Phoenix, Ryan'!I40+'Phoenix, Ryan'!I41)>12)*1)+SUMPRODUCT((('Phoenix, Ryan'!I42+'Phoenix, Ryan'!I43)>12)*1)+SUMPRODUCT((('Phoenix, Ryan'!I45+'Phoenix, Ryan'!I46)>12)*1)+SUMPRODUCT((('Phoenix, Ryan'!I47+'Phoenix, Ryan'!I48)>12)*1) | G25: =IF(MAX(SUM('Phoenix, Ryan'!I14:I27),SUM('Phoenix, Ryan'!I30:I43))>60,"Yes","") | H25: =IF(OR(AND(('Phoenix, Ryan'!I14+'Phoenix, Ryan'!I15)>0,('Phoenix, Ryan'!I16+'Phoenix, Ryan'!I17)>0,('Phoenix, Ryan'!I18+'Phoenix, Ryan'!I19)>0,('Phoenix, Ryan'!I20+'Phoenix, Ryan'!I21)>0,('Phoenix, Ryan'!I22+'Phoenix, Ryan'!I23)>0,('Phoenix, Ryan'!I24+'Phoenix, Ryan'!I25)>0,('Phoenix, Ryan'!I26+'Phoenix, Ryan'!I27)>0),AND(('Phoenix, Ryan'!I30+'Phoenix, Ryan'!I31)>0,('Phoenix, Ryan'!I32+'Phoenix, Ryan'!I33)>0,('Phoenix, Ryan'!I34+'Phoenix, Ryan'!I35)>0,('Phoenix, Ryan'!I36+'Phoenix, Ryan'!I37)>0,('Phoenix, Ryan'!I38+'Phoenix, Ryan'!I39)>0,('Phoenix, Ryan'!I40+'Phoenix, Ryan'!I41)>0,('Phoenix, Ryan'!I42+'Phoenix, Ryan'!I43)>0)),"Yes","") | I25: =IF('Phoenix, Ryan'!N49>40,"Yes","") | J25: =IF(OR(AND(SUM('Phoenix, Ryan'!I14:I27)>0,SUM('Phoenix, Ryan'!I14:I27)<40),AND(SUM('Phoenix, Ryan'!I30:I43)>0,SUM('Phoenix, Ryan'!I30:I43)<40)),"Yes","") | K25: =SUMPRODUCT(('Phoenix, Ryan'!I14:I48>0)*('Phoenix, Ryan'!I14:I48<8)) | L25: =IF('Phoenix, Ryan'!Q50<5,"Yes","") | M25: =IF(AND('Phoenix, Ryan'!I49>0,'Phoenix, Ryan'!I49<80),"Yes","") | N25: =IF(OR(F25>0,G25="Yes",H25="Yes",I25="Yes"),"⚠️ OVERWORK",IF(OR(J25="Yes",K25>0,L25="Yes",M25="Yes"),"🔻 UNDERWORK","✓ OK"))
A26: 22 | B26: Pollard, Lotoya Letitia | C26: 4850 | D26: ='Pollard, Lotoya'!I49 | E26: ='Pollard, Lotoya'!Q50 | F26: =SUMPRODUCT((('Pollard, Lotoya'!I14+'Pollard, Lotoya'!I15)>12)*1)+SUMPRODUCT((('Pollard, Lotoya'!I16+'Pollard, Lotoya'!I17)>12)*1)+SUMPRODUCT((('Pollard, Lotoya'!I18+'Pollard, Lotoya'!I19)>12)*1)+SUMPRODUCT((('Pollard, Lotoya'!I20+'Pollard, Lotoya'!I21)>12)*1)+SUMPRODUCT((('Pollard, Lotoya'!I22+'Pollard, Lotoya'!I23)>12)*1)+SUMPRODUCT((('Pollard, Lotoya'!I24+'Pollard, Lotoya'!I25)>12)*1)+SUMPRODUCT((('Pollard, Lotoya'!I26+'Pollard, Lotoya'!I27)>12)*1)+SUMPRODUCT((('Pollard, Lotoya'!I30+'Pollard, Lotoya'!I31)>12)*1)+SUMPRODUCT((('Pollard, Lotoya'!I32+'Pollard, Lotoya'!I33)>12)*1)+SUMPRODUCT((('Pollard, Lotoya'!I34+'Pollard, Lotoya'!I35)>12)*1)+SUMPRODUCT((('Pollard, Lotoya'!I36+'Pollard, Lotoya'!I37)>12)*1)+SUMPRODUCT((('Pollard, Lotoya'!I38+'Pollard, Lotoya'!I39)>12)*1)+SUMPRODUCT((('Pollard, Lotoya'!I40+'Pollard, Lotoya'!I41)>12)*1)+SUMPRODUCT((('Pollard, Lotoya'!I42+'Pollard, Lotoya'!I43)>12)*1)+SUMPRODUCT((('Pollard, Lotoya'!I45+'Pollard, Lotoya'!I46)>12)*1)+SUMPRODUCT((('Pollard, Lotoya'!I47+'Pollard, Lotoya'!I48)>12)*1) | G26: =IF(MAX(SUM('Pollard, Lotoya'!I14:I27),SUM('Pollard, Lotoya'!I30:I43))>60,"Yes","") | H26: =IF(OR(AND(('Pollard, Lotoya'!I14+'Pollard, Lotoya'!I15)>0,('Pollard, Lotoya'!I16+'Pollard, Lotoya'!I17)>0,('Pollard, Lotoya'!I18+'Pollard, Lotoya'!I19)>0,('Pollard, Lotoya'!I20+'Pollard, Lotoya'!I21)>0,('Pollard, Lotoya'!I22+'Pollard, Lotoya'!I23)>0,('Pollard, Lotoya'!I24+'Pollard, Lotoya'!I25)>0,('Pollard, Lotoya'!I26+'Pollard, Lotoya'!I27)>0),AND(('Pollard, Lotoya'!I30+'Pollard, Lotoya'!I31)>0,('Pollard, Lotoya'!I32+'Pollard, Lotoya'!I33)>0,('Pollard, Lotoya'!I34+'Pollard, Lotoya'!I35)>0,('Pollard, Lotoya'!I36+'Pollard, Lotoya'!I37)>0,('Pollard, Lotoya'!I38+'Pollard, Lotoya'!I39)>0,('Pollard, Lotoya'!I40+'Pollard, Lotoya'!I41)>0,('Pollard, Lotoya'!I42+'Pollard, Lotoya'!I43)>0)),"Yes","") | I26: =IF('Pollard, Lotoya'!N49>40,"Yes","") | J26: =IF(OR(AND(SUM('Pollard, Lotoya'!I14:I27)>0,SUM('Pollard, Lotoya'!I14:I27)<40),AND(SUM('Pollard, Lotoya'!I30:I43)>0,SUM('Pollard, Lotoya'!I30:I43)<40)),"Yes","") | K26: =SUMPRODUCT(('Pollard, Lotoya'!I14:I48>0)*('Pollard, Lotoya'!I14:I48<8)) | L26: =IF('Pollard, Lotoya'!Q50<5,"Yes","") | M26: =IF(AND('Pollard, Lotoya'!I49>0,'Pollard, Lotoya'!I49<80),"Yes","") | N26: =IF(OR(F26>0,G26="Yes",H26="Yes",I26="Yes"),"⚠️ OVERWORK",IF(OR(J26="Yes",K26>0,L26="Yes",M26="Yes"),"🔻 UNDERWORK","✓ OK"))
A27: 23 | B27: Reynolds, Kevin Timothy | C27: 4658 | D27: ='Reynolds, Kevin'!I49 | E27: ='Reynolds, Kevin'!Q50 | F27: =SUMPRODUCT((('Reynolds, Kevin'!I14+'Reynolds, Kevin'!I15)>12)*1)+SUMPRODUCT((('Reynolds, Kevin'!I16+'Reynolds, Kevin'!I17)>12)*1)+SUMPRODUCT((('Reynolds, Kevin'!I18+'Reynolds, Kevin'!I19)>12)*1)+SUMPRODUCT((('Reynolds, Kevin'!I20+'Reynolds, Kevin'!I21)>12)*1)+SUMPRODUCT((('Reynolds, Kevin'!I22+'Reynolds, Kevin'!I23)>12)*1)+SUMPRODUCT((('Reynolds, Kevin'!I24+'Reynolds, Kevin'!I25)>12)*1)+SUMPRODUCT((('Reynolds, Kevin'!I26+'Reynolds, Kevin'!I27)>12)*1)+SUMPRODUCT((('Reynolds, Kevin'!I30+'Reynolds, Kevin'!I31)>12)*1)+SUMPRODUCT((('Reynolds, Kevin'!I32+'Reynolds, Kevin'!I33)>12)*1)+SUMPRODUCT((('Reynolds, Kevin'!I34+'Reynolds, Kevin'!I35)>12)*1)+SUMPRODUCT((('Reynolds, Kevin'!I36+'Reynolds, Kevin'!I37)>12)*1)+SUMPRODUCT((('Reynolds, Kevin'!I38+'Reynolds, Kevin'!I39)>12)*1)+SUMPRODUCT((('Reynolds, Kevin'!I40+'Reynolds, Kevin'!I41)>12)*1)+SUMPRODUCT((('Reynolds, Kevin'!I42+'Reynolds, Kevin'!I43)>12)*1)+SUMPRODUCT((('Reynolds, Kevin'!I45+'Reynolds, Kevin'!I46)>12)*1)+SUMPRODUCT((('Reynolds, Kevin'!I47+'Reynolds, Kevin'!I48)>12)*1) | G27: =IF(MAX(SUM('Reynolds, Kevin'!I14:I27),SUM('Reynolds, Kevin'!I30:I43))>60,"Yes","") | H27: =IF(OR(AND(('Reynolds, Kevin'!I14+'Reynolds, Kevin'!I15)>0,('Reynolds, Kevin'!I16+'Reynolds, Kevin'!I17)>0,('Reynolds, Kevin'!I18+'Reynolds, Kevin'!I19)>0,('Reynolds, Kevin'!I20+'Reynolds, Kevin'!I21)>0,('Reynolds, Kevin'!I22+'Reynolds, Kevin'!I23)>0,('Reynolds, Kevin'!I24+'Reynolds, Kevin'!I25)>0,('Reynolds, Kevin'!I26+'Reynolds, Kevin'!I27)>0),AND(('Reynolds, Kevin'!I30+'Reynolds, Kevin'!I31)>0,('Reynolds, Kevin'!I32+'Reynolds, Kevin'!I33)>0,('Reynolds, Kevin'!I34+'Reynolds, Kevin'!I35)>0,('Reynolds, Kevin'!I36+'Reynolds, Kevin'!I37)>0,('Reynolds, Kevin'!I38+'Reynolds, Kevin'!I39)>0,('Reynolds, Kevin'!I40+'Reynolds, Kevin'!I41)>0,('Reynolds, Kevin'!I42+'Reynolds, Kevin'!I43)>0)),"Yes","") | I27: =IF('Reynolds, Kevin'!N49>40,"Yes","") | J27: =IF(OR(AND(SUM('Reynolds, Kevin'!I14:I27)>0,SUM('Reynolds, Kevin'!I14:I27)<40),AND(SUM('Reynolds, Kevin'!I30:I43)>0,SUM('Reynolds, Kevin'!I30:I43)<40)),"Yes","") | K27: =SUMPRODUCT(('Reynolds, Kevin'!I14:I48>0)*('Reynolds, Kevin'!I14:I48<8)) | L27: =IF('Reynolds, Kevin'!Q50<5,"Yes","") | M27: =IF(AND('Reynolds, Kevin'!I49>0,'Reynolds, Kevin'!I49<80),"Yes","") | N27: =IF(OR(F27>0,G27="Yes",H27="Yes",I27="Yes"),"⚠️ OVERWORK",IF(OR(J27="Yes",K27>0,L27="Yes",M27="Yes"),"🔻 UNDERWORK","✓ OK"))
A28: 24 | B28: Roberts, Odetta Kenesia Shannele | C28: 5466 | D28: ='Roberts, Odetta'!I49 | E28: ='Roberts, Odetta'!Q50 | F28: =SUMPRODUCT((('Roberts, Odetta'!I14+'Roberts, Odetta'!I15)>12)*1)+SUMPRODUCT((('Roberts, Odetta'!I16+'Roberts, Odetta'!I17)>12)*1)+SUMPRODUCT((('Roberts, Odetta'!I18+'Roberts, Odetta'!I19)>12)*1)+SUMPRODUCT((('Roberts, Odetta'!I20+'Roberts, Odetta'!I21)>12)*1)+SUMPRODUCT((('Roberts, Odetta'!I22+'Roberts, Odetta'!I23)>12)*1)+SUMPRODUCT((('Roberts, Odetta'!I24+'Roberts, Odetta'!I25)>12)*1)+SUMPRODUCT((('Roberts, Odetta'!I26+'Roberts, Odetta'!I27)>12)*1)+SUMPRODUCT((('Roberts, Odetta'!I30+'Roberts, Odetta'!I31)>12)*1)+SUMPRODUCT((('Roberts, Odetta'!I32+'Roberts, Odetta'!I33)>12)*1)+SUMPRODUCT((('Roberts, Odetta'!I34+'Roberts, Odetta'!I35)>12)*1)+SUMPRODUCT((('Roberts, Odetta'!I36+'Roberts, Odetta'!I37)>12)*1)+SUMPRODUCT((('Roberts, Odetta'!I38+'Roberts, Odetta'!I39)>12)*1)+SUMPRODUCT((('Roberts, Odetta'!I40+'Roberts, Odetta'!I41)>12)*1)+SUMPRODUCT((('Roberts, Odetta'!I42+'Roberts, Odetta'!I43)>12)*1)+SUMPRODUCT((('Roberts, Odetta'!I45+'Roberts, Odetta'!I46)>12)*1)+SUMPRODUCT((('Roberts, Odetta'!I47+'Roberts, Odetta'!I48)>12)*1) | G28: =IF(MAX(SUM('Roberts, Odetta'!I14:I27),SUM('Roberts, Odetta'!I30:I43))>60,"Yes","") | H28: =IF(OR(AND(('Roberts, Odetta'!I14+'Roberts, Odetta'!I15)>0,('Roberts, Odetta'!I16+'Roberts, Odetta'!I17)>0,('Roberts, Odetta'!I18+'Roberts, Odetta'!I19)>0,('Roberts, Odetta'!I20+'Roberts, Odetta'!I21)>0,('Roberts, Odetta'!I22+'Roberts, Odetta'!I23)>0,('Roberts, Odetta'!I24+'Roberts, Odetta'!I25)>0,('Roberts, Odetta'!I26+'Roberts, Odetta'!I27)>0),AND(('Roberts, Odetta'!I30+'Roberts, Odetta'!I31)>0,('Roberts, Odetta'!I32+'Roberts, Odetta'!I33)>0,('Roberts, Odetta'!I34+'Roberts, Odetta'!I35)>0,('Roberts, Odetta'!I36+'Roberts, Odetta'!I37)>0,('Roberts, Odetta'!I38+'Roberts, Odetta'!I39)>0,('Roberts, Odetta'!I40+'Roberts, Odetta'!I41)>0,('Roberts, Odetta'!I42+'Roberts, Odetta'!I43)>0)),"Yes","") | I28: =IF('Roberts, Odetta'!N49>40,"Yes","") | J28: =IF(OR(AND(SUM('Roberts, Odetta'!I14:I27)>0,SUM('Roberts, Odetta'!I14:I27)<40),AND(SUM('Roberts, Odetta'!I30:I43)>0,SUM('Roberts, Odetta'!I30:I43)<40)),"Yes","") | K28: =SUMPRODUCT(('Roberts, Odetta'!I14:I48>0)*('Roberts, Odetta'!I14:I48<8)) | L28: =IF('Roberts, Odetta'!Q50<5,"Yes","") | M28: =IF(AND('Roberts, Odetta'!I49>0,'Roberts, Odetta'!I49<80),"Yes","") | N28: =IF(OR(F28>0,G28="Yes",H28="Yes",I28="Yes"),"⚠️ OVERWORK",IF(OR(J28="Yes",K28>0,L28="Yes",M28="Yes"),"🔻 UNDERWORK","✓ OK"))
