Workbook
Name valuevx: 42.314159

Sheet Work Hours Summary
A1: 📊 WORK HOURS SUMMARY
A2: Pay Period: 1-15/16 Jan 2026 | Total Employees: 104
A4: # | B4: Employee Name | C4: Emp # | D4: Total Hrs | E4: Days Wkd | F4: Daily >12 | G4: Wkly >60 | H4: 7+ Days | I4: OT >40 | J4: Wkly <40 | K4: Daily <8 | L4: Days <5 | M4: Period <80 | N4: STATUS
A5: 1 | B5: Agard, Desiree Ann | C5: 810 | D5: ='Agard, Desiree Ann'!I49 | E5: ='Agard, Desiree Ann'!Q50 | F5: =SUMPRODUCT((('Agard, Desiree Ann'!I14+'Agard, Desiree Ann'!I15)>12)*1)+SUMPRODUCT((('Agard, Desiree Ann'!I16+'Agard, Desiree Ann'!I17)>12)*1)+SUMPRODUCT((('Agard, Desiree Ann'!I18+'Agard, Desiree Ann'!I19)>12)*1)+SUMPRODUCT((('Agard, Desiree Ann'!I20+'Agard, Desiree Ann'!I21)>12)*1)+SUMPRODUCT((('Agard, Desiree Ann'!I22+'Agard, Desiree Ann'!I23)>12)*1)+SUMPRODUCT((('Agard, Desiree Ann'!I24+'Agard, Desiree Ann'!I25)>12)*1)+SUMPRODUCT((('Agard, Desiree Ann'!I26+'Agard, Desiree Ann'!I27)>12)*1)+SUMPRODUCT((('Agard, Desiree Ann'!I30+'Agard, Desiree Ann'!I31)>12)*1)+SUMPRODUCT((('Agard, Desiree Ann'!I32+'Agard, Desiree Ann'!I33)>12)*1)+SUMPRODUCT((('Agard, Desiree Ann'!I34+'Agard, Desiree Ann'!I35)>12)*1)+SUMPRODUCT((('Agard, Desiree Ann'!I36+'Agard, Desiree Ann'!I37)>12)*1)+SUMPRODUCT((('Agard, Desiree Ann'!I38+'Agard, Desiree Ann'!I39)>12)*1)+SUMPRODUCT((('Agard, Desiree Ann'!I40+'Agard, Desiree Ann'!I41)>12)*1)+SUMPRODUCT((('Agard, Desiree Ann'!I42+'Agard, Desiree Ann'!I43)>12)*1)+SUMPRODUCT((('Agard, Desiree Ann'!I45+'Agard, Desiree Ann'!I46)>12)*1)+SUMPRODUCT((('Agard, Desiree Ann'!I47+'Agard, Desiree Ann'!I48)>12)*1) | G5: =IF(MAX(SUM('Agard, Desiree Ann'!I14:I27),SUM('Agard, Desiree Ann'!I30:I43))>60,"Yes","") | H5: =IF(OR(AND(('Agard, Desiree Ann'!I14+'Agard, Desiree Ann'!I15)>0,('Agard, Desiree Ann'!I16+'Agard, Desiree Ann'!I17)>0,('Agard, Desiree Ann'!I18+'Agard, Desiree Ann'!I19)>0,('Agard, Desiree Ann'!I20+'Agard, Desiree Ann'!I21)>0,('Agard, Desiree Ann'!I22+'Agard, Desiree Ann'!I23)>0,('Agard, Desiree Ann'!I24+'Agard, Desiree Ann'!I25)>0,('Agard, Desiree Ann'!I26+'Agard, Desiree Ann'!I27)>0),AND(('Agard, Desiree Ann'!I30+'Agard, Desiree Ann'!I31)>0,('Agard, Desiree Ann'!I32+'Agard, Desiree Ann'!I33)>0,('Agard, Desiree Ann'!I34+'Agard, Desiree Ann'!I35)>0,('Agard, Desiree Ann'!I36+'Agard, Desiree Ann'!I37)>0,('Agard, Desiree Ann'!I38+'Agard, Desiree Ann'!I39)>0,('Agard, Desiree Ann'!I40+'Agard, Desiree Ann'!I41)>0,('Agard, Desiree Ann'!I42+'Agard, Desiree Ann'!I43)>0)),"Yes","") | I5: =IF('Agard, Desiree Ann'!N49>40,"Yes","") | J5: =IF(OR(AND(SUM('Agard, Desiree Ann'!I14:I27)>0,SUM('Agard, Desiree Ann'!I14:I27)<40),AND(SUM('Agard, Desiree Ann'!I30:I43)>0,SUM('Agard, Desiree Ann'!I30:I43)<40)),"Yes","") | K5: =SUMPRODUCT(('Agard, Desiree Ann'!I14:I48>0)*('Agard, Desiree Ann'!I14:I48<8)) | L5: =IF('Agard, Desiree Ann'!Q50<5,"Yes","") | M5: =IF(AND('Agard, Desiree Ann'!I49>0,'Agard, Desiree Ann'!I49<80),"Yes","") | N5: =IF(OR(F5>0,G5="Yes",H5="Yes",I5="Yes"),"⚠️ OVERWORK",IF(OR(J5="Yes",K5>0,L5="Yes",M5="Yes"),"🔻 UNDERWORK","✓ OK"))
A6: 2 | B6: Alphonso, Tanika Amira | C6: 4699 | D6: ='Alphonso, Tanika Amira'!I49 | E6: ='Alphonso, Tanika Amira'!Q50 | F6: =SUMPRODUCT((('Alphonso, Tanika Amira'!I14+'Alphonso, Tanika Amira'!I15)>12)*1)+SUMPRODUCT((('Alphonso, Tanika Amira'!I16+'Alphonso, Tanika Amira'!I17)>12)*1)+SUMPRODUCT((('Alphonso, Tanika Amira'!I18+'Alphonso, Tanika Amira'!I19)>12)*1)+SUMPRODUCT((('Alphonso, Tanika Amira'!I20+'Alphonso, Tanika Amira'!I21)>12)*1)+SUMPRODUCT((('Alphonso, Tanika Amira'!I22+'Alphonso, Tanika Amira'!I23)>12)*1)+SUMPRODUCT((('Alphonso, Tanika Amira'!I24+'Alphonso, Tanika Amira'!I25)>12)*1)+SUMPRODUCT((('Alphonso, Tanika Amira'!I26+'Alphonso, Tanika Amira'!I27)>12)*1)+SUMPRODUCT((('Alphonso, Tanika Amira'!I30+'Alphonso, Tanika Amira'!I31)>12)*1)+SUMPRODUCT((('Alphonso, Tanika Amira'!I32+'Alphonso, Tanika Amira'!I33)>12)*1)+SUMPRODUCT((('Alphonso, Tanika Amira'!I34+'Alphonso, Tanika Amira'!I35)>12)*1)+SUMPRODUCT((('Alphonso, Tanika Amira'!I36+'Alphonso, Tanika Amira'!I37)>12)*1)+SUMPRODUCT((('Alphonso, Tanika Amira'!I38+'Alphonso, Tanika Amira'!I39)>12)*1)+SUMPRODUCT((('Alphonso, Tanika Amira'!I40+'Alphonso, Tanika Amira'!I41)>12)*1)+SUMPRODUCT((('Alphonso, Tanika Amira'!I42+'Alphonso, Tanika Amira'!I43)>12)*1)+SUMPRODUCT((('Alphonso, Tanika Amira'!I45+'Alphonso, Tanika Amira'!I46)>12)*1)+SUMPRODUCT((('Alphonso, Tanika Amira'!I47+'Alphonso, Tanika Amira'!I48)>12)*1) | G6: =IF(MAX(SUM('Alphonso, Tanika Amira'!I14:I27),SUM('Alphonso, Tanika Amira'!I30:I43))>60,"Yes","") | H6: =IF(OR(AND(('Alphonso, Tanika Amira'!I14+'Alphonso, Tanika Amira'!I15)>0,('Alphonso, Tanika Amira'!I16+'Alphonso, Tanika Amira'!I17)>0,('Alphonso, Tanika Amira'!I18+'Alphonso, Tanika Amira'!I19)>0,('Alphonso, Tanika Amira'!I20+'Alphonso, Tanika Amira'!I21)>0,('Alphonso, Tanika Amira'!I22+'Alphonso, Tanika Amira'!I23)>0,('Alphonso, Tanika Amira'!I24+'Alphonso, Tanika Amira'!I25)>0,('Alphonso, Tanika Amira'!I26+'Alphonso, Tanika Amira'!I27)>0),AND(('Alphonso, Tanika Amira'!I30+'Alphonso, Tanika Amira'!I31)>0,('Alphonso, Tanika Amira'!I32+'Alphonso, Tanika Amira'!I33)>0,('Alphonso, Tanika Amira'!I34+'Alphonso, Tanika Amira'!I35)>0,('Alphonso, Tanika Amira'!I36+'Alphonso, Tanika Amira'!I37)>0,('Alphonso, Tanika Amira'!I38+'Alphonso, Tanika Amira'!I39)>0,('Alphonso, Tanika Amira'!I40+'Alphonso, Tanika Amira'!I41)>0,('Alphonso, Tanika Amira'!I42+'Alphonso, Tanika Amira'!I43)>0)),"Yes","") | I6: =IF('Alphonso, Tanika Amira'!N49>40,"Yes","") | J6: =IF(OR(AND(SUM('Alphonso, Tanika Amira'!I14:I27)>0,SUM('Alphonso, Tanika Amira'!I14:I27)<40),AND(SUM('Alphonso, Tanika Amira'!I30:I43)>0,SUM('Alphonso, Tanika Amira'!I30:I43)<40)),"Yes","") | K6: =SUMPRODUCT(('Alphonso, Tanika Amira'!I14:I48>0)*('Alphonso, Tanika Amira'!I14:I48<8)) | L6: =IF('Alphonso, Tanika Amira'!Q50<5,"Yes","") | M6: =IF(AND('Alphonso, Tanika Amira'!I49>0,'Alphonso, Tanika Amira'!I49<80),"Yes","") | N6: =IF(OR(F6>0,G6="Yes",H6="Yes",I6="Yes"),"⚠️ OVERWORK",IF(OR(J6="Yes",K6>0,L6="Yes",M6="Yes"),"🔻 UNDERWORK","✓ OK"))
A7: 3 | B7: Alstrom, Melanie Yolandia | C7: 1922 | D7: ='Alstrom, Melanie Yolandia'!I49 | E7: ='Alstrom, Melanie Yolandia'!Q50 | F7: =SUMPRODUCT((('Alstrom, Melanie Yolandia'!I14+'Alstrom, Melanie Yolandia'!I15)>12)*1)+SUMPRODUCT((('Alstrom, Melanie Yolandia'!I16+'Alstrom, Melanie Yolandia'!I17)>12)*1)+SUMPRODUCT((('Alstrom, Melanie Yolandia'!I18+'Alstrom, Melanie Yolandia'!I19)>12)*1)+SUMPRODUCT((('Alstrom, Melanie Yolandia'!I20+'Alstrom, Melanie Yolandia'!I21)>12)*1)+SUMPRODUCT((('Alstrom, Melanie Yolandia'!I22+'Alstrom, Melanie Yolandia'!I23)>12)*1)+SUMPRODUCT((('Alstrom, Melanie Yolandia'!I24+'Alstrom, Melanie Yolandia'!I25)>12)*1)+SUMPRODUCT((('Alstrom, Melanie Yolandia'!I26+'Alstrom, Melanie Yolandia'!I27)>12)*1)+SUMPRODUCT((('Alstrom, Melanie Yolandia'!I30+'Alstrom, Melanie Yolandia'!I31)>12)*1)+SUMPRODUCT((('Alstrom, Melanie Yolandia'!I32+'Alstrom, Melanie Yolandia'!I33)>12)*1)+SUMPRODUCT((('Alstrom, Melanie Yolandia'!I34+'Alstrom, Melanie Yolandia'!I35)>12)*1)+SUMPRODUCT((('Alstrom, Melanie Yolandia'!I36+'Alstrom, Melanie Yolandia'!I37)>12)*1)+SUMPRODUCT((('Alstrom, Melanie Yolandia'!I38+'Alstrom, Melanie Yolandia'!I39)>12)*1)+SUMPRODUCT((('Alstrom, Melanie Yolandia'!I40+'Alstrom, Melanie Yolandia'!I41)>12)*1)+SUMPRODUCT((('Alstrom, Melanie Yolandia'!I42+'Alstrom, Melanie Yolandia'!I43)>12)*1)+SUMPRODUCT((('Alstrom, Melanie Yolandia'!I45+'Alstrom, Melanie Yolandia'!I46)>12)*1)+SUMPRODUCT((('Alstrom, Melanie Yolandia'!I47+'Alstrom, Melanie Yolandia'!I48)>12)*1) | G7: =IF(MAX(SUM('Alstrom, Melanie Yolandia'!I14:I27),SUM('Alstrom, Melanie Yolandia'!I30:I43))>60,"Yes","") | H7: =IF(OR(AND(('Alstrom, Melanie Yolandia'!I14+'Alstrom, Melanie Yolandia'!I15)>0,('Alstrom, Melanie Yolandia'!I16+'Alstrom, Melanie Yolandia'!I17)>0,('Alstrom, Melanie Yolandia'!I18+'Alstrom, Melanie Yolandia'!I19)>0,('Alstrom, Melanie Yolandia'!I20+'Alstrom, Melanie Yolandia'!I21)>0,('Alstrom, Melanie Yolandia'!I22+'Alstrom, Melanie Yolandia'!I23)>0,('Alstrom, Melanie Yolandia'!I24+'Alstrom, Melanie Yolandia'!I25)>0,('Alstrom, Melanie Yolandia'!I26+'Alstrom, Melanie Yolandia'!I27)>0),AND(('Alstrom, Melanie Yolandia'!I30+'Alstrom, Melanie Yolandia'!I31)>0,('Alstrom, Melanie Yolandia'!I32+'Alstrom, Melanie Yolandia'!I33)>0,('Alstrom, Melanie Yolandia'!I34+'Alstrom, Melanie Yolandia'!I35)>0,('Alstrom, Melanie Yolandia'!I36+'Alstrom, Melanie Yolandia'!I37)>0,('Alstrom, Melanie Yolandia'!I38+'Alstrom, Melanie Yolandia'!I39)>0,('Alstrom, Melanie Yolandia'!I40+'Alstrom, Melanie Yolandia'!I41)>0,('Alstrom, Melanie Yolandia'!I42+'Alstrom, Melanie Yolandia'!I43)>0)),"Yes","") | I7: =IF('Alstrom, Melanie Yolandia'!N49>40,"Yes","") | J7: =IF(OR(AND(SUM('Alstrom, Melanie Yolandia'!I14:I27)>0,SUM('Alstrom, Melanie Yolandia'!I14:I27)<40),AND(SUM('Alstrom, Melanie Yolandia'!I30:I43)>0,SUM('Alstrom, Melanie Yolandia'!I30:I43)<40)),"Yes","") | K7: =SUMPRODUCT(('Alstrom, Melanie Yolandia'!I14:I48>0)*('Alstrom, Melanie Yolandia'!I14:I48<8)) | L7: =IF('Alstrom, Melanie Yolandia'!Q50<5,"Yes","") | M7: =IF(AND('Alstrom, Melanie Yolandia'!I49>0,'Alstrom, Melanie Yolandia'!I49<80),"Yes","") | N7: =IF(OR(F7>0,G7="Yes",H7="Yes",I7="Yes"),"⚠️ OVERWORK",IF(OR(J7="Yes",K7>0,L7="Yes",M7="Yes"),"🔻 UNDERWORK","✓ OK"))
A8: 4 | B8: Alves, Andrew Alwyn | C8: 5490 | D8: ='Alves, Andrew Alwyn'!I49 | E8: ='Alves, Andrew Alwyn'!Q50 | F8: =SUMPRODUCT((('Alves, Andrew Alwyn'!I14+'Alves, Andrew Alwyn'!I15)>12)*1)+SUMPRODUCT((('Alves, Andrew Alwyn'!I16+'Alves, Andrew Alwyn'!I17)>12)*1)+SUMPRODUCT((('Alves, Andrew Alwyn'!I18+'Alves, Andrew Alwyn'!I19)>12)*1)+SUMPRODUCT((('Alves, Andrew Alwyn'!I20+'Alves, Andrew Alwyn'!I21)>12)*1)+SUMPRODUCT((('Alves, Andrew Alwyn'!I22+'Alves, Andrew Alwyn'!I23)>12)*1)+SUMPRODUCT((('Alves, Andrew Alwyn'!I24+'Alves, Andrew Alwyn'!I25)>12)*1)+SUMPRODUCT((('Alves, Andrew Alwyn'!I26+'Alves, Andrew Alwyn'!I27)>12)*1)+SUMPRODUCT((('Alves, Andrew Alwyn'!I30+'Alves, Andrew Alwyn'!I31)>12)*1)+SUMPRODUCT((('Alves, Andrew Alwyn'!I32+'Alves, Andrew Alwyn'!I33)>12)*1)+SUMPRODUCT((('Alves, Andrew Alwyn'!I34+'Alves, Andrew Alwyn'!I35)>12)*1)+SUMPRODUCT((('Alves, Andrew Alwyn'!I36+'Alves, Andrew Alwyn'!I37)>12)*1)+SUMPRODUCT((('Alves, Andrew Alwyn'!I38+'Alves, Andrew Alwyn'!I39)>12)*1)+SUMPRODUCT((('Alves, Andrew Alwyn'!I40+'Alves, Andrew Alwyn'!I41)>12)*1)+SUMPRODUCT((('Alves, Andrew Alwyn'!I42+'Alves, Andrew Alwyn'!I43)>12)*1)+SUMPRODUCT((('Alves, Andrew Alwyn'!I45+'Alves, Andrew Alwyn'!I46)>12)*1)+SUMPRODUCT((('Alves, Andrew Alwyn'!I47+'Alves, Andrew Alwyn'!I48)>12)*1) | G8: =IF(MAX(SUM('Alves, Andrew Alwyn'!I14:I27),SUM('Alves, Andrew Alwyn'!I30:I43))>60,"Yes","") | H8: =IF(OR(AND(('Alves, Andrew Alwyn'!I14+'Alves, Andrew Alwyn'!I15)>0,('Alves, Andrew Alwyn'!I16+'Alves, Andrew Alwyn'!I17)>0,('Alves, Andrew Alwyn'!I18+'Alves, Andrew Alwyn'!I19)>0,('Alves, Andrew Alwyn'!I20+'Alves, Andrew Alwyn'!I21)>0,('Alves, Andrew Alwyn'!I22+'Alves, Andrew Alwyn'!I23)>0,('Alves, Andrew Alwyn'!I24+'Alves, Andrew Alwyn'!I25)>0,('Alves, Andrew Alwyn'!I26+'Alves, Andrew Alwyn'!I27)>0),AND(('Alves, Andrew Alwyn'!I30+'Alves, Andrew Alwyn'!I31)>0,('Alves, Andrew Alwyn'!I32+'Alves, Andrew Alwyn'!I33)>0,('Alves, Andrew Alwyn'!I34+'Alves, Andrew Alwyn'!I35)>0,('Alves, Andrew Alwyn'!I36+'Alves, Andrew Alwyn'!I37)>0,('Alves, Andrew Alwyn'!I38+'Alves, Andrew Alwyn'!I39)>0,('Alves, Andrew Alwyn'!I40+'Alves, Andrew Alwyn'!I41)>0,('Alves, Andrew Alwyn'!I42+'Alves, Andrew Alwyn'!I43)>0)),"Yes","") | I8: =IF('Alves, Andrew Alwyn'!N49>40,"Yes","") | J8: =IF(OR(AND(SUM('Alves, Andrew Alwyn'!I14:I27)>0,SUM('Alves, Andrew Alwyn'!I14:I27)<40),AND(SUM('Alves, Andrew Alwyn'!I30:I43)>0,SUM('Alves, Andrew Alwyn'!I30:I43)<40)),"Yes","") | K8: =SUMPRODUCT(('Alves, Andrew Alwyn'!I14:I48>0)*('Alves, Andrew Alwyn'!I14:I48<8)) | L8: =IF('Alves, Andrew Alwyn'!Q50<5,"Yes","") | M8: =IF(AND('Alves, Andrew Alwyn'!I49>0,'Alves, Andrew Alwyn'!I49<80),"Yes","") | N8: =IF(OR(F8>0,G8="Yes",H8="Yes",I8="Yes"),"⚠️ OVERWORK",IF(OR(J8="Yes",K8>0,L8="Yes",M8="Yes"),"🔻 UNDERWORK","✓ OK"))
A9: 5 | B9: Auguste, Nadege | C9: 5477 | D9: ='Auguste, Nadege'!I49 | E9: ='Auguste, Nadege'!Q50 | F9: =SUMPRODUCT((('Auguste, Nadege'!I14+'Auguste, Nadege'!I15)>12)*1)+SUMPRODUCT((('Auguste, Nadege'!I16+'Auguste, Nadege'!I17)>12)*1)+SUMPRODUCT((('Auguste, Nadege'!I18+'Auguste, Nadege'!I19)>12)*1)+SUMPRODUCT((('Auguste, Nadege'!I20+'Auguste, Nadege'!I21)>12)*1)+SUMPRODUCT((('Auguste, Nadege'!I22+'Auguste, Nadege'!I23)>12)*1)+SUMPRODUCT((('Auguste, Nadege'!I24+'Auguste, Nadege'!I25)>12)*1)+SUMPRODUCT((('Auguste, Nadege'!I26+'Auguste, Nadege'!I27)>12)*1)+SUMPRODUCT((('Auguste, Nadege'!I30+'Auguste, Nadege'!I31)>12)*1)+SUMPRODUCT((('Auguste, Nadege'!I32+'Auguste, Nadege'!I33)>12)*1)+SUMPRODUCT((('Auguste, Nadege'!I34+'Auguste, Nadege'!I35)>12)*1)+SUMPRODUCT((('Auguste, Nadege'!I36+'Auguste, Nadege'!I37)>12)*1)+SUMPRODUCT((('Auguste, Nadege'!I38+'Auguste, Nadege'!I39)>12)*1)+SUMPRODUCT((('Auguste, Nadege'!I40+'Auguste, Nadege'!I41)>12)*1)+SUMPRODUCT((('Auguste, Nadege'!I42+'Auguste, Nadege'!I43)>12)*1)+SUMPRODUCT((('Auguste, Nadege'!I45+'Auguste, Nadege'!I46)>12)*1)+SUMPRODUCT((('Auguste, Nadege'!I47+'Auguste, Nadege'!I48)>12)*1) | G9: =IF(MAX(SUM('Auguste, Nadege'!I14:I27),SUM('Auguste, Nadege'!I30:I43))>60,"Yes","") | H9: =IF(OR(AND(('Auguste, Nadege'!I14+'Auguste, Nadege'!I15)>0,('Auguste, Nadege'!I16+'Auguste, Nadege'!I17)>0,('Auguste, Nadege'!I18+'Auguste, Nadege'!I19)>0,('Auguste, Nadege'!I20+'Auguste, Nadege'!I21)>0,('Auguste, Nadege'!I22+'Auguste, Nadege'!I23)>0,('Auguste, Nadege'!I24+'Auguste, Nadege'!I25)>0,('Auguste, Nadege'!I26+'Auguste, Nadege'!I27)>0),AND(('Auguste, Nadege'!I30+'Auguste, Nadege'!I31)>0,('Auguste, Nadege'!I32+'Auguste, Nadege'!I33)>0,('Auguste, Nadege'!I34+'Auguste, Nadege'!I35)>0,('Auguste, Nadege'!I36+'Auguste, Nadege'!I37)>0,('Auguste, Nadege'!I38+'Auguste, Nadege'!I39)>0,('Auguste, Nadege'!I40+'Auguste, Nadege'!I41)>0,('Auguste, Nadege'!I42+'Auguste, Nadege'!I43)>0)),"Yes","") | I9: =IF('Auguste, Nadege'!N49>40,"Yes","") | J9: =IF(OR(AND(SUM('Auguste, Nadege'!I14:I27)>0,SUM('Auguste, Nadege'!I14:I27)<40),AND(SUM('Auguste, Nadege'!I30:I43)>0,SUM('Auguste, Nadege'!I30:I43)<40)),"Yes","") | K9: =SUMPRODUCT(('Auguste, Nadege'!I14:I48>0)*('Auguste, Nadege'!I14:I48<8)) | L9: =IF('Auguste, Nadege'!Q50<5,"Yes","") | M9: =IF(AND('Auguste, Nadege'!I49>0,'Auguste, Nadege'!I49<80),"Yes","") | N9: =IF(OR(F9>0,G9="Yes",H9="Yes",I9="Yes"),"⚠️ OVERWORK",IF(OR(J9="Yes",K9>0,L9="Yes",M9="Yes"),"🔻 UNDERWORK","✓ OK"))
A10: 6 | B10: Barlow, Duanne Raule Martin | C10: 4853 | D10: ='Barlow, Duanne Raule Martin'!I49 | E10: ='Barlow, Duanne Raule Martin'!Q50 | F10: =SUMPRODUCT((('Barlow, Duanne Raule Martin'!I14+'Barlow, Duanne Raule Martin'!I15)>12)*1)+SUMPRODUCT((('Barlow, Duanne Raule Martin'!I16+'Barlow, Duanne Raule Martin'!I17)>12)*1)+SUMPRODUCT((('Barlow, Duanne Raule Martin'!I18+'Barlow, Duanne Raule Martin'!I19)>12)*1)+SUMPRODUCT((('Barlow, Duanne Raule Martin'!I20+'Barlow, Duanne Raule Martin'!I21)>12)*1)+SUMPRODUCT((('Barlow, Duanne Raule Martin'!I22+'Barlow, Duanne Raule Martin'!I23)>12)*1)+SUMPRODUCT((('Barlow, Duanne Raule Martin'!I24+'Barlow, Duanne Raule Martin'!I25)>12)*1)+SUMPRODUCT((('Barlow, Duanne Raule Martin'!I26+'Barlow, Duanne Raule Martin'!I27)>12)*1)+SUMPRODUCT((('Barlow, Duanne Raule Martin'!I30+'Barlow, Duanne Raule Martin'!I31)>12)*1)+SUMPRODUCT((('Barlow, Duanne Raule Martin'!I32+'Barlow, Duanne Raule Martin'!I33)>12)*1)+SUMPRODUCT((('Barlow, Duanne Raule Martin'!I34+'Barlow, Duanne Raule Martin'!I35)>12)*1)+SUMPRODUCT((('Barlow, Duanne Raule Martin'!I36+'Barlow, Duanne Raule Martin'!I37)>12)*1)+SUMPRODUCT((('Barlow, Duanne Raule Martin'!I38+'Barlow, Duanne Raule Martin'!I39)>12)*1)+SUMPRODUCT((('Barlow, Duanne Raule Martin'!I40+'Barlow, Duanne Raule Martin'!I41)>12)*1)+SUMPRODUCT((('Barlow, Duanne Raule Martin'!I42+'Barlow, Duanne Raule Martin'!I43)>12)*1)+SUMPRODUCT((('Barlow, Duanne Raule Martin'!I45+'Barlow, Duanne Raule Martin'!I46)>12)*1)+SUMPRODUCT((('Barlow, Duanne Raule Martin'!I47+'Barlow, Duanne Raule Martin'!I48)>12)*1) | G10: =IF(MAX(SUM('Barlow, Duanne Raule Martin'!I14:I27),SUM('Barlow, Duanne Raule Martin'!I30:I43))>60,"Yes","") | H10: =IF(OR(AND(('Barlow, Duanne Raule Martin'!I14+'Barlow, Duanne Raule Martin'!I15)>0,('Barlow, Duanne Raule Martin'!I16+'Barlow, Duanne Raule Martin'!I17)>0,('Barlow, Duanne Raule Martin'!I18+'Barlow, Duanne Raule Martin'!I19)>0,('Barlow, Duanne Raule Martin'!I20+'Barlow, Duanne Raule Martin'!I21)>0,('Barlow, Duanne Raule Martin'!I22+'Barlow, Duanne Raule Martin'!I23)>0,('Barlow, Duanne Raule Martin'!I24+'Barlow, Duanne Raule Martin'!I25)>0,('Barlow, Duanne Raule Martin'!I26+'Barlow, Duanne Raule Martin'!I27)>0),AND(('Barlow, Duanne Raule Martin'!I30+'Barlow, Duanne Raule Martin'!I31)>0,('Barlow, Duanne Raule Martin'!I32+'Barlow, Duanne Raule Martin'!I33)>0,('Barlow, Duanne Raule Martin'!I34+'Barlow, Duanne Raule Martin'!I35)>0,('Barlow, Duanne Raule Martin'!I36+'Barlow, Duanne Raule Martin'!I37)>0,('Barlow, Duanne Raule Martin'!I38+'Barlow, Duanne Raule Martin'!I39)>0,('Barlow, Duanne Raule Martin'!I40+'Barlow, Duanne Raule Martin'!I41)>0,('Barlow, Duanne Raule Martin'!I42+'Barlow, Duanne Raule Martin'!I43)>0)),"Yes","") | I10: =IF('Barlow, Duanne Raule Martin'!N49>40,"Yes","") | J10: =IF(OR(AND(SUM('Barlow, Duanne Raule Martin'!I14:I27)>0,SUM('Barlow, Duanne Raule Martin'!I14:I27)<40),AND(SUM('Barlow, Duanne Raule Martin'!I30:I43)>0,SUM('Barlow, Duanne Raule Martin'!I30:I43)<40)),"Yes","") | K10: =SUMPRODUCT(('Barlow, Duanne Raule Martin'!I14:I48>0)*('Barlow, Duanne Raule Martin'!I14:I48<8)) | L10: =IF('Barlow, Duanne Raule Martin'!Q50<5,"Yes","") | M10: =IF(AND('Barlow, Duanne Raule Martin'!I49>0,'Barlow, Duanne Raule Martin'!I49<80),"Yes","") | N10: =IF(OR(F10>0,G10="Yes",H10="Yes",I10="Yes"),"⚠️ OVERWORK",IF(OR(J10="Yes",K10>0,L10="Yes",M10="Yes"),"🔻 UNDERWORK","✓ OK"))
A11: 7 | B11: Best-Archer, Rozetta | C11: 5442 | D11: ='Best-Archer, Rozetta'!I49 | E11: ='Best-Archer, Rozetta'!Q50 | F11: =SUMPRODUCT((('Best-Archer, Rozetta'!I14+'Best-Archer, Rozetta'!I15)>12)*1)+SUMPRODUCT((('Best-Archer, Rozetta'!I16+'Best-Archer, Rozetta'!I17)>12)*1)+SUMPRODUCT((('Best-Archer, Rozetta'!I18+'Best-Archer, Rozetta'!I19)>12)*1)+SUMPRODUCT((('Best-Archer, Rozetta'!I20+'Best-Archer, Rozetta'!I21)>12)*1)+SUMPRODUCT((('Best-Archer, Rozetta'!I22+'Best-Archer, Rozetta'!I23)>12)*1)+SUMPRODUCT((('Best-Archer, Rozetta'!I24+'Best-Archer, Rozetta'!I25)>12)*1)+SUMPRODUCT((('Best-Archer, Rozetta'!I26+'Best-Archer, Rozetta'!I27)>12)*1)+SUMPRODUCT((('Best-Archer, Rozetta'!I30+'Best-Archer, Rozetta'!I31)>12)*1)+SUMPRODUCT((('Best-Archer, Rozetta'!I32+'Best-Archer, Rozetta'!I33)>12)*1)+SUMPRODUCT((('Best-Archer, Rozetta'!I34+'Best-Archer, Rozetta'!I35)>12)*1)+SUMPRODUCT((('Best-Archer, Rozetta'!I36+'Best-Archer, Rozetta'!I37)>12)*1)+SUMPRODUCT((('Best-Archer, Rozetta'!I38+'Best-Archer, Rozetta'!I39)>12)*1)+SUMPRODUCT((('Best-Archer, Rozetta'!I40+'Best-Archer, Rozetta'!I41)>12)*1)+SUMPRODUCT((('Best-Archer, Rozetta'!I42+'Best-Archer, Rozetta'!I43)>12)*1)+SUMPRODUCT((('Best-Archer, Rozetta'!I45+'Best-Archer, Rozetta'!I46)>12)*1)+SUMPRODUCT((('Best-Archer, Rozetta'!I47+'Best-Archer, Rozetta'!I48)>12)*1) | G11: =IF(MAX(SUM('Best-Archer, Rozetta'!I14:I27),SUM('Best-Archer, Rozetta'!I30:I43))>60,"Yes","") | H11: =IF(OR(AND(('Best-Archer, Rozetta'!I14+'Best-Archer, Rozetta'!I15)>0,('Best-Archer, Rozetta'!I16+'Best-Archer, Rozetta'!I17)>0,('Best-Archer, Rozetta'!I18+'Best-Archer, Rozetta'!I19)>0,('Best-Archer, Rozetta'!I20+'Best-Archer, Rozetta'!I21)>0,('Best-Archer, Rozetta'!I22+'Best-Archer, Rozetta'!I23)>0,('Best-Archer, Rozetta'!I24+'Best-Archer, Rozetta'!I25)>0,('Best-Archer, Rozetta'!I26+'Best-Archer, Rozetta'!I27)>0),AND(('Best-Archer, Rozetta'!I30+'Best-Archer, Rozetta'!I31)>0,('Best-Archer, Rozetta'!I32+'Best-Archer, Rozetta'!I33)>0,('Best-Archer, Rozetta'!I34+'Best-Archer, Rozetta'!I35)>0,('Best-Archer, Rozetta'!I36+'Best-Archer, Rozetta'!I37)>0,('Best-Archer, Rozetta'!I38+'Best-Archer, Rozetta'!I39)>0,('Best-Archer, Rozetta'!I40+'Best-Archer, Rozetta'!I41)>0,('Best-Archer, Rozetta'!I42+'Best-Archer, Rozetta'!I43)>0)),"Yes","") | I11: =IF('Best-Archer, Rozetta'!N49>40,"Yes","") | J11: =IF(OR(AND(SUM('Best-Archer, Rozetta'!I14:I27)>0,SUM('Best-Archer, Rozetta'!I14:I27)<40),AND(SUM('Best-Archer, Rozetta'!I30:I43)>0,SUM('Best-Archer, Rozetta'!I30:I43)<40)),"Yes","") | K11: =SUMPRODUCT(('Best-Archer, Rozetta'!I14:I48>0)*('Best-Archer, Rozetta'!I14:I48<8)) | L11: =IF('Best-Archer, Rozetta'!Q50<5,"Yes","") | M11: =IF(AND('Best-Archer, Rozetta'!I49>0,'Best-Archer, Rozetta'!I49<80),"Yes","") | N11: =IF(OR(F11>0,G11="Yes",H11="Yes",I11="Yes"),"⚠️ OVERWORK",IF(OR(J11="Yes",K11>0,L11="Yes",M11="Yes"),"🔻 UNDERWORK","✓ OK"))
A12: 8 | B12: Blake, Corletta A | C12: 591 | D12: ='Blake, Corletta A'!I49 | E12: ='Blake, Corletta A'!Q50 | F12: =SUMPRODUCT((('Blake, Corletta A'!I14+'Blake, Corletta A'!I15)>12)*1)+SUMPRODUCT((('Blake, Corletta A'!I16+'Blake, Corletta A'!I17)>12)*1)+SUMPRODUCT((('Blake, Corletta A'!I18+'Blake, Corletta A'!I19)>12)*1)+SUMPRODUCT((('Blake, Corletta A'!I20+'Blake, Corletta A'!I21)>12)*1)+SUMPRODUCT((('Blake, Corletta A'!I22+'Blake, Corletta A'!I23)>12)*1)+SUMPRODUCT((('Blake, Corletta A'!I24+'Blake, Corletta A'!I25)>12)*1)+SUMPRODUCT((('Blake, Corletta A'!I26+'Blake, Corletta A'!I27)>12)*1)+SUMPRODUCT((('Blake, Corletta A'!I30+'Blake, Corletta A'!I31)>12)*1)+SUMPRODUCT((('Blake, Corletta A'!I32+'Blake, Corletta A'!I33)>12)*1)+SUMPRODUCT((('Blake, Corletta A'!I34+'Blake, Corletta A'!I35)>12)*1)+SUMPRODUCT((('Blake, Corletta A'!I36+'Blake, Corletta A'!I37)>12)*1)+SUMPRODUCT((('Blake, Corletta A'!I38+'Blake, Corletta A'!I39)>12)*1)+SUMPRODUCT((('Blake, Corletta A'!I40+'Blake, Corletta A'!I41)>12)*1)+SUMPRODUCT((('Blake, Corletta A'!I42+'Blake, Corletta A'!I43)>12)*1)+SUMPRODUCT((('Blake, Corletta A'!I45+'Blake, Corletta A'!I46)>12)*1)+SUMPRODUCT((('Blake, Corletta A'!I47+'Blake, Corletta A'!I48)>12)*1) | G12: =IF(MAX(SUM('Blake, Corletta A'!I14:I27),SUM('Blake, Corletta A'!I30:I43))>60,"Yes","") | H12: =IF(OR(AND(('Blake, Corletta A'!I14+'Blake, Corletta A'!I15)>0,('Blake, Corletta A'!I16+'Blake, Corletta A'!I17)>0,('Blake, Corletta A'!I18+'Blake, Corletta A'!I19)>0,('Blake, Corletta A'!I20+'Blake, Corletta A'!I21)>0,('Blake, Corletta A'!I22+'Blake, Corletta A'!I23)>0,('Blake, Corletta A'!I24+'Blake, Corletta A'!I25)>0,('Blake, Corletta A'!I26+'Blake, Corletta A'!I27)>0),AND(('Blake, Corletta A'!I30+'Blake, Corletta A'!I31)>0,('Blake, Corletta A'!I32+'Blake, Corletta A'!I33)>0,('Blake, Corletta A'!I34+'Blake, Corletta A'!I35)>0,('Blake, Corletta A'!I36+'Blake, Corletta A'!I37)>0,('Blake, Corletta A'!I38+'Blake, Corletta A'!I39)>0,('Blake, Corletta A'!I40+'Blake, Corletta A'!I41)>0,('Blake, Corletta A'!I42+'Blake, Corletta A'!I43)>0)),"Yes","") | I12: =IF('Blake, Corletta A'!N49>40,"Yes","") | J12: =IF(OR(AND(SUM('Blake, Corletta A'!I14:I27)>0,SUM('Blake, Corletta A'!I14:I27)<40),AND(SUM('Blake, Corletta A'!I30:I43)>0,SUM('Blake, Corletta A'!I30:I43)<40)),"Yes","") | K12: =SUMPRODUCT(('Blake, Corletta A'!I14:I48>0)*('Blake, Corletta A'!I14:I48<8)) | L12: =IF('Blake, Corletta A'!Q50<5,"Yes","") | M12: =IF(AND('Blake, Corletta A'!I49>0,'Blake, Corletta A'!I49<80),"Yes","") | N12: =IF(OR(F12>0,G12="Yes",H12="Yes",I12="Yes"),"⚠️ OVERWORK",IF(OR(J12="Yes",K12>0,L12="Yes",M12="Yes"),"🔻 UNDERWORK","✓ OK"))
A13: 9 | B13: Blucher, Winston Deon | C13: 5428 | D13: ='Blucher, Winston Deon'!I49 | E13: ='Blucher, Winston Deon'!Q50 | F13: =SUMPRODUCT((('Blucher, Winston Deon'!I14+'Blucher, Winston Deon'!I15)>12)*1)+SUMPRODUCT((('Blucher, Winston Deon'!I16+'Blucher, Winston Deon'!I17)>12)*1)+SUMPRODUCT((('Blucher, Winston Deon'!I18+'Blucher, Winston Deon'!I19)>12)*1)+SUMPRODUCT((('Blucher, Winston Deon'!I20+'Blucher, Winston Deon'!I21)>12)*1)+SUMPRODUCT((('Blucher, Winston Deon'!I22+'Blucher, Winston Deon'!I23)>12)*1)+SUMPRODUCT((('Blucher, Winston Deon'!I24+'Blucher, Winston Deon'!I25)>12)*1)+SUMPRODUCT((('Blucher, Winston Deon'!I26+'Blucher, Winston Deon'!I27)>12)*1)+SUMPRODUCT((('Blucher, Winston Deon'!I30+'Blucher, Winston Deon'!I31)>12)*1)+SUMPRODUCT((('Blucher, Winston Deon'!I32+'Blucher, Winston Deon'!I33)>12)*1)+SUMPRODUCT((('Blucher, Winston Deon'!I34+'Blucher, Winston Deon'!I35)>12)*1)+SUMPRODUCT((('Blucher, Winston Deon'!I36+'Blucher, Winston Deon'!I37)>12)*1)+SUMPRODUCT((('Blucher, Winston Deon'!I38+'Blucher, Winston Deon'!I39)>12)*1)+SUMPRODUCT((('Blucher, Winston Deon'!I40+'Blucher, Winston Deon'!I41)>12)*1)+SUMPRODUCT((('Blucher, Winston Deon'!I42+'Blucher, Winston Deon'!I43)>12)*1)+SUMPRODUCT((('Blucher, Winston Deon'!I45+'Blucher, Winston Deon'!I46)>12)*1)+SUMPRODUCT((('Blucher, Winston Deon'!I47+'Blucher, Winston Deon'!I48)>12)*1) | G13: =IF(MAX(SUM('Blucher, Winston Deon'!I14:I27),SUM('Blucher, Winston Deon'!I30:I43))>60,"Yes","") | H13: =IF(OR(AND(('Blucher, Winston Deon'!I14+'Blucher, Winston Deon'!I15)>0,('Blucher, Winston Deon'!I16+'Blucher, Winston Deon'!I17)>0,('Blucher, Winston Deon'!I18+'Blucher, Winston Deon'!I19)>0,('Blucher, Winston Deon'!I20+'Blucher, Winston Deon'!I21)>0,('Blucher, Winston Deon'!I22+'Blucher, Winston Deon'!I23)>0,('Blucher, Winston Deon'!I24+'Blucher, Winston Deon'!I25)>0,('Blucher, Winston Deon'!I26+'Blucher, Winston Deon'!I27)>0),AND(('Blucher, Winston Deon'!I30+'Blucher, Winston Deon'!I31)>0,('Blucher, Winston Deon'!I32+'Blucher, Winston Deon'!I33)>0,('Blucher, Winston Deon'!I34+'Blucher, Winston Deon'!I35)>0,('Blucher, Winston Deon'!I36+'Blucher, Winston Deon'!I37)>0,('Blucher, Winston Deon'!I38+'Blucher, Winston Deon'!I39)>0,('Blucher, Winston Deon'!I40+'Blucher, Winston Deon'!I41)>0,('Blucher, Winston Deon'!I42+'Blucher, Winston Deon'!I43)>0)),"Yes","") | I13: =IF('Blucher, Winston Deon'!N49>40,"Yes","") | J13: =IF(OR(AND(SUM('Blucher, Winston Deon'!I14:I27)>0,SUM('Blucher, Winston Deon'!I14:I27)<40),AND(SUM('Blucher, Winston Deon'!I30:I43)>0,SUM('Blucher, Winston Deon'!I30:I43)<40)),"Yes","") | K13: =SUMPRODUCT(('Blucher, Winston Deon'!I14:I48>0)*('Blucher, Winston Deon'!I14:I48<8)) | L13: =IF('Blucher, Winston Deon'!Q50<5,"Yes","") | M13: =IF(AND('Blucher, Winston Deon'!I49>0,'Blucher, Winston Deon'!I49<80),"Yes","") | N13: =IF(OR(F13>0,G13="Yes",H13="Yes",I13="Yes"),"⚠️ OVERWORK",IF(OR(J13="Yes",K13>0,L13="Yes",M13="Yes"),"🔻 UNDERWORK","✓ OK"))
A14: 10 | B14: Braithwaite, Miglon Alexis | C14: 5229 | D14: ='Braithwaite, Miglon Alexis'!I49 | E14: ='Braithwaite, Miglon Alexis'!Q50 | F14: =SUMPRODUCT((('Braithwaite, Miglon Alexis'!I14+'Braithwaite, Miglon Alexis'!I15)>12)*1)+SUMPRODUCT((('Braithwaite, Miglon Alexis'!I16+'Braithwaite, Miglon Alexis'!I17)>12)*1)+SUMPRODUCT((('Braithwaite, Miglon Alexis'!I18+'Braithwaite, Miglon Alexis'!I19)>12)*1)+SUMPRODUCT((('Braithwaite, Miglon Alexis'!I20+'Braithwaite, Miglon Alexis'!I21)>12)*1)+SUMPRODUCT((('Braithwaite, Miglon Alexis'!I22+'Braithwaite, Miglon Alexis'!I23)>12)*1)+SUMPRODUCT((('Braithwaite, Miglon Alexis'!I24+'Braithwaite, Miglon Alexis'!I25)>12)*1)+SUMPRODUCT((('Braithwaite, Miglon Alexis'!I26+'Braithwaite, Miglon Alexis'!I27)>12)*1)+SUMPRODUCT((('Braithwaite, Miglon Alexis'!I30+'Braithwaite, Miglon Alexis'!I31)>12)*1)+SUMPRODUCT((('Braithwaite, Miglon Alexis'!I32+'Braithwaite, Miglon Alexis'!I33)>12)*1)+SUMPRODUCT((('Braithwaite, Miglon Alexis'!I34+'Braithwaite, Miglon Alexis'!I35)>12)*1)+SUMPRODUCT((('Braithwaite, Miglon Alexis'!I36+'Braithwaite, Miglon Alexis'!I37)>12)*1)+SUMPRODUCT((('Braithwaite, Miglon Alexis'!I38+'Braithwaite, Miglon Alexis'!I39)>12)*1)+SUMPRODUCT((('Braithwaite, Miglon Alexis'!I40+'Braithwaite, Miglon Alexis'!I41)>12)*1)+SUMPRODUCT((('Braithwaite, Miglon Alexis'!I42+'Braithwaite, Miglon Alexis'!I43)>12)*1)+SUMPRODUCT((('Braithwaite, Miglon Alexis'!I45+'Braithwaite, Miglon Alexis'!I46)>12)*1)+SUMPRODUCT((('Braithwaite, Miglon Alexis'!I47+'Braithwaite, Miglon Alexis'!I48)>12)*1) | G14: =IF(MAX(SUM('Braithwaite, Miglon Alexis'!I14:I27),SUM('Braithwaite, Miglon Alexis'!I30:I43))>60,"Yes","") | H14: =IF(OR(AND(('Braithwaite, Miglon Alexis'!I14+'Braithwaite, Miglon Alexis'!I15)>0,('Braithwaite, Miglon Alexis'!I16+'Braithwaite, Miglon Alexis'!I17)>0,('Braithwaite, Miglon Alexis'!I18+'Braithwaite, Miglon Alexis'!I19)>0,('Braithwaite, Miglon Alexis'!I20+'Braithwaite, Miglon Alexis'!I21)>0,('Braithwaite, Miglon Alexis'!I22+'Braithwaite, Miglon Alexis'!I23)>0,('Braithwaite, Miglon Alexis'!I24+'Braithwaite, Miglon Alexis'!I25)>0,('Braithwaite, Miglon Alexis'!I26+'Braithwaite, Miglon Alexis'!I27)>0),AND(('Braithwaite, Miglon Alexis'!I30+'Braithwaite, Miglon Alexis'!I31)>0,('Braithwaite, Miglon Alexis'!I32+'Braithwaite, Miglon Alexis'!I33)>0,('Braithwaite, Miglon Alexis'!I34+'Braithwaite, Miglon Alexis'!I35)>0,('Braithwaite, Miglon Alexis'!I36+'Braithwaite, Miglon Alexis'!I37)>0,('Braithwaite, Miglon Alexis'!I38+'Braithwaite, Miglon Alexis'!I39)>0,('Braithwaite, Miglon Alexis'!I40+'Braithwaite, Miglon Alexis'!I41)>0,('Braithwaite, Miglon Alexis'!I42+'Braithwaite, Miglon Alexis'!I43)>0)),"Yes","") | I14: =IF('Braithwaite, Miglon Alexis'!N49>40,"Yes","") | J14: =IF(OR(AND(SUM('Braithwaite, Miglon Alexis'!I14:I27)>0,SUM('Braithwaite, Miglon Alexis'!I14:I27)<40),AND(SUM('Braithwaite, Miglon Alexis'!I30:I43)>0,SUM('Braithwaite, Miglon Alexis'!I30:I43)<40)),"Yes","") | K14: =SUMPRODUCT(('Braithwaite, Miglon Alexis'!I14:I48>0)*('Braithwaite, Miglon Alexis'!I14:I48<8)) | L14: =IF('Braithwaite, Miglon Alexis'!Q50<5,"Yes","") | M14: =IF(AND('Braithwaite, Miglon Alexis'!I49>0,'Braithwaite, Miglon Alexis'!I49<80),"Yes","") | N14: =IF(OR(F14>0,G14="Yes",H14="Yes",I14="Yes"),"⚠️ OVERWORK",IF(OR(J14="Yes",K14>0,L14="Yes",M14="Yes"),"🔻 UNDERWORK","✓ OK"))
A15: 11 | B15: Breedy, Orin Wayne | C15: 3645 | D15: ='Breedy, Orin Wayne'!I49 | E15: ='Breedy, Orin Wayne'!Q50 | F15: =SUMPRODUCT((('Breedy, Orin Wayne'!I14+'Breedy, Orin Wayne'!I15)>12)*1)+SUMPRODUCT((('Breedy, Orin Wayne'!I16+'Breedy, Orin Wayne'!I17)>12)*1)+SUMPRODUCT((('Breedy, Orin Wayne'!I18+'Breedy, Orin Wayne'!I19)>12)*1)+SUMPRODUCT((('Breedy, Orin Wayne'!I20+'Breedy, Orin Wayne'!I21)>12)*1)+SUMPRODUCT((('Breedy, Orin Wayne'!I22+'Breedy, Orin Wayne'!I23)>12)*1)+SUMPRODUCT((('Breedy, Orin Wayne'!I24+'Breedy, Orin Wayne'!I25)>12)*1)+SUMPRODUCT((('Breedy, Orin Wayne'!I26+'Breedy, Orin Wayne'!I27)>12)*1)+SUMPRODUCT((('Breedy, Orin Wayne'!I30+'Breedy, Orin Wayne'!I31)>12)*1)+SUMPRODUCT((('Breedy, Orin Wayne'!I32+'Breedy, Orin Wayne'!I33)>12)*1)+SUMPRODUCT((('Breedy, Orin Wayne'!I34+'Breedy, Orin Wayne'!I35)>12)*1)+SUMPRODUCT((('Breedy, Orin Wayne'!I36+'Breedy, Orin Wayne'!I37)>12)*1)+SUMPRODUCT((('Breedy, Orin Wayne'!I38+'Breedy, Orin Wayne'!I39)>12)*1)+SUMPRODUCT((('Breedy, Orin Wayne'!I40+'Breedy, Orin Wayne'!I41)>12)*1)+SUMPRODUCT((('Breedy, Orin Wayne'!I42+'Breedy, Orin Wayne'!I43)>12)*1)+SUMPRODUCT((('Breedy, Orin Wayne'!I45+'Breedy, Orin Wayne'!I46)>12)*1)+SUMPRODUCT((('Breedy, Orin Wayne'!I47+'Breedy, Orin Wayne'!I48)>12)*1) | G15: =IF(MAX(SUM('Breedy, Orin Wayne'!I14:I27),SUM('Breedy, Orin Wayne'!I30:I43))>60,"Yes","") | H15: =IF(OR(AND(('Breedy, Orin Wayne'!I14+'Breedy, Orin Wayne'!I15)>0,('Breedy, Orin Wayne'!I16+'Breedy, Orin Wayne'!I17)>0,('Breedy, Orin Wayne'!I18+'Breedy, Orin Wayne'!I19)>0,('Breedy, Orin Wayne'!I20+'Breedy, Orin Wayne'!I21)>0,('Breedy, Orin Wayne'!I22+'Breedy, Orin Wayne'!I23)>0,('Breedy, Orin Wayne'!I24+'Breedy, Orin Wayne'!I25)>0,('Breedy, Orin Wayne'!I26+'Breedy, Orin Wayne'!I27)>0),AND(('Breedy, Orin Wayne'!I30+'Breedy, Orin Wayne'!I31)>0,('Breedy, Orin Wayne'!I32+'Breedy, Orin Wayne'!I33)>0,('Breedy, Orin Wayne'!I34+'Breedy, Orin Wayne'!I35)>0,('Breedy, Orin Wayne'!I36+'Breedy, Orin Wayne'!I37)>0,('Breedy, Orin Wayne'!I38+'Breedy, Orin Wayne'!I39)>0,('Breedy, Orin Wayne'!I40+'Breedy, Orin Wayne'!I41)>0,('Breedy, Orin Wayne'!I42+'Breedy, Orin Wayne'!I43)>0)),"Yes","") | I15: =IF('Breedy, Orin Wayne'!N49>40,"Yes","") | J15: =IF(OR(AND(SUM('Breedy, Orin Wayne'!I14:I27)>0,SUM('Breedy, Orin Wayne'!I14:I27)<40),AND(SUM('Breedy, Orin Wayne'!I30:I43)>0,SUM('Breedy, Orin Wayne'!I30:I43)<40)),"Yes","") | K15: =SUMPRODUCT(('Breedy, Orin Wayne'!I14:I48>0)*('Breedy, Orin Wayne'!I14:I48<8)) | L15: =IF('Breedy, Orin Wayne'!Q50<5,"Yes","") | M15: =IF(AND('Breedy, Orin Wayne'!I49>0,'Breedy, Orin Wayne'!I49<80),"Yes","") | N15: =IF(OR(F15>0,G15="Yes",H15="Yes",I15="Yes"),"⚠️ OVERWORK",IF(OR(J15="Yes",K15>0,L15="Yes",M15="Yes"),"🔻 UNDERWORK","✓ OK"))
A16: 12 | B16: Breedy, Phoolkumarie | C16: 3752 | D16: ='Breedy, Phoolkumarie'!I49 | E16: ='Breedy, Phoolkumarie'!Q50 | F16: =SUMPRODUCT((('Breedy, Phoolkumarie'!I14+'Breedy, Phoolkumarie'!I15)>12)*1)+SUMPRODUCT((('Breedy, Phoolkumarie'!I16+'Breedy, Phoolkumarie'!I17)>12)*1)+SUMPRODUCT((('Breedy, Phoolkumarie'!I18+'Breedy, Phoolkumarie'!I19)>12)*1)+SUMPRODUCT((('Breedy, Phoolkumarie'!I20+'Breedy, Phoolkumarie'!I21)>12)*1)+SUMPRODUCT((('Breedy, Phoolkumarie'!I22+'Breedy, Phoolkumarie'!I23)>12)*1)+SUMPRODUCT((('Breedy, Phoolkumarie'!I24+'Breedy, Phoolkumarie'!I25)>12)*1)+SUMPRODUCT((('Breedy, Phoolkumarie'!I26+'Breedy, Phoolkumarie'!I27)>12)*1)+SUMPRODUCT((('Breedy, Phoolkumarie'!I30+'Breedy, Phoolkumarie'!I31)>12)*1)+SUMPRODUCT((('Breedy, Phoolkumarie'!I32+'Breedy, Phoolkumarie'!I33)>12)*1)+SUMPRODUCT((('Breedy, Phoolkumarie'!I34+'Breedy, Phoolkumarie'!I35)>12)*1)+SUMPRODUCT((('Breedy, Phoolkumarie'!I36+'Breedy, Phoolkumarie'!I37)>12)*1)+SUMPRODUCT((('Breedy, Phoolkumarie'!I38+'Breedy, Phoolkumarie'!I39)>12)*1)+SUMPRODUCT((('Breedy, Phoolkumarie'!I40+'Breedy, Phoolkumarie'!I41)>12)*1)+SUMPRODUCT((('Breedy, Phoolkumarie'!I42+'Breedy, Phoolkumarie'!I43)>12)*1)+SUMPRODUCT((('Breedy, Phoolkumarie'!I45+'Breedy, Phoolkumarie'!I46)>12)*1)+SUMPRODUCT((('Breedy, Phoolkumarie'!I47+'Breedy, Phoolkumarie'!I48)>12)*1) | G16: =IF(MAX(SUM('Breedy, Phoolkumarie'!I14:I27),SUM('Breedy, Phoolkumarie'!I30:I43))>60,"Yes","") | H16: =IF(OR(AND(('Breedy, Phoolkumarie'!I14+'Breedy, Phoolkumarie'!I15)>0,('Breedy, Phoolkumarie'!I16+'Breedy, Phoolkumarie'!I17)>0,('Breedy, Phoolkumarie'!I18+'Breedy, Phoolkumarie'!I19)>0,('Breedy, Phoolkumarie'!I20+'Breedy, Phoolkumarie'!I21)>0,('Breedy, Phoolkumarie'!I22+'Breedy, Phoolkumarie'!I23)>0,('Breedy, Phoolkumarie'!I24+'Breedy, Phoolkumarie'!I25)>0,('Breedy, Phoolkumarie'!I26+'Breedy, Phoolkumarie'!I27)>0),AND(('Breedy, Phoolkumarie'!I30+'Breedy, Phoolkumarie'!I31)>0,('Breedy, Phoolkumarie'!I32+'Breedy, Phoolkumarie'!I33)>0,('Breedy, Phoolkumarie'!I34+'Breedy, Phoolkumarie'!I35)>0,('Breedy, Phoolkumarie'!I36+'Breedy, Phoolkumarie'!I37)>0,('Breedy, Phoolkumarie'!I38+'Breedy, Phoolkumarie'!I39)>0,('Breedy, Phoolkumarie'!I40+'Breedy, Phoolkumarie'!I41)>0,('Breedy, Phoolkumarie'!I42+'Breedy, Phoolkumarie'!I43)>0)),"Yes","") | I16: =IF('Breedy, Phoolkumarie'!N49>40,"Yes","") | J16: =IF(OR(AND(SUM('Breedy, Phoolkumarie'!I14:I27)>0,SUM('Breedy, Phoolkumarie'!I14:I27)<40),AND(SUM('Breedy, Phoolkumarie'!I30:I43)>0,SUM('Breedy, Phoolkumarie'!I30:I43)<40)),"Yes","") | K16: =SUMPRODUCT(('Breedy, Phoolkumarie'!I14:I48>0)*('Breedy, Phoolkumarie'!I14:I48<8)) | L16: =IF('Breedy, Phoolkumarie'!Q50<5,"Yes","") | M16: =IF(AND('Breedy, Phoolkumarie'!I49>0,'Breedy, Phoolkumarie'!I49<80),"Yes","") | N16: =IF(OR(F16>0,G16="Yes",H16="Yes",I16="Yes"),"⚠️ OVERWORK",IF(OR(J16="Yes",K16>0,L16="Yes",M16="Yes"),"🔻 UNDERWORK","✓ OK"))
A17: 13 | B17: Brewster, Hilroy | C17: 1511 | D17: ='Brewster, Hilroy'!I49 | E17: ='Brewster, Hilroy'!Q50 | F17: =SUMPRODUCT((('Brewster, Hilroy'!I14+'Brewster, Hilroy'!I15)>12)*1)+SUMPRODUCT((('Brewster, Hilroy'!I16+'Brewster, Hilroy'!I17)>12)*1)+SUMPRODUCT((('Brewster, Hilroy'!I18+'Brewster, Hilroy'!I19)>12)*1)+SUMPRODUCT((('Brewster, Hilroy'!I20+'Brewster, Hilroy'!I21)>12)*1)+SUMPRODUCT((('Brewster, Hilroy'!I22+'Brewster, Hilroy'!I23)>12)*1)+SUMPRODUCT((('Brewster, Hilroy'!I24+'Brewster, Hilroy'!I25)>12)*1)+SUMPRODUCT((('Brewster, Hilroy'!I26+'Brewster, Hilroy'!I27)>12)*1)+SUMPRODUCT((('Brewster, Hilroy'!I30+'Brewster, Hilroy'!I31)>12)*1)+SUMPRODUCT((('Brewster, Hilroy'!I32+'Brewster, Hilroy'!I33)>12)*1)+SUMPRODUCT((('Brewster, Hilroy'!I34+'Brewster, Hilroy'!I35)>12)*1)+SUMPRODUCT((('Brewster, Hilroy'!I36+'Brewster, Hilroy'!I37)>12)*1)+SUMPRODUCT((('Brewster, Hilroy'!I38+'Brewster, Hilroy'!I39)>12)*1)+SUMPRODUCT((('Brewster, Hilroy'!I40+'Brewster, Hilroy'!I41)>12)*1)+SUMPRODUCT((('Brewster, Hilroy'!I42+'Brewster, Hilroy'!I43)>12)*1)+SUMPRODUCT((('Brewster, Hilroy'!I45+'Brewster, Hilroy'!I46)>12)*1)+SUMPRODUCT((('Brewster, Hilroy'!I47+'Brewster, Hilroy'!I48)>12)*1) | G17: =IF(MAX(SUM('Brewster, Hilroy'!I14:I27),SUM('Brewster, Hilroy'!I30:I43))>60,"Yes","") | H17: =IF(OR(AND(('Brewster, Hilroy'!I14+'Brewster, Hilroy'!I15)>0,('Brewster, Hilroy'!I16+'Brewster, Hilroy'!I17)>0,('Brewster, Hilroy'!I18+'Brewster, Hilroy'!I19)>0,('Brewster, Hilroy'!I20+'Brewster, Hilroy'!I21)>0,('Brewster, Hilroy'!I22+'Brewster, Hilroy'!I23)>0,('Brewster, Hilroy'!I24+'Brewster, Hilroy'!I25)>0,('Brewster, Hilroy'!I26+'Brewster, Hilroy'!I27)>0),AND(('Brewster, Hilroy'!I30+'Brewster, Hilroy'!I31)>0,('Brewster, Hilroy'!I32+'Brewster, Hilroy'!I33)>0,('Brewster, Hilroy'!I34+'Brewster, Hilroy'!I35)>0,('Brewster, Hilroy'!I36+'Brewster, Hilroy'!I37)>0,('Brewster, Hilroy'!I38+'Brewster, Hilroy'!I39)>0,('Brewster, Hilroy'!I40+'Brewster, Hilroy'!I41)>0,('Brewster, Hilroy'!I42+'Brewster, Hilroy'!I43)>0)),"Yes","") | I17: =IF('Brewster, Hilroy'!N49>40,"Yes","") | J17: =IF(OR(AND(SUM('Brewster, Hilroy'!I14:I27)>0,SUM('Brewster, Hilroy'!I14:I27)<40),AND(SUM('Brewster, Hilroy'!I30:I43)>0,SUM('Brewster, Hilroy'!I30:I43)<40)),"Yes","") | K17: =SUMPRODUCT(('Brewster, Hilroy'!I14:I48>0)*('Brewster, Hilroy'!I14:I48<8)) | L17: =IF('Brewster, Hilroy'!Q50<5,"Yes","") | M17: =IF(AND('Brewster, Hilroy'!I49>0,'Brewster, Hilroy'!I49<80),"Yes","") | N17: =IF(OR(F17>0,G17="Yes",H17="Yes",I17="Yes"),"⚠️ OVERWORK",IF(OR(J17="Yes",K17>0,L17="Yes",M17="Yes"),"🔻 UNDERWORK","✓ OK"))
A18: 14 | B18: Browne, Marvina Feona | C18: 3909 | D18: ='Browne, Marvina Feona'!I49 | E18: ='Browne, Marvina Feona'!Q50 | F18: =SUMPRODUCT((('Browne, Marvina Feona'!I14+'Browne, Marvina Feona'!I15)>12)*1)+SUMPRODUCT((('Browne, Marvina Feona'!I16+'Browne, Marvina Feona'!I17)>12)*1)+SUMPRODUCT((('Browne, Marvina Feona'!I18+'Browne, Marvina Feona'!I19)>12)*1)+SUMPRODUCT((('Browne, Marvina Feona'!I20+'Browne, Marvina Feona'!I21)>12)*1)+SUMPRODUCT((('Browne, Marvina Feona'!I22+'Browne, Marvina Feona'!I23)>12)*1)+SUMPRODUCT((('Browne, Marvina Feona'!I24+'Browne, Marvina Feona'!I25)>12)*1)+SUMPRODUCT((('Browne, Marvina Feona'!I26+'Browne, Marvina Feona'!I27)>12)*1)+SUMPRODUCT((('Browne, Marvina Feona'!I30+'Browne, Marvina Feona'!I31)>12)*1)+SUMPRODUCT((('Browne, Marvina Feona'!I32+'Browne, Marvina Feona'!I33)>12)*1)+SUMPRODUCT((('Browne, Marvina Feona'!I34+'Browne, Marvina Feona'!I35)>12)*1)+SUMPRODUCT((('Browne, Marvina Feona'!I36+'Browne, Marvina Feona'!I37)>12)*1)+SUMPRODUCT((('Browne, Marvina Feona'!I38+'Browne, Marvina Feona'!I39)>12)*1)+SUMPRODUCT((('Browne, Marvina Feona'!I40+'Browne, Marvina Feona'!I41)>12)*1)+SUMPRODUCT((('Browne, Marvina Feona'!I42+'Browne, Marvina Feona'!I43)>12)*1)+SUMPRODUCT((('Browne, Marvina Feona'!I45+'Browne, Marvina Feona'!I46)>12)*1)+SUMPRODUCT((('Browne, Marvina Feona'!I47+'Browne, Marvina Feona'!I48)>12)*1) | G18: =IF(MAX(SUM('Browne, Marvina Feona'!I14:I27),SUM('Browne, Marvina Feona'!I30:I43))>60,"Yes","") | H18: =IF(OR(AND(('Browne, Marvina Feona'!I14+'Browne, Marvina Feona'!I15)>0,('Browne, Marvina Feona'!I16+'Browne, Marvina Feona'!I17)>0,('Browne, Marvina Feona'!I18+'Browne, Marvina Feona'!I19)>0,('Browne, Marvina Feona'!I20+'Browne, Marvina Feona'!I21)>0,('Browne, Marvina Feona'!I22+'Browne, Marvina Feona'!I23)>0,('Browne, Marvina Feona'!I24+'Browne, Marvina Feona'!I25)>0,('Browne, Marvina Feona'!I26+'Browne, Marvina Feona'!I27)>0),AND(('Browne, Marvina Feona'!I30+'Browne, Marvina Feona'!I31)>0,('Browne, Marvina Feona'!I32+'Browne, Marvina Feona'!I33)>0,('Browne, Marvina Feona'!I34+'Browne, Marvina Feona'!I35)>0,('Browne, Marvina Feona'!I36+'Browne, Marvina Feona'!I37)>0,('Browne, Marvina Feona'!I38+'Browne, Marvina Feona'!I39)>0,('Browne, Marvina Feona'!I40+'Browne, Marvina Feona'!I41)>0,('Browne, Marvina Feona'!I42+'Browne, Marvina Feona'!I43)>0)),"Yes","") | I18: =IF('Browne, Marvina Feona'!N49>40,"Yes","") | J18: =IF(OR(AND(SUM('Browne, Marvina Feona'!I14:I27)>0,SUM('Browne, Marvina Feona'!I14:I27)<40),AND(SUM('Browne, Marvina Feona'!I30:I43)>0,SUM('Browne, Marvina Feona'!I30:I43)<40)),"Yes","") | K18: =SUMPRODUCT(('Browne, Marvina Feona'!I14:I48>0)*('Browne, Marvina Feona'!I14:I48<8)) | L18: =IF('Browne, Marvina Feona'!Q50<5,"Yes","") | M18: =IF(AND('Browne, Marvina Feona'!I49>0,'Browne, Marvina Feona'!I49<80),"Yes","") | N18: =IF(OR(F18>0,G18="Yes",H18="Yes",I18="Yes"),"⚠️ OVERWORK",IF(OR(J18="Yes",K18>0,L18="Yes",M18="Yes"),"🔻 UNDERWORK","✓ OK"))
A19: 15 | B19: Bullen, Herman Fitzgerald | C19: 4131 | D19: ='Bullen, Herman Fitzgerald'!I49 | E19: ='Bullen, Herman Fitzgerald'!Q50 | F19: =SUMPRODUCT((('Bullen, Herman Fitzgerald'!I14+'Bullen, Herman Fitzgerald'!I15)>12)*1)+SUMPRODUCT((('Bullen, Herman Fitzgerald'!I16+'Bullen, Herman Fitzgerald'!I17)>12)*1)+SUMPRODUCT((('Bullen, Herman Fitzgerald'!I18+'Bullen, Herman Fitzgerald'!I19)>12)*1)+SUMPRODUCT((('Bullen, Herman Fitzgerald'!I20+'Bullen, Herman Fitzgerald'!I21)>12)*1)+SUMPRODUCT((('Bullen, Herman Fitzgerald'!I22+'Bullen, Herman Fitzgerald'!I23)>12)*1)+SUMPRODUCT((('Bullen, Herman Fitzgerald'!I24+'Bullen, Herman Fitzgerald'!I25)>12)*1)+SUMPRODUCT((('Bullen, Herman Fitzgerald'!I26+'Bullen, Herman Fitzgerald'!I27)>12)*1)+SUMPRODUCT((('Bullen, Herman Fitzgerald'!I30+'Bullen, Herman Fitzgerald'!I31)>12)*1)+SUMPRODUCT((('Bullen, Herman Fitzgerald'!I32+'Bullen, Herman Fitzgerald'!I33)>12)*1)+SUMPRODUCT((('Bullen, Herman Fitzgerald'!I34+'Bullen, Herman Fitzgerald'!I35)>12)*1)+SUMPRODUCT((('Bullen, Herman Fitzgerald'!I36+'Bullen, Herman Fitzgerald'!I37)>12)*1)+SUMPRODUCT((('Bullen, Herman Fitzgerald'!I38+'Bullen, Herman Fitzgerald'!I39)>12)*1)+SUMPRODUCT((('Bullen, Herman Fitzgerald'!I40+'Bullen, Herman Fitzgerald'!I41)>12)*1)+SUMPRODUCT((('Bullen, Herman Fitzgerald'!I42+'Bullen, Herman Fitzgerald'!I43)>12)*1)+SUMPRODUCT((('Bullen, Herman Fitzgerald'!I45+'Bullen, Herman Fitzgerald'!I46)>12)*1)+SUMPRODUCT((('Bullen, Herman Fitzgerald'!I47+'Bullen, Herman Fitzgerald'!I48)>12)*1) | G19: =IF(MAX(SUM('Bullen, Herman Fitzgerald'!I14:I27),SUM('Bullen, Herman Fitzgerald'!I30:I43))>60,"Yes","") | H19: =IF(OR(AND(('Bullen, Herman Fitzgerald'!I14+'Bullen, Herman Fitzgerald'!I15)>0,('Bullen, Herman Fitzgerald'!I16+'Bullen, Herman Fitzgerald'!I17)>0,('Bullen, Herman Fitzgerald'!I18+'Bullen, Herman Fitzgerald'!I19)>0,('Bullen, Herman Fitzgerald'!I20+'Bullen, Herman Fitzgerald'!I21)>0,('Bullen, Herman Fitzgerald'!I22+'Bullen, Herman Fitzgerald'!I23)>0,('Bullen, Herman Fitzgerald'!I24+'Bullen, Herman Fitzgerald'!I25)>0,('Bullen, Herman Fitzgerald'!I26+'Bullen, Herman Fitzgerald'!I27)>0),AND(('Bullen, Herman Fitzgerald'!I30+'Bullen, Herman Fitzgerald'!I31)>0,('Bullen, Herman Fitzgerald'!I32+'Bullen, Herman Fitzgerald'!I33)>0,('Bullen, Herman Fitzgerald'!I34+'Bullen, Herman Fitzgerald'!I35)>0,('Bullen, Herman Fitzgerald'!I36+'Bullen, Herman Fitzgerald'!I37)>0,('Bullen, Herman Fitzgerald'!I38+'Bullen, Herman Fitzgerald'!I39)>0,('Bullen, Herman Fitzgerald'!I40+'Bullen, Herman Fitzgerald'!I41)>0,('Bullen, Herman Fitzgerald'!I42+'Bullen, Herman Fitzgerald'!I43)>0)),"Yes","") | I19: =IF('Bullen, Herman Fitzgerald'!N49>40,"Yes","") | J19: =IF(OR(AND(SUM('Bullen, Herman Fitzgerald'!I14:I27)>0,SUM('Bullen, Herman Fitzgerald'!I14:I27)<40),AND(SUM('Bullen, Herman Fitzgerald'!I30:I43)>0,SUM('Bullen, Herman Fitzgerald'!I30:I43)<40)),"Yes","") | K19: =SUMPRODUCT(('Bullen, Herman Fitzgerald'!I14:I48>0)*('Bullen, Herman Fitzgerald'!I14:I48<8)) | L19: =IF('Bullen, Herman Fitzgerald'!Q50<5,"Yes","") | M19: =IF(AND('Bullen, Herman Fitzgerald'!I49>0,'Bullen, Herman Fitzgerald'!I49<80),"Yes","") | N19: =IF(OR(F19>0,G19="Yes",H19="Yes",I19="Yes"),"⚠️ OVERWORK",IF(OR(J19="Yes",K19>0,L19="Yes",M19="Yes"),"🔻 UNDERWORK","✓ OK"))
A20: 16 | B20: Bumbury, Joan | C20: 3348 | D20: ='Bumbury, Joan'!I49 | E20: ='Bumbury, Joan'!Q50 | F20: =SUMPRODUCT((('Bumbury, Joan'!I14+'Bumbury, Joan'!I15)>12)*1)+SUMPRODUCT((('Bumbury, Joan'!I16+'Bumbury, Joan'!I17)>12)*1)+SUMPRODUCT((('Bumbury, Joan'!I18+'Bumbury, Joan'!I19)>12)*1)+SUMPRODUCT((('Bumbury, Joan'!I20+'Bumbury, Joan'!I21)>12)*1)+SUMPRODUCT((('Bumbury, Joan'!I22+'Bumbury, Joan'!I23)>12)*1)+SUMPRODUCT((('Bumbury, Joan'!I24+'Bumbury, Joan'!I25)>12)*1)+SUMPRODUCT((('Bumbury, Joan'!I26+'Bumbury, Joan'!I27)>12)*1)+SUMPRODUCT((('Bumbury, Joan'!I30+'Bumbury, Joan'!I31)>12)*1)+SUMPRODUCT((('Bumbury, Joan'!I32+'Bumbury, Joan'!I33)>12)*1)+SUMPRODUCT((('Bumbury, Joan'!I34+'Bumbury, Joan'!I35)>12)*1)+SUMPRODUCT((('Bumbury, Joan'!I36+'Bumbury, Joan'!I37)>12)*1)+SUMPRODUCT((('Bumbury, Joan'!I38+'Bumbury, Joan'!I39)>12)*1)+SUMPRODUCT((('Bumbury, Joan'!I40+'Bumbury, Joan'!I41)>12)*1)+SUMPRODUCT((('Bumbury, Joan'!I42+'Bumbury, Joan'!I43)>12)*1)+SUMPRODUCT((('Bumbury, Joan'!I45+'Bumbury, Joan'!I46)>12)*1)+SUMPRODUCT((('Bumbury, Joan'!I47+'Bumbury, Joan'!I48)>12)*1) | G20: =IF(MAX(SUM('Bumbury, Joan'!I14:I27),SUM('Bumbury, Joan'!I30:I43))>60,"Yes","") | H20: =IF(OR(AND(('Bumbury, Joan'!I14+'Bumbury, Joan'!I15)>0,('Bumbury, Joan'!I16+'Bumbury, Joan'!I17)>0,('Bumbury, Joan'!I18+'Bumbury, Joan'!I19)>0,('Bumbury, Joan'!I20+'Bumbury, Joan'!I21)>0,('Bumbury, Joan'!I22+'Bumbury, Joan'!I23)>0,('Bumbury, Joan'!I24+'Bumbury, Joan'!I25)>0,('Bumbury, Joan'!I26+'Bumbury, Joan'!I27)>0),AND(('Bumbury, Joan'!I30+'Bumbury, Joan'!I31)>0,('Bumbury, Joan'!I32+'Bumbury, Joan'!I33)>0,('Bumbury, Joan'!I34+'Bumbury, Joan'!I35)>0,('Bumbury, Joan'!I36+'Bumbury, Joan'!I37)>0,('Bumbury, Joan'!I38+'Bumbury, Joan'!I39)>0,('Bumbury, Joan'!I40+'Bumbury, Joan'!I41)>0,('Bumbury, Joan'!I42+'Bumbury, Joan'!I43)>0)),"Yes","") | I20: =IF('Bumbury, Joan'!N49>40,"Yes","") | J20: =IF(OR(AND(SUM('Bumbury, Joan'!I14:I27)>0,SUM('Bumbury, Joan'!I14:I27)<40),AND(SUM('Bumbury, Joan'!I30:I43)>0,SUM('Bumbury, Joan'!I30:I43)<40)),"Yes","") | K20: =SUMPRODUCT(('Bumbury, Joan'!I14:I48>0)*('Bumbury, Joan'!I14:I48<8)) | L20: =IF('Bumbury, Joan'!Q50<5,"Yes","") | M20: =IF(AND('Bumbury, Joan'!I49>0,'Bumbury, Joan'!I49<80),"Yes","") | N20: =IF(OR(F20>0,G20="Yes",H20="Yes",I20="Yes"),"⚠️ OVERWORK",IF(OR(J20="Yes",K20>0,L20="Yes",M20="Yes"),"🔻 UNDERWORK","✓ OK"))
A21: 17 | B21: Chester, Violet | C21: 4175 | D21: ='Chester, Violet'!I49 | E21: ='Chester, Violet'!Q50 | F21: =SUMPRODUCT((('Chester, Violet'!I14+'Chester, Violet'!I15)>12)*1)+SUMPRODUCT((('Chester, Violet'!I16+'Chester, Violet'!I17)>12)*1)+SUMPRODUCT((('Chester, Violet'!I18+'Chester, Violet'!I19)>12)*1)+SUMPRODUCT((('Chester, Violet'!I20+'Chester, Violet'!I21)>12)*1)+SUMPRODUCT((('Chester, Violet'!I22+'Chester, Violet'!I23)>12)*1)+SUMPRODUCT((('Chester, Violet'!I24+'Chester, Violet'!I25)>12)*1)+SUMPRODUCT((('Chester, Violet'!I26+'Chester, Violet'!I27)>12)*1)+SUMPRODUCT((('Chester, Violet'!I30+'Chester, Violet'!I31)>12)*1)+SUMPRODUCT((('Chester, Violet'!I32+'Chester, Violet'!I33)>12)*1)+SUMPRODUCT((('Chester, Violet'!I34+'Chester, Violet'!I35)>12)*1)+SUMPRODUCT((('Chester, Violet'!I36+'Chester, Violet'!I37)>12)*1)+SUMPRODUCT((('Chester, Violet'!I38+'Chester, Violet'!I39)>12)*1)+SUMPRODUCT((('Chester, Violet'!I40+'Chester, Violet'!I41)>12)*1)+SUMPRODUCT((('Chester, Violet'!I42+'Chester, Violet'!I43)>12)*1)+SUMPRODUCT((('Chester, Violet'!I45+'Chester, Violet'!I46)>12)*1)+SUMPRODUCT((('Chester, Violet'!I47+'Chester, Violet'!I48)>12)*1) | G21: =IF(MAX(SUM('Chester, Violet'!I14:I27),SUM('Chester, Violet'!I30:I43))>60,"Yes","") | H21: =IF(OR(AND(('Chester, Violet'!I14+'Chester, Violet'!I15)>0,('Chester, Violet'!I16+'Chester, Violet'!I17)>0,('Chester, Violet'!I18+'Chester, Violet'!I19)>0,('Chester, Violet'!I20+'Chester, Violet'!I21)>0,('Chester, Violet'!I22+'Chester, Violet'!I23)>0,('Chester, Violet'!I24+'Chester, Violet'!I25)>0,('Chester, Violet'!I26+'Chester, Violet'!I27)>0),AND(('Chester, Violet'!I30+'Chester, Violet'!I31)>0,('Chester, Violet'!I32+'Chester, Violet'!I33)>0,('Chester, Violet'!I34+'Chester, Violet'!I35)>0,('Chester, Violet'!I36+'Chester, Violet'!I37)>0,('Chester, Violet'!I38+'Chester, Violet'!I39)>0,('Chester, Violet'!I40+'Chester, Violet'!I41)>0,('Chester, Violet'!I42+'Chester, Violet'!I43)>0)),"Yes","") | I21: =IF('Chester, Violet'!N49>40,"Yes","") | J21: =IF(OR(AND(SUM('Chester, Violet'!I14:I27)>0,SUM('Chester, Violet'!I14:I27)<40),AND(SUM('Chester, Violet'!I30:I43)>0,SUM('Chester, Violet'!I30:I43)<40)),"Yes","") | K21: =SUMPRODUCT(('Chester, Violet'!I14:I48>0)*('Chester, Violet'!I14:I48<8)) | L21: =IF('Chester, Violet'!Q50<5,"Yes","") | M21: =IF(AND('Chester, Violet'!I49>0,'Chester, Violet'!I49<80),"Yes","") | N21: =IF(OR(F21>0,G21="Yes",H21="Yes",I21="Yes"),"⚠️ OVERWORK",IF(OR(J21="Yes",K21>0,L21="Yes",M21="Yes"),"🔻 UNDERWORK","✓ OK"))
A22: 18 | B22: Clarke, Penopolly | C22: 2380 | D22: ='Clarke, Penopolly'!I49 | E22: ='Clarke, Penopolly'!Q50 | F22: =SUMPRODUCT((('Clarke, Penopolly'!I14+'Clarke, Penopolly'!I15)>12)*1)+SUMPRODUCT((('Clarke, Penopolly'!I16+'Clarke, Penopolly'!I17)>12)*1)+SUMPRODUCT((('Clarke, Penopolly'!I18+'Clarke, Penopolly'!I19)>12)*1)+SUMPRODUCT((('Clarke, Penopolly'!I20+'Clarke, Penopolly'!I21)>12)*1)+SUMPRODUCT((('Clarke, Penopolly'!I22+'Clarke, Penopolly'!I23)>12)*1)+SUMPRODUCT((('Clarke, Penopolly'!I24+'Clarke, Penopolly'!I25)>12)*1)+SUMPRODUCT((('Clarke, Penopolly'!I26+'Clarke, Penopolly'!I27)>12)*1)+SUMPRODUCT((('Clarke, Penopolly'!I30+'Clarke, Penopolly'!I31)>12)*1)+SUMPRODUCT((('Clarke, Penopolly'!I32+'Clarke, Penopolly'!I33)>12)*1)+SUMPRODUCT((('Clarke, Penopolly'!I34+'Clarke, Penopolly'!I35)>12)*1)+SUMPRODUCT((('Clarke, Penopolly'!I36+'Clarke, Penopolly'!I37)>12)*1)+SUMPRODUCT((('Clarke, Penopolly'!I38+'Clarke, Penopolly'!I39)>12)*1)+SUMPRODUCT((('Clarke, Penopolly'!I40+'Clarke, Penopolly'!I41)>12)*1)+SUMPRODUCT((('Clarke, Penopolly'!I42+'Clarke, Penopolly'!I43)>12)*1)+SUMPRODUCT((('Clarke, Penopolly'!I45+'Clarke, Penopolly'!I46)>12)*1)+SUMPRODUCT((('Clarke, Penopolly'!I47+'Clarke, Penopolly'!I48)>12)*1) | G22: =IF(MAX(SUM('Clarke, Penopolly'!I14:I27),SUM('Clarke, Penopolly'!I30:I43))>60,"Yes","") | H22: =IF(OR(AND(('Clarke, Penopolly'!I14+'Clarke, Penopolly'!I15)>0,('Clarke, Penopolly'!I16+'Clarke, Penopolly'!I17)>0,('Clarke, Penopolly'!I18+'Clarke, Penopolly'!I19)>0,('Clarke, Penopolly'!I20+'Clarke, Penopolly'!I21)>0,('Clarke, Penopolly'!I22+'Clarke, Penopolly'!I23)>0,('Clarke, Penopolly'!I24+'Clarke, Penopolly'!I25)>0,('Clarke, Penopolly'!I26+'Clarke, Penopolly'!I27)>0),AND(('Clarke, Penopolly'!I30+'Clarke, Penopolly'!I31)>0,('Clarke, Penopolly'!I32+'Clarke, Penopolly'!I33)>0,('Clarke, Penopolly'!I34+'Clarke, Penopolly'!I35)>0,('Clarke, Penopolly'!I36+'Clarke, Penopolly'!I37)>0,('Clarke, Penopolly'!I38+'Clarke, Penopolly'!I39)>0,('Clarke, Penopolly'!I40+'Clarke, Penopolly'!I41)>0,('Clarke, Penopolly'!I42+'Clarke, Penopolly'!I43)>0)),"Yes","") | I22: =IF('Clarke, Penopolly'!N49>40,"Yes","") | J22: =IF(OR(AND(SUM('Clarke, Penopolly'!I14:I27)>0,SUM('Clarke, Penopolly'!I14:I27)<40),AND(SUM('Clarke, Penopolly'!I30:I43)>0,SUM('Clarke, Penopolly'!I30:I43)<40)),"Yes","") | K22: =SUMPRODUCT(('Clarke, Penopolly'!I14:I48>0)*('Clarke, Penopolly'!I14:I48<8)) | L22: =IF('Clarke, Penopolly'!Q50<5,"Yes","") | M22: =IF(AND('Clarke, Penopolly'!I49>0,'Clarke, Penopolly'!I49<80),"Yes","") | N22: =IF(OR(F22>0,G22="Yes",H22="Yes",I22="Yes"),"⚠️ OVERWORK",IF(OR(J22="Yes",K22>0,L22="Yes",M22="Yes"),"🔻 UNDERWORK","✓ OK"))
A23: 19 | B23: Clarke, Richard | C23: 3399 | D23: ='Clarke, Richard'!I49 | E23: ='Clarke, Richard'!Q50 | F23: =SUMPRODUCT((('Clarke, Richard'!I14+'Clarke, Richard'!I15)>12)*1)+SUMPRODUCT((('Clarke, Richard'!I16+'Clarke, Richard'!I17)>12)*1)+SUMPRODUCT((('Clarke, Richard'!I18+'Clarke, Richard'!I19)>12)*1)+SUMPRODUCT((('Clarke, Richard'!I20+'Clarke, Richard'!I21)>12)*1)+SUMPRODUCT((('Clarke, Richard'!I22+'Clarke, Richard'!I23)>12)*1)+SUMPRODUCT((('Clarke, Richard'!I24+'Clarke, Richard'!I25)>12)*1)+SUMPRODUCT((('Clarke, Richard'!I26+'Clarke, Richard'!I27)>12)*1)+SUMPRODUCT((('Clarke, Richard'!I30+'Clarke, Richard'!I31)>12)*1)+SUMPRODUCT((('Clarke, Richard'!I32+'Clarke, Richard'!I33)>12)*1)+SUMPRODUCT((('Clarke, Richard'!I34+'Clarke, Richard'!I35)>12)*1)+SUMPRODUCT((('Clarke, Richard'!I36+'Clarke, Richard'!I37)>12)*1)+SUMPRODUCT((('Clarke, Richard'!I38+'Clarke, Richard'!I39)>12)*1)+SUMPRODUCT((('Clarke, Richard'!I40+'Clarke, Richard'!I41)>12)*1)+SUMPRODUCT((('Clarke, Richard'!I42+'Clarke, Richard'!I43)>12)*1)+SUMPRODUCT((('Clarke, Richard'!I45+'Clarke, Richard'!I46)>12)*1)+SUMPRODUCT((('Clarke, Richard'!I47+'Clarke, Richard'!I48)>12)*1) | G23: =IF(MAX(SUM('Clarke, Richard'!I14:I27),SUM('Clarke, Richard'!I30:I43))>60,"Yes","") | H23: =IF(OR(AND(('Clarke, Richard'!I14+'Clarke, Richard'!I15)>0,('Clarke, Richard'!I16+'Clarke, Richard'!I17)>0,('Clarke, Richard'!I18+'Clarke, Richard'!I19)>0,('Clarke, Richard'!I20+'Clarke, Richard'!I21)>0,('Clarke, Richard'!I22+'Clarke, Richard'!I23)>0,('Clarke, Richard'!I24+'Clarke, Richard'!I25)>0,('Clarke, Richard'!I26+'Clarke, Richard'!I27)>0),AND(('Clarke, Richard'!I30+'Clarke, Richard'!I31)>0,('Clarke, Richard'!I32+'Clarke, Richard'!I33)>0,('Clarke, Richard'!I34+'Clarke, Richard'!I35)>0,('Clarke, Richard'!I36+'Clarke, Richard'!I37)>0,('Clarke, Richard'!I38+'Clarke, Richard'!I39)>0,('Clarke, Richard'!I40+'Clarke, Richard'!I41)>0,('Clarke, Richard'!I42+'Clarke, Richard'!I43)>0)),"Yes","") | I23: =IF('Clarke, Richard'!N49>40,"Yes","") | J23: =IF(OR(AND(SUM('Clarke, Richard'!I14:I27)>0,SUM('Clarke, Richard'!I14:I27)<40),AND(SUM('Clarke, Richard'!I30:I43)>0,SUM('Clarke, Richard'!I30:I43)<40)),"Yes","") | K23: =SUMPRODUCT(('Clarke, Richard'!I14:I48>0)*('Clarke, Richard'!I14:I48<8)) | L23: =IF('Clarke, Richard'!Q50<5,"Yes","") | M23: =IF(AND('Clarke, Richard'!I49>0,'Clarke, Richard'!I49<80),"Yes","") | N23: =IF(OR(F23>0,G23="Yes",H23="Yes",I23="Yes"),"⚠️ OVERWORK",IF(OR(J23="Yes",K23>0,L23="Yes",M23="Yes"),"🔻 UNDERWORK","✓ OK"))
A24: 20 | B24: Cockfield, Nichola Roxann | C24: 4250 | D24: ='Cockfield, Nichola Roxann'!I49 | E24: ='Cockfield, Nichola Roxann'!Q50 | F24: =SUMPRODUCT((('Cockfield, Nichola Roxann'!I14+'Cockfield, Nichola Roxann'!I15)>12)*1)+SUMPRODUCT((('Cockfield, Nichola Roxann'!I16+'Cockfield, Nichola Roxann'!I17)>12)*1)+SUMPRODUCT((('Cockfield, Nichola Roxann'!I18+'Cockfield, Nichola Roxann'!I19)>12)*1)+SUMPRODUCT((('Cockfield, Nichola Roxann'!I20+'Cockfield, Nichola Roxann'!I21)>12)*1)+SUMPRODUCT((('Cockfield, Nichola Roxann'!I22+'Cockfield, Nichola Roxann'!I23)>12)*1)+SUMPRODUCT((('Cockfield, Nichola Roxann'!I24+'Cockfield, Nichola Roxann'!I25)>12)*1)+SUMPRODUCT((('Cockfield, Nichola Roxann'!I26+'Cockfield, Nichola Roxann'!I27)>12)*1)+SUMPRODUCT((('Cockfield, Nichola Roxann'!I30+'Cockfield, Nichola Roxann'!I31)>12)*1)+SUMPRODUCT((('Cockfield, Nichola Roxann'!I32+'Cockfield, Nichola Roxann'!I33)>12)*1)+SUMPRODUCT((('Cockfield, Nichola Roxann'!I34+'Cockfield, Nichola Roxann'!I35)>12)*1)+SUMPRODUCT((('Cockfield, Nichola Roxann'!I36+'Cockfield, Nichola Roxann'!I37)>12)*1)+SUMPRODUCT((('Cockfield, Nichola Roxann'!I38+'Cockfield, Nichola Roxann'!I39)>12)*1)+SUMPRODUCT((('Cockfield, Nichola Roxann'!I40+'Cockfield, Nichola Roxann'!I41)>12)*1)+SUMPRODUCT((('Cockfield, Nichola Roxann'!I42+'Cockfield, Nichola Roxann'!I43)>12)*1)+SUMPRODUCT((('Cockfield, Nichola Roxann'!I45+'Cockfield, Nichola Roxann'!I46)>12)*1)+SUMPRODUCT((('Cockfield, Nichola Roxann'!I47+'Cockfield, Nichola Roxann'!I48)>12)*1) | G24: =IF(MAX(SUM('Cockfield, Nichola Roxann'!I14:I27),SUM('Cockfield, Nichola Roxann'!I30:I43))>60,"Yes","") | H24: =IF(OR(AND(('Cockfield, Nichola Roxann'!I14+'Cockfield, Nichola Roxann'!I15)>0,('Cockfield, Nichola Roxann'!I16+'Cockfield, Nichola Roxann'!I17)>0,('Cockfield, Nichola Roxann'!I18+'Cockfield, Nichola Roxann'!I19)>0,('Cockfield, Nichola Roxann'!I20+'Cockfield, Nichola Roxann'!I21)>0,('Cockfield, Nichola Roxann'!I22+'Cockfield, Nichola Roxann'!I23)>0,('Cockfield, Nichola Roxann'!I24+'Cockfield, Nichola Roxann'!I25)>0,('Cockfield, Nichola Roxann'!I26+'Cockfield, Nichola Roxann'!I27)>0),AND(('Cockfield, Nichola Roxann'!I30+'Cockfield, Nichola Roxann'!I31)>0,('Cockfield, Nichola Roxann'!I32+'Cockfield, Nichola Roxann'!I33)>0,('Cockfield, Nichola Roxann'!I34+'Cockfield, Nichola Roxann'!I35)>0,('Cockfield, Nichola Roxann'!I36+'Cockfield, Nichola Roxann'!I37)>0,('Cockfield, Nichola Roxann'!I38+'Cockfield, Nichola Roxann'!I39)>0,('Cockfield, Nichola Roxann'!I40+'Cockfield, Nichola Roxann'!I41)>0,('Cockfield, Nichola Roxann'!I42+'Cockfield, Nichola Roxann'!I43)>0)),"Yes","") | I24: =IF('Cockfield, Nichola Roxann'!N49>40,"Yes","") | J24: =IF(OR(AND(SUM('Cockfield, Nichola Roxann'!I14:I27)>0,SUM('Cockfield, Nichola Roxann'!I14:I27)<40),AND(SUM('Cockfield, Nichola Roxann'!I30:I43)>0,SUM('Cockfield, Nichola Roxann'!I30:I43)<40)),"Yes","") | K24: =SUMPRODUCT(('Cockfield, Nichola Roxann'!I14:I48>0)*('Cockfield, Nichola Roxann'!I14:I48<8)) | L24: =IF('Cockfield, Nichola Roxann'!Q50<5,"Yes","") | M24: =IF(AND('Cockfield, Nichola Roxann'!I49>0,'Cockfield, Nichola Roxann'!I49<80),"Yes","") | N24: =IF(OR(F24>0,G24="Yes",H24="Yes",I24="Yes"),"⚠️ OVERWORK",IF(OR(J24="Yes",K24>0,L24="Yes",M24="Yes"),"🔻 UNDERWORK","✓ OK"))
